Workbook

Sheet Input-Start
A2: 0. >> INSTRUCTION << | D2: I. | F2: TRAFFIC DATA | M2: IIa. | N2: COSTS INFORMATION--Baseline (No ETC) | V2: IIb. | W2: COSTS INFORMATION--ETC Alternative | AF2: III. | AG2: FACT OF TOLL TRANSACTION | AO2: IV. | AP2: TRAVEL AT THE TOLL PLAZA | AX2: V. | AY2: FUEL CONSUMPTION & OTHER ASSUMPTIONS
A3: This spreadsheet model is designed exclusively for benefit-cost evaluation of | C3: INSTRUCTION: | L3: INSTRUCTION: | U3: INSTRUCTION: | AE3: INSTRUCTION: | AN3: INSTRUCTION: | AW3: INSTRUCTION:
A4: Electronic Toll Collection system. | D4: In this section, You are asked to give information about annual traffic | M4: In this section, You are asked to give information about costs for baseline | V4: In this section, You are asked to give information about costs under ETC scenario. | AF4: Required Inputs - white cells | AO4: In this section, You are asked to give information about travel fact at the toll plaza | AX4: In this section, You are asked to give information about fuel consumption in
D5: volume, peak hour volume, D factor and duration of peak period and ETC | M5: operations. Costs are broken down into two categories: one-time costs and | V5: Costs are broken down into two categories: capital investment and operating costs. | AF5: If you have more information about payment split other base year and year 20, go to | AO5: Required Inputs - white cells | AX5: order to estimate the fuel reduction, and other general assumptions.
A6: Where to Start? | D6: Split both in base year and in year 20 or one of them. | M6: continuing costs. All the costs are presented in current value. | V6: All the costs are presented in current value. | AF6: Table IV, expected payment split, in sheet"Input-Details" after completing this table. | AO6: a)Ramp Distance prior to (leading from) the Toll Plaza: The distance that a vehicle | AX6: The Numbers shown in pink cells are the values from previously studies and
A7: Please start with sheet "Input-Start" and fill out all required cells. You may check | D7: If you have information in between, go to sheet "Input-Detail" table Ia, Ib, and 1c | M7: Go to sheet "Input-Detail" table IIa after completing this table if you have | V7: If you have more information, go to sheet "Input-Detail" table IIb after completing this table. | AF7: Default Values - pink cells | AO7: starts to slow down from the normal speed (to accelerate from complete stop). | AX7: used as default values to run the model. Please update it if you have
A8: "Input-Detail" and make some changes based on your own knowledge, or go to the | D8: after completing this table. | M8: detailed information regarding baseline costs. | V8: Required Inputs - white cells | AF8: The values shown in the pink cells are the default number we used previously to run | AO8: b)Prevailing Travel Speed: The travel speed in the adjacent highway sections that | AX8: different values in your case.
A9: "Results Summary" and "Results-Detail" directly to find out the analytical results. | D9: Required Inputs - white cells | M9: Required Inputs - white cells | V9: a) Capital Investment: Initial investment needed to implement ETC project | AF9: the model, please change it if you have different numbers. | AO9: is not influenced by the existence of the toll plaza.
A10: Notice that:always complete this sheet first. | D10: a) Annual Traffic Volume in Base Year as well as in Year 20: | M10: a) One-Time Costs: Costs which occur only once at a specific point of time. | V10: b) Operating Costs: Costs in order to operate the system under ETC scenario | AF10: a) Avg. Tags per Account: The ratio of the number of transponders issued over | AO10: Default Values - pink cells | AX10: Assumptions about Fuel Consumption
D11: "Annual Traffic Volume" here is defined as the number of traffic goes | M11: enter "0" if no costs incurred. | V11: 1) One-time costs: costs which occur only once at a specific point of time | AF11: over the number of accounts open. Several cars may share one account. | AO11: The numbers in pink cells are used previously to run the model, please update it
A12: Other sheets in this files are for the sake of estimation. You may want to have a | D12: through the Toll Plaza per year. | M12: b) Continuing Costs: Costs incurred every year | V12: 2) Operations/Materials Costs | AF12: b)Avg. Usage per Year: Total number of transactions divided by the total | AO12: if your case has different values . | AX12: Average Mileage of Consuming one Gallon of Fuel | BA12: 25
A13: glance and get a general idea of how to get these numbers. You can refer to | D13: b) Expected ETC Split in Base Year as well as in Year 20 | M13: 1) Operations/Materials Costs | V13: 3) Others | AF13: number of accounts open. | AX13: Fuel Price per Gallon | BA13: 1.1
A14: footnotes right below the spreadsheet which provide formula and assumptions | D14: c) Peak Hour Volume (PHV) in Base Year. | M14: 2) Others | V14: Staff Costs is estimated automatically by given units of personal year needed for toll | AF14: c)Deposits: This number refers to the required deposits for transponders. | AX14: Emission Rates during Acceleration (grams/gallon)
A15: employed to proceed the clalculation. | D15: "Peak Hour Volume" here is defined as traffic volume in both direction during | M15: Staff Costs is estimated automatically by given units of personal year needed for | V15: collection and information technology, and costs per personal year. | AO15: Configuration of the Toll Plaza | AY15: Nox | BA15: 24.7
D16: the peak period. | M16: toll collection and information technology, and costs per personal year. | AF16: Transaction Time (sec) | AP16: Total Number of Lanes (max 22) | AR16: 12 | AY16: HC | BA16: 9.5
A17: q SHEET "Input-Start" | D17: d) Peak Hour Duration (T) in Base Year | V17: Year | W17: Capital Investment | X17: Operating Costs | AG17: Cash | AI17: 7 | AP17: Ramp Distance prior to the Toll Plaza (miles) | AR17: 0.2 | AY17: CO | BA17: 209
A18: In this Sheet, you are asked to give the basic information required for Benefit-Cost analysis. | D18: e) D factor (D) in Base Year - directional split | M18: Year | N18: One-Time Costs | O18: Continuing Costs: | X18: One-Time Costs | Y18: Staff | Z18: Operations/Materials | AA18: Other | AG18: Ticket | AI18: 4.5 | AP18: Ramp Distance leading from the toll Plaza (miles) | AR18: 0.2 | AX18: Emission Rates during Idling (grams/minute)
A19: Basically, you have to provide the data for Base Year as well as for Year 20. | O19: Staff | P19: Operations/Materials | Q19: Other | V19: Base | W19: 3009339.7 | X19: 0 | Z19: 8356 | AA19: 301760 | AG19: ETC (headway) | AI19: 2.4 | AY19: Nox | BA19: 0
A20: Then, the model estimates the numbers in between automatically by linear interpolation. | D20: Estimated Annual Traffic Volume (ATV) | M20: Base | N20: 0 | P20: 8356.16 | Q20: 297120 | V20: 1 | W20: 0 | X20: 0 | AF20: Payment Split | AO20: Prevailing Travel Speed (mph) | AR20: 55 | AY20: HC | BA20: 0.15
A21: If you have more data regarding information required other than base in year and in year 20, | F21: Base Year | G21: Year 20 | M21: 1 | N21: 0 | V21: 2 | W21: 284813 | X21: 0 | AF21: Manual Lane-Baseline | AH21: Base Year | AI21: Year 20 | AY21: CO | BA21: 2.5
A22: enter the basic data required in this sheet first; | E22: Traffic Volume | F22: 19016173 | G22: 30000000 | M22: 2 | N22: 0 | V22: 3 | W22: 448581 | X22: 0 | AG22: Cash | AH22: 0.83 | AI22: 0.83 | AO22: Mode Split among ETC Users | AX22: Cost of Air Polution ($/kg of pollutant)
A23: then, go to the sheet "Input-Detail" to change the number shown in blue cells. | E23: ETC Split | F23: 0 | G23: 0.99 | M23: 3 | N23: 0 | V23: 4 | W23: 273801 | X23: 0 | AG23: Ticket | AH23: =1-AH22 -> 0.17 | AI23: =1-AI22 -> 0.17 | AP23: Auto | AR23: 0.9476 | AY23: Nox | BA23: 1.275
M24: 4 | N24: 0 | V24: 5 | W24: 289568 | X24: 0 | AF24: Manual Lane-ETC Alternative | AP24: Truck | AR24: 0.0511 | AY24: HC | BA24: 1.275
A25: q SHEET "Input-Detail" | D25: Peak Hour Statistics in Base Year | M25: 5 | N25: 0 | V25: 6 | W25: 306036 | X25: 0 | AG25: Cash | AH25: 0.83 | AI25: 1 | AP25: Bus | AR25: 0.0013 | AY25: CO | BA25: 0.0063
A26: In this Sheet, you you may change the numbers estimated automatically by this model based | F26: Morning | G26: Evening | M26: 6 | N26: 0 | V26: 7 | W26: 323231 | X26: 0 | AG26: Ticket | AH26: =1-AH25 -> 0.17 | AI26: =1-AI25 -> 0 | AO26: Average Vehicle Occupancy
A27: on the numbers you enter in "Input-Start". | E27: PHV (veh/hr) | F27: 8200 | G27: 8200 | M27: 7 | N27: 0 | V27: 8 | W27: 341183 | X27: 0 | AF27: ETC Lane-ETC Alternative | AP27: Auto | AR27: 1.8
E28: T (hr) | F28: 2 | G28: 2 | M28: 8 | N28: 0 | V28: 9 | W28: 359920 | X28: 0 | AG28: Cash, Checks | AH28: 0.64 | AI28: 0.64 | AP28: Truck | AR28: 1.1 | AX28: General Assumptions
A29: q SHEET "Results Summary" | E29: D factor | F29: 0.3 | G29: 0.7 | M29: 9 | N29: 0 | V29: 10 | W29: 379475 | X29: 0 | AG29: Credit Card | AH29: =1-AH28 -> 0.36 | AI29: =1-AI28 -> 0.36 | AP29: Bus | AR29: 20
A30: In this Sheet, , overall analytical results are presented as well as benefit-cost ratio and | M30: 10 | N30: 0 | V30: 11 | W30: 0 | X30: 0 | AF30: ETC Account Fact | AX30: Inflation Rate | BA30: 0.03
A31: estimated internal interest rate. | M31: 11 | N31: 0 | V31: 12 | W31: 0 | X31: 0 | AF31: Cash & Checks Account | AI31: Base Year | AO31: Time Value of a User for Each Mode ($/hr) | AX31: Annual Interest Rate | BA31: 0.05
M32: 12 | N32: 0 | V32: 13 | W32: 0 | X32: 0 | AG32: Avg. Tags per Accout | AI32: 1.35 | AP32: Auto | AR32: 12.75 | AX32: Discount Rate | BA32: 0.02
A33: q SHEET "Results-Detail" | M33: 13 | N33: 0 | V33: 14 | W33: 0 | X33: 0 | AG33: Avg. Usage per Year | AI33: 160 | AP33: Truck | AR33: 33.41 | AX33: Personal Year (PY)
A34: In this Sheet, benefit-cost analyses are shown for Toll Agency, Users, and Community. | M34: 14 | N34: 0 | V34: 15 | W34: 0 | X34: 0 | AG34: Deposits | AI34: 30 | AP34: Bus (per rider) | AR34: 12.75 | AY34: Hours per Unit Personal Year | BA34: 1768
A35: respectively. | M35: 15 | N35: 0 | V35: 16 | W35: 0 | X35: 0 | AG35: Avg. Balance other than Deposit | AI35: 20 | AY35: PY for Information Technology | BA35: 0.11
M36: 16 | N36: 0 | V36: 17 | W36: 0 | X36: 0 | AF36: Credit Card Account | AI36: Base Year | AY36: PY for Program Costs (Toll Collection) | BA36: 61.5
M37: 17 | N37: 0 | V37: 18 | W37: 0 | X37: 0 | AG37: Avg. Tags per Accout | AI37: 1.35 | AY37: Unit Cost per Personal Year | BA37: 65000
M38: 18 | N38: 0 | V38: 19 | W38: 0 | X38: 0 | AG38: Avg. Usage per Year | AI38: 160
M39: 19 | N39: 0 | V39: 20 | W39: 0 | X39: 0 | AG39: Deposits | AI39: 0
M40: 20 | N40: 0 | AG40: Avg. Balance other than Deposit | AI40: 20

Sheet Input-Detail
C2: Ia. | D2: TRAFFIC DATA - Annual | L2: Ib. | M2: TRAFFIC DATA - Morning Peak | U2: Ic. | V2: TRAFFIC DATA - Evening Peak | AD2: IIa. | AE2: COSTS INFORMATION--Baseline (No ETC) | AM2: IIa. | AN2: COSTS INFORMATION--ETC Alternative | AW2: III. | AX2: FACT OF TOLL TRANSACTION & Travel at Toll Plaza | BF2: IV. | BI2: EXPECTED PAYMENT SPLIT | BS2: V. | BT2: FUEL CONSUMPTION & OTHER ASSUMPTIONS
B3: INSTRUCTION: | K3: INSTRUCTION: | T3: INSTRUCTION: | AC3: INSTRUCTION: | AL3: INSTRUCTION: | AV3: INSTRUCTION: | BE3: INSTRUCTION: | BR3: INSTRUCTION:
C4: Change the numbers in blue cells only - | L4: Change the numbers in blue cells only - | U4: Change the numbers in blue cells only - | AD4: Change the numbers in blue cells only - | AM4: Change the numbers in blue cells only - | AW4: The values shown in pink cells are the default number we used to run the model. | BF4: Change the numbers in blue cells only - | BS4: The values shown in pink cells are the default number we used to run the model.
C5: The data in Base Year and Year 20 you enter in sheet "Input-Start" are | L5: The data in Base Year and Year 20 you enter in sheet "Input-Start" are | U5: The data in Base Year and Year 20 you enter in sheet "Input-Start" are | AD5: The data in Base Year and Year 20 you enter in sheet "Input-Start" are shown | AM5: The data in Base Year and Year 20 you enter in sheet "Input-Start" are | AW5: The numbers in white cells are those you entered in Table III &IV in "Input-Start" Sheet. | BF5: the numbers in white cells are those you entered in "Input-Start" Sheet about . | BS5: The numbers in white cells are those you entered in Table V in "Input-Start" Sheet.
C6: shown on white cells. | L6: shown on white cells. | U6: shown on white cells. | AD6: on white cells after inflation effect. That is, the number show on this table | AM6: shown on white cells after inflation effect. That is, the number show on this | AW6: You can not make any change here. | BF6: payment split among Manual Users as well as among ETC Users. | BS6: You can not make any change here.
C7: Based on these data, the model estimated automatically annual traffic volume | L7: Based on these data, the model estimated automatically peak hour traffic | U7: Based on these data, the model estimated automatically peak hour traffic | AD7: are no longer current value but nominal value in year i. | AM7: table are no longer current value but nominal value. | AW7: If you would like to make any change, go back to the sheet "Input-Start". | BS7: If you would like to make any change, go back to the sheet "Input-Start".
C8: and ETC Split in between by interpolation. | L8: volume, duration of peak period, and D factor for each year. | U8: volume, duration of peak period, and D factor. | AD8: Based on these data, the model estimates continuing costs automatically. | AM8: Based on these data, the model estimated continuing cost automatically. | BF8: Payment Split
C9: Please make reasonable adjustions in blue cells. | L9: a) Peak Hour Volume (PHV): assume that ATV/PHV remains constant over | U9: a) Peak Hour Volume (PHV) - assume that ATV/PHV remains constant over | AD9: For the knowledge of estimation, check the footnote right below the table. | AM9: For the knowledge of estimation, check the footnote right below the table. | AW9: Transaction Time (sec) | BS9: Assumptions about Fuel Consumption
L10: the analysis period. Thus, peak hour volume in year i is estimated by | U10: the analysis period. Thus, peak hour volume in year i is estimated by | AD10: Please make reasonable adjustions in blue cells. | AM10: Please make reasonable adjustions in blue cells. | AX10: Cash | AZ10: ='Input-Start'!AI17 -> 7 | BG10: Year | BH10: Baseline | BJ10: ETC Alternative
C11: Estimated Annual Traffic Volume (ATV) | L11: estimated annual traffic volume times ATV/PHV. | U11: estimated annual traffic volume times ATV/PHV. | AX11: Ticket | AZ11: ='Input-Start'!AI18 -> 4.5 | BH11: Manual Users | BJ11: Manual Users | BL11: ETC Users | BS11: Average Milage of Consuming one Gallon of Fuel | BV11: ='Input-Start'!BA12 -> 25
L12: b) ATV/PHV - the ratio of annual traffic volume over peak hour volume. | U12: b) ATV/PHV - the ratio of annual traffic volume over peak hour volume. | AD12: Year | AE12: One-Time Costs | AF12: Continuing Costs: | AM12: Year | AN12: Capital Investment | AO12: Continuing Costs: | AX12: ETC (headway) | AZ12: ='Input-Start'!AI19 -> 2.4 | BH12: Cash | BI12: Ticket | BJ12: Cash | BK12: Ticket | BL12: Cash &Checks | BM12: Credit Card | BS12: Fuel Price per Gallon | BV12: ='Input-Start'!BA13 -> 1.1
D13: Year | E13: Traffic Vol. | F13: ETC Split | L13: c) Duration of Peak Period (T) in the morning peak in Based Year, hrs/day. | U13: c) Duration of Peak Period (T) in the evening peak in Based Year, hrs/day | AF13: Staff* | AG13: Operations/Materials | AH13: Other | AO13: One-Time Costs | AP13: Staff | AQ13: Operations/Materials | AR13: Other | AW13: ETC Account Fact | BG13: Base | BH13: ='Input-Start'!AH22 -> 0.83 | BI13: =1-BH13 -> 0.17 | BJ13: ='Input-Start'!AH25 -> 0.83 | BK13: =1-BJ13 -> 0.17 | BL13: ='Input-Start'!AH28 -> 0.64 | BM13: =1-BL13 -> 0.36 | BS13: Emission Rates during Acceleration (grams/gallon)
D14: Base | E14: ='Input-Start'!F22 -> 19016173 | F14: ='Input-Start'!F23 -> 0 | L14: d) Direction Factor (D) during the morning peak in Base Year | U14: d) Direction Factor (D) during the evening peak in Base Year | AD14: Base | AE14: ='Input-Start'!N20 -> 0 | AF14: =Cost_PY*('Input-Start'!BA36+PY_for_Inf) -> 4004650 | AG14: ='Input-Start'!P20 -> 8356.16 | AH14: ='Input-Start'!Q20 -> 297120 | AM14: Base | AN14: ='Input-Start'!W19 -> 3009339.7 | AO14: ='Input-Start'!X19 -> 0 | AP14: =Cost_PY*(PY_for_Inf+PY!$Q6) -> 4004650 | AQ14: ='Input-Start'!Z19 -> 8356 | AR14: ='Input-Start'!AA19 -> 301760 | AW14: Cash & Checks | BG14: 1 | BH14: =BH$13+(BH$33-BH$13)*$D15/$D$34 -> 0.83 | BI14: =1-BH14 -> 0.17 | BJ14: =BJ$13+(BJ$33-BJ$13)*$D15/$D$34 -> 0.8385 | BK14: =1-BJ14 -> 0.1615 | BL14: =BL$13+(BL$33-BL$13)*$D15/$D$34 -> 0.64 | BM14: =1-BL14 -> 0.36 | BT14: Nox | BV14: ='Input-Start'!BA15 -> 24.7
D15: 1 | E15: =E$14+(E$34-E$14)*$D15/$D$34 -> 19565364 | F15: =F$14+(F$34-F$14)*$D15/$D$34 -> 0.0495 | L15: Please make reasonable adjustions in blue cells. | U15: Please make reasonable adjustions in blue cells. | AD15: 1 | AE15: ='Input-Start'!N21^(1+Inflation_Rate)^Year -> 0 | AF15: =Cost_PY*(PY_for_Inf+PY!$L7)*(1+Inflation_Rate)^Year -> 4230053.2 | AG15: =AG14*(1+Inflation_Rate) -> 8606.8448 | AH15: =AH14*(1+Inflation_Rate) -> 306033.6 | AM15: 1 | AN15: ='Input-Start'!W20*(1+Inflation_Rate)^Year -> 0 | AO15: ='Input-Start'!X20*(1+Inflation_Rate)^'Input-Detail'!$AM15 -> 0 | AP15: =Cost_PY*(PY_for_Inf+PY!$Q7)*(1+Inflation_Rate)^Year -> 4005040.9 | AQ15: =AQ14*(1+Inflation_Rate) -> 8606.68 | AR15: =AR14*(1+Inflation_Rate) -> 310812.8 | AX15: Avg. Tags per Accout | AZ15: ='Input-Start'!AI32 -> 1.35 | BG15: 2 | BH15: =BH$13+(BH$33-BH$13)*$D16/$D$34 -> 0.83 | BI15: =1-BH15 -> 0.17 | BJ15: =BJ$13+(BJ$33-BJ$13)*$D16/$D$34 -> 0.847 | BK15: =1-BJ15 -> 0.153 | BL15: =BL$13+(BL$33-BL$13)*$D16/$D$34 -> 0.64 | BM15: =1-BL15 -> 0.36 | BT15: HC | BV15: ='Input-Start'!BA16 -> 9.5
D16: 2 | E16: =E$14+(E$34-E$14)*$D16/$D$34 -> 20114556 | F16: =F$14+(F$34-F$14)*$D16/$D$34 -> 0.099 | AD16: 2 | AE16: ='Input-Start'!N22^(1+Inflation_Rate)^Year -> 0 | AF16: =Cost_PY*(PY_for_Inf+PY!$L8)*(1+Inflation_Rate)^Year -> 4465376.4 | AG16: =AG15*(1+Inflation_Rate) -> 8865.0501 | AH16: =AH15*(1+Inflation_Rate) -> 315214.61 | AM16: 2 | AN16: ='Input-Start'!W21*(1+Inflation_Rate)^Year -> 302158.11 | AO16: ='Input-Start'!X21*(1+Inflation_Rate)^'Input-Detail'!$AM16 -> 0 | AP16: =Cost_PY*(PY_for_Inf+PY!$Q8)*(1+Inflation_Rate)^$AM16 -> 4031681.1 | AQ16: =AQ15*(1+Inflation_Rate) -> 8864.8804 | AR16: =AR15*(1+Inflation_Rate) -> 320137.18 | AX16: Avg. Usage per Year | AZ16: ='Input-Start'!AI33 -> 160 | BG16: 3 | BH16: =BH$13+(BH$33-BH$13)*$D17/$D$34 -> 0.83 | BI16: =1-BH16 -> 0.17 | BJ16: =BJ$13+(BJ$33-BJ$13)*$D17/$D$34 -> 0.8555 | BK16: =1-BJ16 -> 0.1445 | BL16: =BL$13+(BL$33-BL$13)*$D17/$D$34 -> 0.64 | BM16: =1-BL16 -> 0.36 | BT16: CO | BV16: ='Input-Start'!BA17 -> 209
D17: 3 | E17: =E$14+(E$34-E$14)*$D17/$D$34 -> 20663747 | F17: =F$14+(F$34-F$14)*$D17/$D$34 -> 0.1485 | L17: Year | M17: PHV | N17: ATV/PHV | O17: T (hr) | P17: K | U17: Year | V17: PHV | W17: ATV/PHV | X17: T (hr) | Y17: K | AD17: 3 | AE17: ='Input-Start'!N23^(1+Inflation_Rate)^Year -> 0 | AF17: =Cost_PY*(PY_for_Inf+PY!$L9)*(1+Inflation_Rate)^Year -> 4711012 | AG17: =AG16*(1+Inflation_Rate) -> 9131.0016 | AH17: =AH16*(1+Inflation_Rate) -> 324671.05 | AM17: 3 | AN17: ='Input-Start'!W22*(1+Inflation_Rate)^Year -> 490176.57 | AO17: ='Input-Start'!X22*(1+Inflation_Rate)^'Input-Detail'!$AM17 -> 0 | AP17: =Cost_PY*(PY_for_Inf+PY!$Q9)*(1+Inflation_Rate)^$AM17 -> 4045259.5 | AQ17: =AQ16*(1+Inflation_Rate) -> 9130.8268 | AR17: =AR16*(1+Inflation_Rate) -> 329741.3 | AX17: Deposits | AZ17: ='Input-Start'!AI34 -> 30 | BG17: 4 | BH17: =BH$13+(BH$33-BH$13)*$D18/$D$34 -> 0.83 | BI17: =1-BH17 -> 0.17 | BJ17: =BJ$13+(BJ$33-BJ$13)*$D18/$D$34 -> 0.864 | BK17: =1-BJ17 -> 0.136 | BL17: =BL$13+(BL$33-BL$13)*$D18/$D$34 -> 0.64 | BM17: =1-BL17 -> 0.36 | BS17: Emission Rates during Idling (grams/minute)
D18: 4 | E18: =E$14+(E$34-E$14)*$D18/$D$34 -> 21212938 | F18: =F$14+(F$34-F$14)*$D18/$D$34 -> 0.198 | L18: Base | M18: ='Input-Start'!F27 -> 8200 | N18: =E14/M18 -> 2319.0455 | O18: ='Input-Start'!F28 -> 2 | P18: ='Input-Start'!F29 -> 0.3 | U18: Base | V18: ='Input-Start'!G27 -> 8200 | W18: =E14/V18 -> 2319.0455 | X18: ='Input-Start'!G28 -> 2 | Y18: ='Input-Start'!G29 -> 0.7 | AD18: 4 | AE18: ='Input-Start'!N24^(1+Inflation_Rate)^Year -> 0 | AF18: =Cost_PY*(PY_for_Inf+PY!$L10)*(1+Inflation_Rate)^Year -> 4967366.8 | AG18: =AG17*(1+Inflation_Rate) -> 9404.9317 | AH18: =AH17*(1+Inflation_Rate) -> 334411.18 | AM18: 4 | AN18: ='Input-Start'!W23*(1+Inflation_Rate)^Year -> 308165.44 | AO18: ='Input-Start'!X23*(1+Inflation_Rate)^'Input-Detail'!$AM18 -> 0 | AP18: =Cost_PY*(PY_for_Inf+PY!$Q10)*(1+Inflation_Rate)^$AM18 -> 4044636.6 | AQ18: =AQ17*(1+Inflation_Rate) -> 9404.7516 | AR18: =AR17*(1+Inflation_Rate) -> 339633.54 | AX18: Avg. Balance other than Deposit | AZ18: ='Input-Start'!AI35 -> 20 | BG18: 5 | BH18: =BH$13+(BH$33-BH$13)*$D19/$D$34 -> 0.83 | BI18: =1-BH18 -> 0.17 | BJ18: =BJ$13+(BJ$33-BJ$13)*$D19/$D$34 -> 0.8725 | BK18: =1-BJ18 -> 0.1275 | BL18: =BL$13+(BL$33-BL$13)*$D19/$D$34 -> 0.64 | BM18: =1-BL18 -> 0.36 | BT18: Nox | BV18: ='Input-Start'!BA19 -> 0
D19: 5 | E19: =E$14+(E$34-E$14)*$D19/$D$34 -> 21762130 | F19: =F$14+(F$34-F$14)*$D19/$D$34 -> 0.2475 | L19: 1 | M19: =E15/$N$18 -> 8436.8178 | N19: =E15/M19 -> 2319.0455 | O19: =O18 -> 2 | P19: =P18 -> 0.3 | U19: 1 | V19: =E15/$W$18 -> 8436.8178 | W19: =E15/V19 -> 2319.0455 | X19: =X18 -> 2 | Y19: =Y18 -> 0.7 | AD19: 5 | AE19: ='Input-Start'!N25^(1+Inflation_Rate)^Year -> 0 | AF19: =Cost_PY*(PY_for_Inf+PY!$L11)*(1+Inflation_Rate)^Year -> 5234863.1 | AG19: =AG18*(1+Inflation_Rate) -> 9687.0796 | AH19: =AH18*(1+Inflation_Rate) -> 344443.51 | AM19: 5 | AN19: ='Input-Start'!W24*(1+Inflation_Rate)^Year -> 335688.68 | AO19: ='Input-Start'!X24*(1+Inflation_Rate)^'Input-Detail'!$AM19 -> 0 | AP19: =Cost_PY*(PY_for_Inf+PY!$Q11)*(1+Inflation_Rate)^$AM19 -> 3984281.4 | AQ19: =AQ18*(1+Inflation_Rate) -> 9686.8942 | AR19: =AR18*(1+Inflation_Rate) -> 349822.54 | AW19: Credit Card | BG19: 6 | BH19: =BH$13+(BH$33-BH$13)*$D20/$D$34 -> 0.83 | BI19: =1-BH19 -> 0.17 | BJ19: =BJ$13+(BJ$33-BJ$13)*$D20/$D$34 -> 0.881 | BK19: =1-BJ19 -> 0.119 | BL19: =BL$13+(BL$33-BL$13)*$D20/$D$34 -> 0.64 | BM19: =1-BL19 -> 0.36 | BT19: HC | BV19: ='Input-Start'!BA20 -> 0.15
D20: 6 | E20: =E$14+(E$34-E$14)*$D20/$D$34 -> 22311321 | F20: =F$14+(F$34-F$14)*$D20/$D$34 -> 0.297 | L20: 2 | M20: =E16/$N$18 -> 8673.6357 | N20: =E16/M20 -> 2319.0455 | O20: =O19 -> 2 | P20: =P19 -> 0.3 | U20: 2 | V20: =E16/$W$18 -> 8673.6357 | W20: =E16/V20 -> 2319.0455 | X20: =X19 -> 2 | Y20: =Y19 -> 0.7 | AD20: 6 | AE20: ='Input-Start'!N26^(1+Inflation_Rate)^Year -> 0 | AF20: =Cost_PY*(PY_for_Inf+PY!$L12)*(1+Inflation_Rate)^Year -> 5513938.4 | AG20: =AG19*(1+Inflation_Rate) -> 9977.692 | AH20: =AH19*(1+Inflation_Rate) -> 354776.82 | AM20: 6 | AN20: ='Input-Start'!W25*(1+Inflation_Rate)^Year -> 365422.99 | AO20: ='Input-Start'!X25*(1+Inflation_Rate)^'Input-Detail'!$AM20 -> 0 | AP20: =Cost_PY*(PY_for_Inf+PY!$Q12)*(1+Inflation_Rate)^$AM20 -> 3950238.7 | AQ20: =AQ19*(1+Inflation_Rate) -> 9977.501 | AR20: =AR19*(1+Inflation_Rate) -> 360317.22 | AX20: Avg. Tags per Accout | AZ20: ='Input-Start'!AI37 -> 1.35 | BG20: 7 | BH20: =BH$13+(BH$33-BH$13)*$D21/$D$34 -> 0.83 | BI20: =1-BH20 -> 0.17 | BJ20: =BJ$13+(BJ$33-BJ$13)*$D21/$D$34 -> 0.8895 | BK20: =1-BJ20 -> 0.1105 | BL20: =BL$13+(BL$33-BL$13)*$D21/$D$34 -> 0.64 | BM20: =1-BL20 -> 0.36 | BT20: CO | BV20: ='Input-Start'!BA21 -> 2.5
D21: 7 | E21: =E$14+(E$34-E$14)*$D21/$D$34 -> 22860512 | F21: =F$14+(F$34-F$14)*$D21/$D$34 -> 0.3465 | L21: 3 | M21: =E17/$N$18 -> 8910.4535 | N21: =E17/M21 -> 2319.0455 | O21: =O20 -> 2 | P21: =P20 -> 0.3 | U21: 3 | V21: =E17/$W$18 -> 8910.4535 | W21: =E17/V21 -> 2319.0455 | X21: =X20 -> 2 | Y21: =Y20 -> 0.7 | AD21: 7 | AE21: ='Input-Start'!N27^(1+Inflation_Rate)^Year -> 0 | AF21: =Cost_PY*(PY_for_Inf+PY!$L13)*(1+Inflation_Rate)^Year -> 5805047 | AG21: =AG20*(1+Inflation_Rate) -> 10277.023 | AH21: =AH20*(1+Inflation_Rate) -> 365420.12 | AM21: 7 | AN21: ='Input-Start'!W26*(1+Inflation_Rate)^Year -> 397533.36 | AO21: ='Input-Start'!X26*(1+Inflation_Rate)^'Input-Detail'!$AM21 -> 0 | AP21: =Cost_PY*(PY_for_Inf+PY!$Q13)*(1+Inflation_Rate)^$AM21 -> 3898124.2 | AQ21: =AQ20*(1+Inflation_Rate) -> 10276.826 | AR21: =AR20*(1+Inflation_Rate) -> 371126.74 | AX21: Avg. Usage per Year | AZ21: ='Input-Start'!AI38 -> 160 | BG21: 8 | BH21: =BH$13+(BH$33-BH$13)*$D22/$D$34 -> 0.83 | BI21: =1-BH21 -> 0.17 | BJ21: =BJ$13+(BJ$33-BJ$13)*$D22/$D$34 -> 0.898 | BK21: =1-BJ21 -> 0.102 | BL21: =BL$13+(BL$33-BL$13)*$D22/$D$34 -> 0.64 | BM21: =1-BL21 -> 0.36 | BS21: Cost of Air Polution ($/kg of pollutant)
D22: 8 | E22: =E$14+(E$34-E$14)*$D22/$D$34 -> 23409704 | F22: =F$14+(F$34-F$14)*$D22/$D$34 -> 0.396 | L22: 4 | M22: =E18/$N$18 -> 9147.2714 | N22: =E18/M22 -> 2319.0455 | O22: =O21 -> 2 | P22: =P21 -> 0.3 | U22: 4 | V22: =E18/$W$18 -> 9147.2714 | W22: =E18/V22 -> 2319.0455 | X22: =X21 -> 2 | Y22: =Y21 -> 0.7 | AD22: 8 | AE22: ='Input-Start'!N28^(1+Inflation_Rate)^Year -> 0 | AF22: =Cost_PY*(PY_for_Inf+PY!$L14)*(1+Inflation_Rate)^Year -> 6108659.4 | AG22: =AG21*(1+Inflation_Rate) -> 10585.333 | AH22: =AH21*(1+Inflation_Rate) -> 376382.73 | AM22: 8 | AN22: ='Input-Start'!W27*(1+Inflation_Rate)^Year -> 432200.42 | AO22: ='Input-Start'!X27*(1+Inflation_Rate)^'Input-Detail'!$AM22 -> 0 | AP22: =Cost_PY*(PY_for_Inf+PY!$Q14)*(1+Inflation_Rate)^$AM22 -> 3778075.7 | AQ22: =AQ21*(1+Inflation_Rate) -> 10585.131 | AR22: =AR21*(1+Inflation_Rate) -> 382260.54 | AX22: Deposits | AZ22: ='Input-Start'!AI39 -> 0 | BG22: 9 | BH22: =BH$13+(BH$33-BH$13)*$D23/$D$34 -> 0.83 | BI22: =1-BH22 -> 0.17 | BJ22: =BJ$13+(BJ$33-BJ$13)*$D23/$D$34 -> 0.9065 | BK22: =1-BJ22 -> 0.0935 | BL22: =BL$13+(BL$33-BL$13)*$D23/$D$34 -> 0.64 | BM22: =1-BL22 -> 0.36 | BT22: Nox | BV22: ='Input-Start'!BA23 -> 1.275
D23: 9 | E23: =E$14+(E$34-E$14)*$D23/$D$34 -> 23958895 | F23: =F$14+(F$34-F$14)*$D23/$D$34 -> 0.4455 | L23: 5 | M23: =E19/$N$18 -> 9384.0892 | N23: =E19/M23 -> 2319.0455 | O23: =O22 -> 2 | P23: =P22 -> 0.3 | U23: 5 | V23: =E19/$W$18 -> 9384.0892 | W23: =E19/V23 -> 2319.0455 | X23: =X22 -> 2 | Y23: =Y22 -> 0.7 | AD23: 9 | AE23: ='Input-Start'!N29^(1+Inflation_Rate)^Year -> 0 | AF23: =Cost_PY*(PY_for_Inf+PY!$L15)*(1+Inflation_Rate)^Year -> 6425264.1 | AG23: =AG22*(1+Inflation_Rate) -> 10902.893 | AH23: =AH22*(1+Inflation_Rate) -> 387674.21 | AM23: 9 | AN23: ='Input-Start'!W28*(1+Inflation_Rate)^Year -> 469613.96 | AO23: ='Input-Start'!X28*(1+Inflation_Rate)^'Input-Detail'!$AM23 -> 0 | AP23: =Cost_PY*(PY_for_Inf+PY!$Q15)*(1+Inflation_Rate)^$AM23 -> 3684003.2 | AQ23: =AQ22*(1+Inflation_Rate) -> 10902.685 | AR23: =AR22*(1+Inflation_Rate) -> 393728.36 | AX23: Avg. Balance other than Deposit | AZ23: ='Input-Start'!AI40 -> 20 | BG23: 10 | BH23: =BH$13+(BH$33-BH$13)*$D24/$D$34 -> 0.83 | BI23: =1-BH23 -> 0.17 | BJ23: =BJ$13+(BJ$33-BJ$13)*$D24/$D$34 -> 0.915 | BK23: =1-BJ23 -> 0.085 | BL23: =BL$13+(BL$33-BL$13)*$D24/$D$34 -> 0.64 | BM23: =1-BL23 -> 0.36 | BT23: HC | BV23: ='Input-Start'!BA24 -> 1.275
D24: 10 | E24: =E$14+(E$34-E$14)*$D24/$D$34 -> 24508086 | F24: =F$14+(F$34-F$14)*$D24/$D$34 -> 0.495 | L24: 6 | M24: =E20/$N$18 -> 9620.9071 | N24: =E20/M24 -> 2319.0455 | O24: =O23 -> 2 | P24: =P23 -> 0.3 | U24: 6 | V24: =E20/$W$18 -> 9620.9071 | W24: =E20/V24 -> 2319.0455 | X24: =X23 -> 2 | Y24: =Y23 -> 0.7 | AD24: 10 | AE24: ='Input-Start'!N30^(1+Inflation_Rate)^Year -> 0 | AF24: =Cost_PY*(PY_for_Inf+PY!$L16)*(1+Inflation_Rate)^Year -> 6755367.3 | AG24: =AG23*(1+Inflation_Rate) -> 11229.98 | AH24: =AH23*(1+Inflation_Rate) -> 399304.43 | AM24: 10 | AN24: ='Input-Start'!W29*(1+Inflation_Rate)^Year -> 509982.67 | AO24: ='Input-Start'!X29*(1+Inflation_Rate)^'Input-Detail'!$AM24 -> 0 | AP24: =Cost_PY*(PY_for_Inf+PY!$Q16)*(1+Inflation_Rate)^$AM24 -> 3567289 | AQ24: =AQ23*(1+Inflation_Rate) -> 11229.765 | AR24: =AR23*(1+Inflation_Rate) -> 405540.21 | AW24: Configuration of the Toll Plaza | BG24: 11 | BH24: =BH$13+(BH$33-BH$13)*$D25/$D$34 -> 0.83 | BI24: =1-BH24 -> 0.17 | BJ24: =BJ$13+(BJ$33-BJ$13)*$D25/$D$34 -> 0.9235 | BK24: =1-BJ24 -> 0.0765 | BL24: =BL$13+(BL$33-BL$13)*$D25/$D$34 -> 0.64 | BM24: =1-BL24 -> 0.36 | BT24: CO | BV24: ='Input-Start'!BA25 -> 0.0063
D25: 11 | E25: =E$14+(E$34-E$14)*$D25/$D$34 -> 25057278 | F25: =F$14+(F$34-F$14)*$D25/$D$34 -> 0.5445 | L25: 7 | M25: =E21/$N$18 -> 9857.7249 | N25: =E21/M25 -> 2319.0455 | O25: =O24 -> 2 | P25: =P24 -> 0.3 | U25: 7 | V25: =E21/$W$18 -> 9857.7249 | W25: =E21/V25 -> 2319.0455 | X25: =X24 -> 2 | Y25: =Y24 -> 0.7 | AD25: 11 | AE25: ='Input-Start'!N31^(1+Inflation_Rate)^Year -> 0 | AF25: =Cost_PY*(PY_for_Inf+PY!$L17)*(1+Inflation_Rate)^Year -> 7099494 | AG25: =AG24*(1+Inflation_Rate) -> 11566.88 | AH25: =AH24*(1+Inflation_Rate) -> 411283.57 | AM25: 11 | AN25: ='Input-Start'!W30*(1+Inflation_Rate)^Year -> 0 | AO25: ='Input-Start'!X30*(1+Inflation_Rate)^'Input-Detail'!$AM25 -> 0 | AP25: =Cost_PY*(PY_for_Inf+PY!$Q17)*(1+Inflation_Rate)^$AM25 -> 3373324.5 | AQ25: =AQ24*(1+Inflation_Rate) -> 11566.658 | AR25: =AR24*(1+Inflation_Rate) -> 417706.41 | AX25: Total Number of Lanes | AZ25: ='Input-Start'!AR16 -> 12 | BG25: 12 | BH25: =BH$13+(BH$33-BH$13)*$D26/$D$34 -> 0.83 | BI25: =1-BH25 -> 0.17 | BJ25: =BJ$13+(BJ$33-BJ$13)*$D26/$D$34 -> 0.932 | BK25: =1-BJ25 -> 0.068 | BL25: =BL$13+(BL$33-BL$13)*$D26/$D$34 -> 0.64 | BM25: =1-BL25 -> 0.36
D26: 12 | E26: =E$14+(E$34-E$14)*$D26/$D$34 -> 25606469 | F26: =F$14+(F$34-F$14)*$D26/$D$34 -> 0.594 | L26: 8 | M26: =E22/$N$18 -> 10094.543 | N26: =E22/M26 -> 2319.0455 | O26: =O25 -> 2 | P26: =P25 -> 0.3 | U26: 8 | V26: =E22/$W$18 -> 10094.543 | W26: =E22/V26 -> 2319.0455 | X26: =X25 -> 2 | Y26: =Y25 -> 0.7 | AD26: 12 | AE26: ='Input-Start'!N32^(1+Inflation_Rate)^Year -> 0 | AF26: =Cost_PY*(PY_for_Inf+PY!$L18)*(1+Inflation_Rate)^Year -> 7458188.4 | AG26: =AG25*(1+Inflation_Rate) -> 11913.886 | AH26: =AH25*(1+Inflation_Rate) -> 423622.07 | AM26: 12 | AN26: ='Input-Start'!W31*(1+Inflation_Rate)^Year -> 0 | AO26: ='Input-Start'!X31*(1+Inflation_Rate)^'Input-Detail'!$AM26 -> 0 | AP26: =Cost_PY*(PY_for_Inf+PY!$Q18)*(1+Inflation_Rate)^$AM26 -> 3204600.8 | AQ26: =AQ25*(1+Inflation_Rate) -> 11913.658 | AR26: =AR25*(1+Inflation_Rate) -> 430237.61 | AX26: Ramp Distance prior to the Toll Plaza (miles) | AZ26: ='Input-Start'!AR17 -> 0.2 | BG26: 13 | BH26: =BH$13+(BH$33-BH$13)*$D27/$D$34 -> 0.83 | BI26: =1-BH26 -> 0.17 | BJ26: =BJ$13+(BJ$33-BJ$13)*$D27/$D$34 -> 0.9405 | BK26: =1-BJ26 -> 0.0595 | BL26: =BL$13+(BL$33-BL$13)*$D27/$D$34 -> 0.64 | BM26: =1-BL26 -> 0.36
D27: 13 | E27: =E$14+(E$34-E$14)*$D27/$D$34 -> 26155661 | F27: =F$14+(F$34-F$14)*$D27/$D$34 -> 0.6435 | L27: 9 | M27: =E23/$N$18 -> 10331.361 | N27: =E23/M27 -> 2319.0455 | O27: =O26 -> 2 | P27: =P26 -> 0.3 | U27: 9 | V27: =E23/$W$18 -> 10331.361 | W27: =E23/V27 -> 2319.0455 | X27: =X26 -> 2 | Y27: =Y26 -> 0.7 | AD27: 13 | AE27: ='Input-Start'!N33^(1+Inflation_Rate)^Year -> 0 | AF27: =Cost_PY*(PY_for_Inf+PY!$L19)*(1+Inflation_Rate)^Year -> 7832014.9 | AG27: =AG26*(1+Inflation_Rate) -> 12271.303 | AH27: =AH26*(1+Inflation_Rate) -> 436330.74 | AM27: 13 | AN27: ='Input-Start'!W32*(1+Inflation_Rate)^Year -> 0 | AO27: ='Input-Start'!X32*(1+Inflation_Rate)^'Input-Detail'!$AM27 -> 0 | AP27: =Cost_PY*(PY_for_Inf+PY!$Q19)*(1+Inflation_Rate)^$AM27 -> 2951709.9 | AQ27: =AQ26*(1+Inflation_Rate) -> 12271.068 | AR27: =AR26*(1+Inflation_Rate) -> 443144.73 | AX27: Ramp Distance leading from the toll Plaza (miles) | AZ27: ='Input-Start'!AR18 -> 0.2 | BG27: 14 | BH27: =BH$13+(BH$33-BH$13)*$D28/$D$34 -> 0.83 | BI27: =1-BH27 -> 0.17 | BJ27: =BJ$13+(BJ$33-BJ$13)*$D28/$D$34 -> 0.949 | BK27: =1-BJ27 -> 0.051 | BL27: =BL$13+(BL$33-BL$13)*$D28/$D$34 -> 0.64 | BM27: =1-BL27 -> 0.36 | BS27: General Assumptions
D28: 14 | E28: =E$14+(E$34-E$14)*$D28/$D$34 -> 26704852 | F28: =F$14+(F$34-F$14)*$D28/$D$34 -> 0.693 | L28: 10 | M28: =E24/$N$18 -> 10568.178 | N28: =E24/M28 -> 2319.0455 | O28: =O27 -> 2 | P28: =P27 -> 0.3 | U28: 10 | V28: =E24/$W$18 -> 10568.178 | W28: =E24/V28 -> 2319.0455 | X28: =X27 -> 2 | Y28: =Y27 -> 0.7 | AD28: 14 | AE28: ='Input-Start'!N34^(1+Inflation_Rate)^Year -> 0 | AF28: =Cost_PY*(PY_for_Inf+PY!$L20)*(1+Inflation_Rate)^Year -> 8221558.6 | AG28: =AG27*(1+Inflation_Rate) -> 12639.442 | AH28: =AH27*(1+Inflation_Rate) -> 449420.66 | AM28: 14 | AN28: ='Input-Start'!W33*(1+Inflation_Rate)^Year -> 0 | AO28: ='Input-Start'!X33*(1+Inflation_Rate)^'Input-Detail'!$AM28 -> 0 | AP28: =Cost_PY*(PY_for_Inf+PY!$Q20)*(1+Inflation_Rate)^$AM28 -> 2723291.9 | AQ28: =AQ27*(1+Inflation_Rate) -> 12639.2 | AR28: =AR27*(1+Inflation_Rate) -> 456439.08 | BG28: 15 | BH28: =BH$13+(BH$33-BH$13)*$D29/$D$34 -> 0.83 | BI28: =1-BH28 -> 0.17 | BJ28: =BJ$13+(BJ$33-BJ$13)*$D29/$D$34 -> 0.9575 | BK28: =1-BJ28 -> 0.0425 | BL28: =BL$13+(BL$33-BL$13)*$D29/$D$34 -> 0.64 | BM28: =1-BL28 -> 0.36
D29: 15 | E29: =E$14+(E$34-E$14)*$D29/$D$34 -> 27254043 | F29: =F$14+(F$34-F$14)*$D29/$D$34 -> 0.7425 | L29: 11 | M29: =E25/$N$18 -> 10804.996 | N29: =E25/M29 -> 2319.0455 | O29: =O28 -> 2 | P29: =P28 -> 0.3 | U29: 11 | V29: =E25/$W$18 -> 10804.996 | W29: =E25/V29 -> 2319.0455 | X29: =X28 -> 2 | Y29: =Y28 -> 0.7 | AD29: 15 | AE29: ='Input-Start'!N35^(1+Inflation_Rate)^Year -> 0 | AF29: =Cost_PY*(PY_for_Inf+PY!$L21)*(1+Inflation_Rate)^Year -> 8627426.2 | AG29: =AG28*(1+Inflation_Rate) -> 13018.625 | AH29: =AH28*(1+Inflation_Rate) -> 462903.28 | AM29: 15 | AN29: ='Input-Start'!W34*(1+Inflation_Rate)^Year -> 0 | AO29: ='Input-Start'!X34*(1+Inflation_Rate)^'Input-Detail'!$AM29 -> 0 | AP29: =Cost_PY*(PY_for_Inf+PY!$Q21)*(1+Inflation_Rate)^$AM29 -> 2403180.1 | AQ29: =AQ28*(1+Inflation_Rate) -> 13018.376 | AR29: =AR28*(1+Inflation_Rate) -> 470132.25 | AW29: Prevailing Travel Speed (mph) | AZ29: ='Input-Start'!AR20 -> 55 | BG29: 16 | BH29: =BH$13+(BH$33-BH$13)*$D30/$D$34 -> 0.83 | BI29: =1-BH29 -> 0.17 | BJ29: =BJ$13+(BJ$33-BJ$13)*$D30/$D$34 -> 0.966 | BK29: =1-BJ29 -> 0.034 | BL29: =BL$13+(BL$33-BL$13)*$D30/$D$34 -> 0.64 | BM29: =1-BL29 -> 0.36 | BS29: Inflation Rate | BV29: ='Input-Start'!BA30 -> 0.03
D30: 16 | E30: =E$14+(E$34-E$14)*$D30/$D$34 -> 27803235 | F30: =F$14+(F$34-F$14)*$D30/$D$34 -> 0.792 | L30: 12 | M30: =E26/$N$18 -> 11041.814 | N30: =E26/M30 -> 2319.0455 | O30: =O29 -> 2 | P30: =P29 -> 0.3 | U30: 12 | V30: =E26/$W$18 -> 11041.814 | W30: =E26/V30 -> 2319.0455 | X30: =X29 -> 2 | Y30: =Y29 -> 0.7 | AD30: 16 | AE30: ='Input-Start'!N36^(1+Inflation_Rate)^Year -> 0 | AF30: =Cost_PY*(PY_for_Inf+PY!$L22)*(1+Inflation_Rate)^Year -> 9050246.4 | AG30: =AG29*(1+Inflation_Rate) -> 13409.184 | AH30: =AH29*(1+Inflation_Rate) -> 476790.38 | AM30: 16 | AN30: ='Input-Start'!W35*(1+Inflation_Rate)^Year -> 0 | AO30: ='Input-Start'!X35*(1+Inflation_Rate)^'Input-Detail'!$AM30 -> 0 | AP30: =Cost_PY*(PY_for_Inf+PY!$Q22)*(1+Inflation_Rate)^$AM30 -> 2045174.9 | AQ30: =AQ29*(1+Inflation_Rate) -> 13408.927 | AR30: =AR29*(1+Inflation_Rate) -> 484236.22 | AW30: Mode Split among ETC Users | BG30: 17 | BH30: =BH$13+(BH$33-BH$13)*$D31/$D$34 -> 0.83 | BI30: =1-BH30 -> 0.17 | BJ30: =BJ$13+(BJ$33-BJ$13)*$D31/$D$34 -> 0.9745 | BK30: =1-BJ30 -> 0.0255 | BL30: =BL$13+(BL$33-BL$13)*$D31/$D$34 -> 0.64 | BM30: =1-BL30 -> 0.36 | BS30: Annual Interest Rate | BV30: ='Input-Start'!BA31 -> 0.05
D31: 17 | E31: =E$14+(E$34-E$14)*$D31/$D$34 -> 28352426 | F31: =F$14+(F$34-F$14)*$D31/$D$34 -> 0.8415 | L31: 13 | M31: =E27/$N$18 -> 11278.632 | N31: =E27/M31 -> 2319.0455 | O31: =O30 -> 2 | P31: =P30 -> 0.3 | U31: 13 | V31: =E27/$W$18 -> 11278.632 | W31: =E27/V31 -> 2319.0455 | X31: =X30 -> 2 | Y31: =Y30 -> 0.7 | AD31: 17 | AE31: ='Input-Start'!N37^(1+Inflation_Rate)^Year -> 0 | AF31: =Cost_PY*(PY_for_Inf+PY!$L23)*(1+Inflation_Rate)^Year -> 9490671.1 | AG31: =AG30*(1+Inflation_Rate) -> 13811.459 | AH31: =AH30*(1+Inflation_Rate) -> 491094.09 | AM31: 17 | AN31: ='Input-Start'!W36*(1+Inflation_Rate)^Year -> 0 | AO31: ='Input-Start'!X36*(1+Inflation_Rate)^'Input-Detail'!$AM31 -> 0 | AP31: =Cost_PY*(PY_for_Inf+PY!$Q23)*(1+Inflation_Rate)^$AM31 -> 1710000.8 | AQ31: =AQ30*(1+Inflation_Rate) -> 13811.195 | AR31: =AR30*(1+Inflation_Rate) -> 498763.3 | AX31: Auto | AZ31: ='Input-Start'!AR23 -> 0.9476 | BG31: 18 | BH31: =BH$13+(BH$33-BH$13)*$D32/$D$34 -> 0.83 | BI31: =1-BH31 -> 0.17 | BJ31: =BJ$13+(BJ$33-BJ$13)*$D32/$D$34 -> 0.983 | BK31: =1-BJ31 -> 0.017 | BL31: =BL$13+(BL$33-BL$13)*$D32/$D$34 -> 0.64 | BM31: =1-BL31 -> 0.36 | BS31: Discount Rate | BV31: ='Input-Start'!BA32 -> 0.02
D32: 18 | E32: =E$14+(E$34-E$14)*$D32/$D$34 -> 28901617 | F32: =F$14+(F$34-F$14)*$D32/$D$34 -> 0.891 | L32: 14 | M32: =E28/$N$18 -> 11515.45 | N32: =E28/M32 -> 2319.0455 | O32: =O31 -> 2 | P32: =P31 -> 0.3 | U32: 14 | V32: =E28/$W$18 -> 11515.45 | W32: =E28/V32 -> 2319.0455 | X32: =X31 -> 2 | Y32: =Y31 -> 0.7 | AD32: 18 | AE32: ='Input-Start'!N38^(1+Inflation_Rate)^Year -> 0 | AF32: =Cost_PY*(PY_for_Inf+PY!$L24)*(1+Inflation_Rate)^Year -> 9949376.1 | AG32: =AG31*(1+Inflation_Rate) -> 14225.803 | AH32: =AH31*(1+Inflation_Rate) -> 505826.91 | AM32: 18 | AN32: ='Input-Start'!W37*(1+Inflation_Rate)^Year -> 0 | AO32: ='Input-Start'!X37*(1+Inflation_Rate)^'Input-Detail'!$AM32 -> 0 | AP32: =Cost_PY*(PY_for_Inf+PY!$Q24)*(1+Inflation_Rate)^$AM32 -> 1270558 | AQ32: =AQ31*(1+Inflation_Rate) -> 14225.531 | AR32: =AR31*(1+Inflation_Rate) -> 513726.2 | AX32: Truck | AZ32: ='Input-Start'!AR24 -> 0.0511 | BG32: 19 | BH32: =BH$13+(BH$33-BH$13)*$D33/$D$34 -> 0.83 | BI32: =1-BH32 -> 0.17 | BJ32: =BJ$13+(BJ$33-BJ$13)*$D33/$D$34 -> 0.9915 | BK32: =1-BJ32 -> 0.0085 | BL32: =BL$13+(BL$33-BL$13)*$D33/$D$34 -> 0.64 | BM32: =1-BL32 -> 0.36 | BS32: Personal Year (PY)
D33: 19 | E33: =E$14+(E$34-E$14)*$D33/$D$34 -> 29450809 | F33: =F$14+(F$34-F$14)*$D33/$D$34 -> 0.9405 | L33: 15 | M33: =E29/$N$18 -> 11752.268 | N33: =E29/M33 -> 2319.0455 | O33: =O32 -> 2 | P33: =P32 -> 0.3 | U33: 15 | V33: =E29/$W$18 -> 11752.268 | W33: =E29/V33 -> 2319.0455 | X33: =X32 -> 2 | Y33: =Y32 -> 0.7 | AD33: 19 | AE33: ='Input-Start'!N39^(1+Inflation_Rate)^Year -> 0 | AF33: =Cost_PY*(PY_for_Inf+PY!$L25)*(1+Inflation_Rate)^Year -> 10427062 | AG33: =AG32*(1+Inflation_Rate) -> 14652.577 | AH33: =AH32*(1+Inflation_Rate) -> 521001.72 | AM33: 19 | AN33: ='Input-Start'!W38*(1+Inflation_Rate)^Year -> 0 | AO33: ='Input-Start'!X38*(1+Inflation_Rate)^'Input-Detail'!$AM33 -> 0 | AP33: =Cost_PY*(PY_for_Inf+PY!$Q25)*(1+Inflation_Rate)^$AM33 -> 785468.51 | AQ33: =AQ32*(1+Inflation_Rate) -> 14652.297 | AR33: =AR32*(1+Inflation_Rate) -> 529137.99 | AX33: Bus | AZ33: ='Input-Start'!AR25 -> 0.0013 | BG33: 20 | BH33: ='Input-Start'!AI22 -> 0.83 | BI33: =1-BH33 -> 0.17 | BJ33: ='Input-Start'!AI25 -> 1 | BK33: =1-BJ33 -> 0 | BL33: ='Input-Start'!AI28 -> 0.64 | BM33: =1-BL33 -> 0.36 | BT33: Hours per Unit Personal Year | BV33: ='Input-Start'!BA34 -> 1768
D34: 20 | E34: ='Input-Start'!G22 -> 30000000 | F34: ='Input-Start'!G23 -> 0.99 | L34: 16 | M34: =E30/$N$18 -> 11989.085 | N34: =E30/M34 -> 2319.0455 | O34: =O33 -> 2 | P34: =P33 -> 0.3 | U34: 16 | V34: =E30/$W$18 -> 11989.085 | W34: =E30/V34 -> 2319.0455 | X34: =X33 -> 2 | Y34: =Y33 -> 0.7 | AD34: 20 | AE34: ='Input-Start'!N40^(1+Inflation_Rate)^Year -> 0 | AF34: =Cost_PY*(PY_for_Inf+PY!$L26)*(1+Inflation_Rate)^Year -> 10924454 | AG34: =AG33*(1+Inflation_Rate) -> 15092.154 | AH34: =AH33*(1+Inflation_Rate) -> 536631.77 | AM34: 20 | AN34: ='Input-Start'!W39*(1+Inflation_Rate)^Year -> 0 | AO34: ='Input-Start'!X39*(1+Inflation_Rate)^'Input-Detail'!$AM34 -> 0 | AP34: =Cost_PY*(PY_for_Inf+PY!$Q26)*(1+Inflation_Rate)^$AM34 -> 182799.43 | AQ34: =AQ33*(1+Inflation_Rate) -> 15091.865 | AR34: =AR33*(1+Inflation_Rate) -> 545012.13 | AW34: Average Vehicle Occupancy | BT34: PY for Information Technology | BV34: ='Input-Start'!BA35 -> 0.11
L35: 17 | M35: =E31/$N$18 -> 12225.903 | N35: =E31/M35 -> 2319.0455 | O35: =O34 -> 2 | P35: =P34 -> 0.3 | U35: 17 | V35: =E31/$W$18 -> 12225.903 | W35: =E31/V35 -> 2319.0455 | X35: =X34 -> 2 | Y35: =Y34 -> 0.7 | AX35: Auto | AZ35: ='Input-Start'!AR27 -> 1.8 | BT35: PY for Program Costs (Toll Collection) | BV35: ='Input-Start'!BA36 -> 61.5
L36: 18 | M36: =E32/$N$18 -> 12462.721 | N36: =E32/M36 -> 2319.0455 | O36: =O35 -> 2 | P36: =P35 -> 0.3 | U36: 18 | V36: =E32/$W$18 -> 12462.721 | W36: =E32/V36 -> 2319.0455 | X36: =X35 -> 2 | Y36: =Y35 -> 0.7 | AX36: Truck | AZ36: ='Input-Start'!AR28 -> 1.1 | BT36: Unit Cost per Personal Year | BV36: ='Input-Start'!BA37 -> 65000
L37: 19 | M37: =E33/$N$18 -> 12699.539 | N37: =E33/M37 -> 2319.0455 | O37: =O36 -> 2 | P37: =P36 -> 0.3 | U37: 19 | V37: =E33/$W$18 -> 12699.539 | W37: =E33/V37 -> 2319.0455 | X37: =X36 -> 2 | Y37: =Y36 -> 0.7 | AX37: Bus | AZ37: ='Input-Start'!AR29 -> 20
L38: 20 | M38: =E34/$N$18 -> 12936.357 | N38: =E34/M38 -> 2319.0455 | O38: =O37 -> 2 | P38: =P37 -> 0.3 | U38: 20 | V38: =E34/$W$18 -> 12936.357 | W38: =E34/V38 -> 2319.0455 | X38: =X37 -> 2 | Y38: =Y37 -> 0.7 | AW38: Time Value for Each Mode ($/hr)
AX39: Auto | AZ39: ='Input-Start'!AR32 -> 12.75
AX40: Truck | AZ40: ='Input-Start'!AR33 -> 33.41
AX41: Bus (per rider) | AZ41: ='Input-Start'!AR34 -> 12.75
...

Sheet Results Summary
A2: Analytical Result: | C2: NPV1 = | D2: ='Results-Detail'!R26 -> 60859829 | E2: PVB2 = | F2: ='Results-Detail'!Q26 -> 67060995 | G2: NPC3 = | H2: ='Results-Detail'!P26 -> 6201165.9
C3: B/C4 = | D3: ='Results-Detail'!Q26/'Results-Detail'!P26 -> 10.814256 | E3: IRR5= | F3: =IRR(B13:B33) -> 0.3178927
A4: 1NPV: net present value, NPV = PVB - PVC
A5: 2PVB: present value of benefits
A6: 3PVC: present value of costs
A7: 4B/C: Total benefit over capital investment, B/C = PVB/PVC
A8: 5IRR: Internal Rate of Return
A10: y Overall Values of Benefits & Costs ($ in base year)
A11: Discount Rate: | C11: ='Input-Detail'!BV31 -> 0.02
A12: Year | B12: B-C | C12: NPV | D12: Capital Invesment | E12: PVC ($ in Base Year) | F12: DFuel Value* | G12: Dtime Value | H12: DEnv Value** | I12: DCost Reduction | J12: DOperational Revenue*** | K12: DInterest Gain | L12: Total Benefit | M12: PVB ($ in Base Year)
A13: Base | B13: =L13-D13 -> -3013979.5 | C13: =M13-E13 -> -3013979.5 | D13: ='Results-Detail'!B5 -> 3009339.7 | E13: ='Results-Detail'!C5 -> 3009339.7 | F13: ='Results-Detail'!F5 -> 0 | G13: ='Results-Detail'!G5 -> 0 | H13: ='Results-Detail'!H5 -> 0 | I13: ='Results-Detail'!I5 -> -4639.84 | J13: ='Results-Detail'!J5 -> 0 | K13: ='Results-Detail'!K5 -> 0 | L13: ='Results-Detail'!L5 -> -4639.84 | M13: ='Results-Detail'!M5 -> -4639.84
A14: 1 | B14: =L14-D14 -> 232661.25 | C14: =M14-E14 -> 228099.26 | D14: ='Results-Detail'!B6 -> 0 | E14: ='Results-Detail'!C6 -> 0 | F14: ='Results-Detail'!F6 -> 8778.3529 | G14: ='Results-Detail'!G6 -> 3338.5093 | H14: ='Results-Detail'!H6 -> 311.09272 | I14: ='Results-Detail'!I6 -> 220233.29 | J14: ='Results-Detail'!J6 -> 13897.767 | K14: ='Results-Detail'!K6 -> -13897.767 | L14: ='Results-Detail'!L6 -> 232661.25 | M14: ='Results-Detail'!M6 -> 228099.26
A15: 2 | B15: =L15-D15 -> 158447.87 | C15: =M15-E15 -> 152295.14 | D15: ='Results-Detail'!B7 -> 302158.11 | E15: ='Results-Detail'!C7 -> 290424.94 | F15: ='Results-Detail'!F7 -> 18591 | G15: ='Results-Detail'!G7 -> 12508.863 | H15: ='Results-Detail'!H7 -> 733.21246 | I15: ='Results-Detail'!I7 -> 428772.9 | J15: ='Results-Detail'!J7 -> 28575.744 | K15: ='Results-Detail'!K7 -> -28575.744 | L15: ='Results-Detail'!L7 -> 460605.98 | M15: ='Results-Detail'!M7 -> 442720.09
A16: 3 | B16: =L16-D16 -> 222516.26 | C16: =M16-E16 -> 209682.04 | D16: ='Results-Detail'!B8 -> 490176.57 | E16: ='Results-Detail'!C8 -> 461904.33 | F16: ='Results-Detail'!F8 -> 29507.327 | G16: ='Results-Detail'!G8 -> 21311.698 | H16: ='Results-Detail'!H8 -> 1191.376 | I16: ='Results-Detail'!I8 -> 660682.43 | J16: ='Results-Detail'!J8 -> 44033.928 | K16: ='Results-Detail'!K8 -> -44033.928 | L16: ='Results-Detail'!L8 -> 712692.83 | M16: ='Results-Detail'!M8 -> 671586.37
A17: 4 | B17: =L17-D17 -> 681356.37 | C17: =M17-E17 -> 629467.96 | D17: ='Results-Detail'!B9 -> 308165.44 | E17: ='Results-Detail'!C9 -> 284697.23 | F17: ='Results-Detail'!F9 -> 41600.408 | G17: ='Results-Detail'!G9 -> 28739.717 | H17: ='Results-Detail'!H9 -> 1673.6152 | I17: ='Results-Detail'!I9 -> 917508.06 | J17: ='Results-Detail'!J9 -> 60272.322 | K17: ='Results-Detail'!K9 -> -60272.322 | L17: ='Results-Detail'!L9 -> 989521.8 | M17: ='Results-Detail'!M9 -> 914165.19
A18: 5 | B18: =L18-D18 -> 1004000 | C18: =M18-E18 -> 909353.72 | D18: ='Results-Detail'!B10 -> 335688.68 | E18: ='Results-Detail'!C10 -> 304043.58 | F18: ='Results-Detail'!F10 -> 54947.178 | G18: ='Results-Detail'!G10 -> 37321.349 | H18: ='Results-Detail'!H10 -> 2217.2843 | I18: ='Results-Detail'!I10 -> 1245202.9 | J18: ='Results-Detail'!J10 -> 77290.924 | K18: ='Results-Detail'!K10 -> -77290.924 | L18: ='Results-Detail'!L10 -> 1339688.7 | M18: ='Results-Detail'!M10 -> 1213397.3
A19: 6 | B19: =L19-D19 -> 1313275.9 | C19: =M19-E19 -> 1166151.4 | D19: ='Results-Detail'!B11 -> 365422.99 | E19: ='Results-Detail'!C11 -> 324485.16 | F19: ='Results-Detail'!F11 -> 69628.615 | G19: ='Results-Detail'!G11 -> 48069.037 | H19: ='Results-Detail'!H11 -> 2841.6568 | I19: ='Results-Detail'!I11 -> 1558159.5 | J19: ='Results-Detail'!J11 -> 95089.735 | K19: ='Results-Detail'!K11 -> -95089.735 | L19: ='Results-Detail'!L11 -> 1678698.9 | M19: ='Results-Detail'!M11 -> 1490636.5
A20: 7 | B20: =L20-D20 -> 1650849.4 | C20: =M20-E20 -> 1437163.8 | D20: ='Results-Detail'!B12 -> 397533.36 | E20: ='Results-Detail'!C12 -> 346076.71 | F20: ='Results-Detail'!F12 -> 85729.925 | G20: ='Results-Detail'!G12 -> 57930.594 | H20: ='Results-Detail'!H12 -> 3505.951 | I20: ='Results-Detail'!I12 -> 1901216.3 | J20: ='Results-Detail'!J12 -> 113668.75 | K20: ='Results-Detail'!K12 -> -113668.75 | L20: ='Results-Detail'!L12 -> 2048382.8 | M20: ='Results-Detail'!M12 -> 1783240.5
A21: 8 | B21: =L21-D21 -> 2068012.4 | C21: =M21-E21 -> 1765028.6 | D21: ='Results-Detail'!B13 -> 432200.42 | E21: ='Results-Detail'!C13 -> 368878.89 | F21: ='Results-Detail'!F13 -> 103340.74 | G21: ='Results-Detail'!G13 -> 67937.569 | H21: ='Results-Detail'!H13 -> 4228.3637 | I21: ='Results-Detail'!I13 -> 2324706.1 | J21: ='Results-Detail'!J13 -> 133027.98 | K21: ='Results-Detail'!K13 -> -133027.98 | L21: ='Results-Detail'!L13 -> 2500212.8 | M21: ='Results-Detail'!M13 -> 2133907.5
A22: 9 | B22: =L22-D22 -> 2472752.3 | C22: =M22-E22 -> 2069088.5 | D22: ='Results-Detail'!B14 -> 469613.96 | E22: ='Results-Detail'!C14 -> 392951.96 | F22: ='Results-Detail'!F14 -> 122555.33 | G22: ='Results-Detail'!G14 -> 79567.611 | H22: ='Results-Detail'!H14 -> 5036.3543 | I22: ='Results-Detail'!I14 -> 2735207 | J22: ='Results-Detail'!J14 -> 153167.42 | K22: ='Results-Detail'!K14 -> -153167.42 | L22: ='Results-Detail'!L14 -> 2942366.2 | M22: ='Results-Detail'!M14 -> 2462040.5
A23: 10 | B23: =L23-D23 -> 2911728.4 | C23: =M23-E23 -> 2388631.4 | D23: ='Results-Detail'!B15 -> 509982.67 | E23: ='Results-Detail'!C15 -> 418363.41 | F23: ='Results-Detail'!F15 -> 143472.78 | G23: ='Results-Detail'!G15 -> 90498.451 | H23: ='Results-Detail'!H15 -> 5897.007 | I23: ='Results-Detail'!I15 -> 3181842.8 | J23: ='Results-Detail'!J15 -> 174087.07 | K23: ='Results-Detail'!K15 -> -174087.07 | L23: ='Results-Detail'!L15 -> 3421711 | M23: ='Results-Detail'!M15 -> 2806994.8
A24: 11 | B24: =L24-D24 -> 3995492 | C24: =M24-E24 -> 3213426.5 | D24: ='Results-Detail'!B16 -> 0 | E24: ='Results-Detail'!C16 -> 0 | F24: ='Results-Detail'!F16 -> 166197.28 | G24: ='Results-Detail'!G16 -> 102701.04 | H24: ='Results-Detail'!H16 -> 6846.8788 | I24: ='Results-Detail'!I16 -> 3719746.8 | J24: ='Results-Detail'!J16 -> 195786.92 | K24: ='Results-Detail'!K16 -> -195786.92 | L24: ='Results-Detail'!L16 -> 3995492 | M24: ='Results-Detail'!M16 -> 3213426.5
A25: 12 | B25: =L25-D25 -> 4560534 | C25: =M25-E25 -> 3595949.9 | D25: ='Results-Detail'!B17 -> 0 | E25: ='Results-Detail'!C17 -> 0 | F25: ='Results-Detail'!F17 -> 190838.29 | G25: ='Results-Detail'!G17 -> 114855.05 | H25: ='Results-Detail'!H17 -> 7868.4317 | I25: ='Results-Detail'!I17 -> 4246972.2 | J25: ='Results-Detail'!J17 -> 218266.98 | K25: ='Results-Detail'!K17 -> -218266.98 | L25: ='Results-Detail'!L17 -> 4560534 | M25: ='Results-Detail'!M17 -> 3595949.9
... A33: 20 | B33: =L33-D33 -> 11452876 | C33: =M33-E33 -> 7707457.5 | D33: ='Results-Detail'!B25 -> 0 | E33: ='Results-Detail'!C25 -> 0 | F33: ='Results-Detail'!F25 -> 472045.23 | G33: ='Results-Detail'!G25 -> 228009.63 | H33: ='Results-Detail'!H25 -> 19546.739 | I33: ='Results-Detail'!I25 -> 10733275 | J33: ='Results-Detail'!J25 -> 426195 | K33: ='Results-Detail'!K25 -> -426195 | L33: ='Results-Detail'!L25 -> 11452876 | M33: ='Results-Detail'!M25 -> 7707457.5
A34: Total | C34: =SUM(C13:C33) -> 60859829 | E34: =SUM(E13:E33) -> 6201165.9 | M34: =SUM(M13:M33) -> 67060995 | S34: b/c | T34: =C34/#REF! -> #REF!
A36: *Fuel Value is the costs reduction of purchasing fuels.
A37: ** Environmental Value is estimated by the value of reduction in fuel emission.
A38: *** Agency's operational revenue is equal to user's loss in interest gain.

Sheet Results-Detail
A2: y Total Cost Streams of Baseline and ETC | E2: y Total Benefit Streams | O2: y Total Net Benefit ($ in base year)
A3: Discount Rate: | C3: ='Input-Detail'!BV31 -> 0.02
A4: Year | B4: Capital Invesment | C4: PVC ($ in Base Year) | E4: Year | F4: DFuel Value | G4: DTime Value | H4: DEnv Value | I4: Agency Cost Reduction | J4: DOperational Revenue | K4: DInterest Gain | L4: Total Benefit | M4: PVB ($ in Base Year) | O4: Year | P4: PVC | Q4: PVB | R4: NPV
A5: Base | B5: =B31+B57+B83 -> 3009339.7 | C5: =B5/(1+Discount_Rate)^0 -> 3009339.7 | E5: Base | F5: =F57 -> 0 | G5: =G57 -> 0 | H5: =F83 -> 0 | I5: =F31 -> -4639.84 | J5: =G31 -> 0 | K5: =H57 -> 0 | L5: =SUM(F5:K5) -> -4639.84 | M5: =L5/(1+Discount_Rate)^0 -> -4639.84 | O5: Base | P5: =C5 -> 3009339.7 | Q5: =M5 -> -4639.84 | R5: =Q5-P5 -> -3013979.5
A6: 1 | B6: =B32+B58+B84 -> 0 | C6: =B6/(1+Discount_Rate)^A6 -> 0 | E6: 1 | F6: =F58 -> 8778.3529 | G6: =G58 -> 3338.5093 | H6: =F84 -> 311.09272 | I6: =F32 -> 220233.29 | J6: =G32 -> 13897.767 | K6: =H58 -> -13897.767 | L6: =SUM(F6:K6) -> 232661.25 | M6: =L6/(1+Discount_Rate)^E6 -> 228099.26 | O6: 1 | P6: =C6 -> 0 | Q6: =M6 -> 228099.26 | R6: =Q6-P6 -> 228099.26
A7: 2 | B7: =B33+B59+B85 -> 302158.11 | C7: =B7/(1+Discount_Rate)^A7 -> 290424.94 | E7: 2 | F7: =F59 -> 18591 | G7: =G59 -> 12508.863 | H7: =F85 -> 733.21246 | I7: =F33 -> 428772.9 | J7: =G33 -> 28575.744 | K7: =H59 -> -28575.744 | L7: =SUM(F7:K7) -> 460605.98 | M7: =L7/(1+Discount_Rate)^E7 -> 442720.09 | O7: 2 | P7: =C7 -> 290424.94 | Q7: =M7 -> 442720.09 | R7: =Q7-P7 -> 152295.14
A8: 3 | B8: =B34+B60+B86 -> 490176.57 | C8: =B8/(1+Discount_Rate)^A8 -> 461904.33 | E8: 3 | F8: =F60 -> 29507.327 | G8: =G60 -> 21311.698 | H8: =F86 -> 1191.376 | I8: =F34 -> 660682.43 | J8: =G34 -> 44033.928 | K8: =H60 -> -44033.928 | L8: =SUM(F8:K8) -> 712692.83 | M8: =L8/(1+Discount_Rate)^E8 -> 671586.37 | O8: 3 | P8: =C8 -> 461904.33 | Q8: =M8 -> 671586.37 | R8: =Q8-P8 -> 209682.04
A9: 4 | B9: =B35+B61+B87 -> 308165.44 | C9: =B9/(1+Discount_Rate)^A9 -> 284697.23 | E9: 4 | F9: =F61 -> 41600.408 | G9: =G61 -> 28739.717 | H9: =F87 -> 1673.6152 | I9: =F35 -> 917508.06 | J9: =G35 -> 60272.322 | K9: =H61 -> -60272.322 | L9: =SUM(F9:K9) -> 989521.8 | M9: =L9/(1+Discount_Rate)^E9 -> 914165.19 | O9: 4 | P9: =C9 -> 284697.23 | Q9: =M9 -> 914165.19 | R9: =Q9-P9 -> 629467.96
A10: 5 | B10: =B36+B62+B88 -> 335688.68 | C10: =B10/(1+Discount_Rate)^A10 -> 304043.58 | E10: 5 | F10: =F62 -> 54947.178 | G10: =G62 -> 37321.349 | H10: =F88 -> 2217.2843 | I10: =F36 -> 1245202.9 | J10: =G36 -> 77290.924 | K10: =H62 -> -77290.924 | L10: =SUM(F10:K10) -> 1339688.7 | M10: =L10/(1+Discount_Rate)^E10 -> 1213397.3 | O10: 5 | P10: =C10 -> 304043.58 | Q10: =M10 -> 1213397.3 | R10: =Q10-P10 -> 909353.72
A11: 6 | B11: =B37+B63+B89 -> 365422.99 | C11: =B11/(1+Discount_Rate)^A11 -> 324485.16 | E11: 6 | F11: =F63 -> 69628.615 | G11: =G63 -> 48069.037 | H11: =F89 -> 2841.6568 | I11: =F37 -> 1558159.5 | J11: =G37 -> 95089.735 | K11: =H63 -> -95089.735 | L11: =SUM(F11:K11) -> 1678698.9 | M11: =L11/(1+Discount_Rate)^E11 -> 1490636.5 | O11: 6 | P11: =C11 -> 324485.16 | Q11: =M11 -> 1490636.5 | R11: =Q11-P11 -> 1166151.4
A12: 7 | B12: =B38+B64+B90 -> 397533.36 | C12: =B12/(1+Discount_Rate)^A12 -> 346076.71 | E12: 7 | F12: =F64 -> 85729.925 | G12: =G64 -> 57930.594 | H12: =F90 -> 3505.951 | I12: =F38 -> 1901216.3 | J12: =G38 -> 113668.75 | K12: =H64 -> -113668.75 | L12: =SUM(F12:K12) -> 2048382.8 | M12: =L12/(1+Discount_Rate)^E12 -> 1783240.5 | O12: 7 | P12: =C12 -> 346076.71 | Q12: =M12 -> 1783240.5 | R12: =Q12-P12 -> 1437163.8
A13: 8 | B13: =B39+B65+B91 -> 432200.42 | C13: =B13/(1+Discount_Rate)^A13 -> 368878.89 | E13: 8 | F13: =F65 -> 103340.74 | G13: =G65 -> 67937.569 | H13: =F91 -> 4228.3637 | I13: =F39 -> 2324706.1 | J13: =G39 -> 133027.98 | K13: =H65 -> -133027.98 | L13: =SUM(F13:K13) -> 2500212.8 | M13: =L13/(1+Discount_Rate)^E13 -> 2133907.5 | O13: 8 | P13: =C13 -> 368878.89 | Q13: =M13 -> 2133907.5 | R13: =Q13-P13 -> 1765028.6
A14: 9 | B14: =B40+B66+B92 -> 469613.96 | C14: =B14/(1+Discount_Rate)^A14 -> 392951.96 | E14: 9 | F14: =F66 -> 122555.33 | G14: =G66 -> 79567.611 | H14: =F92 -> 5036.3543 | I14: =F40 -> 2735207 | J14: =G40 -> 153167.42 | K14: =H66 -> -153167.42 | L14: =SUM(F14:K14) -> 2942366.2 | M14: =L14/(1+Discount_Rate)^E14 -> 2462040.5 | O14: 9 | P14: =C14 -> 392951.96 | Q14: =M14 -> 2462040.5 | R14: =Q14-P14 -> 2069088.5
A15: 10 | B15: =B41+B67+B93 -> 509982.67 | C15: =B15/(1+Discount_Rate)^A15 -> 418363.41 | E15: 10 | F15: =F67 -> 143472.78 | G15: =G67 -> 90498.451 | H15: =F93 -> 5897.007 | I15: =F41 -> 3181842.8 | J15: =G41 -> 174087.07 | K15: =H67 -> -174087.07 | L15: =SUM(F15:K15) -> 3421711 | M15: =L15/(1+Discount_Rate)^E15 -> 2806994.8 | O15: 10 | P15: =C15 -> 418363.41 | Q15: =M15 -> 2806994.8 | R15: =Q15-P15 -> 2388631.4
A16: 11 | B16: =B42+B68+B94 -> 0 | C16: =B16/(1+Discount_Rate)^A16 -> 0 | E16: 11 | F16: =F68 -> 166197.28 | G16: =G68 -> 102701.04 | H16: =F94 -> 6846.8788 | I16: =F42 -> 3719746.8 | J16: =G42 -> 195786.92 | K16: =H68 -> -195786.92 | L16: =SUM(F16:K16) -> 3995492 | M16: =L16/(1+Discount_Rate)^E16 -> 3213426.5 | O16: 11 | P16: =C16 -> 0 | Q16: =M16 -> 3213426.5 | R16: =Q16-P16 -> 3213426.5
A17: 12 | B17: =B43+B69+B95 -> 0 | C17: =B17/(1+Discount_Rate)^A17 -> 0 | E17: 12 | F17: =F69 -> 190838.29 | G17: =G69 -> 114855.05 | H17: =F95 -> 7868.4317 | I17: =F43 -> 4246972.2 | J17: =G43 -> 218266.98 | K17: =H69 -> -218266.98 | L17: =SUM(F17:K17) -> 4560534 | M17: =L17/(1+Discount_Rate)^E17 -> 3595949.9 | O17: 12 | P17: =C17 -> 0 | Q17: =M17 -> 3595949.9 | R17: =Q17-P17 -> 3595949.9
... A25: 20 | B25: =B51+B77+B103 -> 0 | C25: =B25/(1+Discount_Rate)^A25 -> 0 | E25: 20 | F25: =F77 -> 472045.23 | G25: =G77 -> 228009.63 | H25: =F103 -> 19546.739 | I25: =F51 -> 10733275 | J25: =G51 -> 426195 | K25: =H77 -> -426195 | L25: =SUM(F25:K25) -> 11452876 | M25: =L25/(1+Discount_Rate)^E25 -> 7707457.5 | O25: 20 | P25: =C25 -> 0 | Q25: =M25 -> 7707457.5 | R25: =Q25-P25 -> 7707457.5
O26: Total | P26: =SUM(P5:P25) -> 6201165.9 | Q26: =SUM(Q5:Q25) -> 67060995 | R26: =SUM(R5:R25) -> 60859829
A28: a Cost Streams of Toll Agency | E28: a Benefit Streams of Toll Agency | O28: a Net Benefit of Toll Agency ($ in base year)
A30: Year | B30: Capital Investment | C30: PVC ($ in Base Year) | E30: Year | F30: Cost Reduction | G30: DOperational Revenue* | H30: Total Benefit | I30: PVB ($ in Base Year) | O30: Year | P30: PVC | Q30: PVB | R30: NPV
A31: Base | B31: ='Input-Detail'!AN14 -> 3009339.7 | C31: =B31/(1+Discount_Rate)^0 -> 3009339.7 | E31: Base | F31: ='Agency Costs Reduction'!L6 -> -4639.84 | G31: ='Interest Gain'!T6 -> 0 | H31: =SUM(F31:G31) -> -4639.84 | I31: =H31/(1+Discount_Rate)^0 -> -4639.84 | O31: Base | P31: =C31 -> 3009339.7 | Q31: =I31 -> -4639.84 | R31: =Q31-P31 -> -3013979.5
A32: 1 | B32: ='Input-Detail'!AN15 -> 0 | C32: =B32/(1+Discount_Rate)^A32 -> 0 | E32: 1 | F32: ='Agency Costs Reduction'!L7 -> 220233.29 | G32: ='Interest Gain'!T7 -> 13897.767 | H32: =SUM(F32:G32) -> 234131.06 | I32: =H32/(1+Discount_Rate)^E32 -> 229540.25 | O32: 1 | P32: =C32 -> 0 | Q32: =I32 -> 229540.25 | R32: =Q32-P32 -> 229540.25
A33: 2 | B33: ='Input-Detail'!AN16 -> 302158.11 | C33: =B33/(1+Discount_Rate)^A33 -> 290424.94 | E33: 2 | F33: ='Agency Costs Reduction'!L8 -> 428772.9 | G33: ='Interest Gain'!T8 -> 28575.744 | H33: =SUM(F33:G33) -> 457348.65 | I33: =H33/(1+Discount_Rate)^E33 -> 439589.24 | O33: 2 | P33: =C33 -> 290424.94 | Q33: =I33 -> 439589.24 | R33: =Q33-P33 -> 149164.3
A34: 3 | B34: ='Input-Detail'!AN17 -> 490176.57 | C34: =B34/(1+Discount_Rate)^A34 -> 461904.33 | E34: 3 | F34: ='Agency Costs Reduction'!L9 -> 660682.43 | G34: ='Interest Gain'!T9 -> 44033.928 | H34: =SUM(F34:G34) -> 704716.36 | I34: =H34/(1+Discount_Rate)^E34 -> 664069.97 | O34: 3 | P34: =C34 -> 461904.33 | Q34: =I34 -> 664069.97 | R34: =Q34-P34 -> 202165.64
A35: 4 | B35: ='Input-Detail'!AN18 -> 308165.44 | C35: =B35/(1+Discount_Rate)^A35 -> 284697.23 | E35: 4 | F35: ='Agency Costs Reduction'!L10 -> 917508.06 | G35: ='Interest Gain'!T10 -> 60272.322 | H35: =SUM(F35:G35) -> 977780.39 | I35: =H35/(1+Discount_Rate)^E35 -> 903317.94 | O35: 4 | P35: =C35 -> 284697.23 | Q35: =I35 -> 903317.94 | R35: =Q35-P35 -> 618620.71
A36: 5 | B36: ='Input-Detail'!AN19 -> 335688.68 | C36: =B36/(1+Discount_Rate)^A36 -> 304043.58 | E36: 5 | F36: ='Agency Costs Reduction'!L11 -> 1245202.9 | G36: ='Interest Gain'!T11 -> 77290.924 | H36: =SUM(F36:G36) -> 1322493.8 | I36: =H36/(1+Discount_Rate)^E36 -> 1197823.4 | O36: 5 | P36: =C36 -> 304043.58 | Q36: =I36 -> 1197823.4 | R36: =Q36-P36 -> 893779.78
A37: 6 | B37: ='Input-Detail'!AN20 -> 365422.99 | C37: =B37/(1+Discount_Rate)^A37 -> 324485.16 | E37: 6 | F37: ='Agency Costs Reduction'!L12 -> 1558159.5 | G37: ='Interest Gain'!T12 -> 95089.735 | H37: =SUM(F37:G37) -> 1653249.3 | I37: =H37/(1+Discount_Rate)^E37 -> 1468038 | O37: 6 | P37: =C37 -> 324485.16 | Q37: =I37 -> 1468038 | R37: =Q37-P37 -> 1143552.9
A38: 7 | B38: ='Input-Detail'!AN21 -> 397533.36 | C38: =B38/(1+Discount_Rate)^A38 -> 346076.71 | E38: 7 | F38: ='Agency Costs Reduction'!L13 -> 1901216.3 | G38: ='Interest Gain'!T13 -> 113668.75 | H38: =SUM(F38:G38) -> 2014885.1 | I38: =H38/(1+Discount_Rate)^E38 -> 1754078.7 | O38: 7 | P38: =C38 -> 346076.71 | Q38: =I38 -> 1754078.7 | R38: =Q38-P38 -> 1408002
A39: 8 | B39: ='Input-Detail'!AN22 -> 432200.42 | C39: =B39/(1+Discount_Rate)^A39 -> 368878.89 | E39: 8 | F39: ='Agency Costs Reduction'!L14 -> 2324706.1 | G39: ='Interest Gain'!T14 -> 133027.98 | H39: =SUM(F39:G39) -> 2457734.1 | I39: =H39/(1+Discount_Rate)^E39 -> 2097652.4 | O39: 8 | P39: =C39 -> 368878.89 | Q39: =I39 -> 2097652.4 | R39: =Q39-P39 -> 1728773.5
A40: 9 | B40: ='Input-Detail'!AN23 -> 469613.96 | C40: =B40/(1+Discount_Rate)^A40 -> 392951.96 | E40: 9 | F40: ='Agency Costs Reduction'!L15 -> 2735207 | G40: ='Interest Gain'!T15 -> 153167.42 | H40: =SUM(F40:G40) -> 2888374.4 | I40: =H40/(1+Discount_Rate)^E40 -> 2416862.5 | O40: 9 | P40: =C40 -> 392951.96 | Q40: =I40 -> 2416862.5 | R40: =Q40-P40 -> 2023910.5
A41: 10 | B41: ='Input-Detail'!AN24 -> 509982.67 | C41: =B41/(1+Discount_Rate)^A41 -> 418363.41 | E41: 10 | F41: ='Agency Costs Reduction'!L16 -> 3181842.8 | G41: ='Interest Gain'!T16 -> 174087.07 | H41: =SUM(F41:G41) -> 3355929.9 | I41: =H41/(1+Discount_Rate)^E41 -> 2753031.4 | O41: 10 | P41: =C41 -> 418363.41 | Q41: =I41 -> 2753031.4 | R41: =Q41-P41 -> 2334667.9
A42: 11 | B42: ='Input-Detail'!AN25 -> 0 | C42: =B42/(1+Discount_Rate)^A42 -> 0 | E42: 11 | F42: ='Agency Costs Reduction'!L17 -> 3719746.8 | G42: ='Interest Gain'!T17 -> 195786.92 | H42: =SUM(F42:G42) -> 3915533.7 | I42: =H42/(1+Discount_Rate)^E42 -> 3149119 | O42: 11 | P42: =C42 -> 0 | Q42: =I42 -> 3149119 | R42: =Q42-P42 -> 3149119
