Workbook

Sheet Input-Start
A2: 0. >> INSTRUCTION << | D2: I. | F2: TRAFFIC DATA | M2: IIa. | N2: COSTS INFORMATION--Baseline (No ETC) | V2: IIb. | W2: COSTS INFORMATION--ETC Alternative | AF2: III. | AG2: FACT OF TOLL TRANSACTION | AO2: IV. | AP2: TRAVEL AT THE TOLL PLAZA | AX2: V. | AY2: FUEL CONSUMPTION & OTHER ASSUMPTIONS
A3: This spreadsheet model is designed exclusively for benefit-cost evaluation of | C3: INSTRUCTION: | L3: INSTRUCTION: | U3: INSTRUCTION: | AE3: INSTRUCTION: | AN3: INSTRUCTION: | AW3: INSTRUCTION:
A4: Electronic Toll Collection system. | D4: In this section, You are asked to give information about annual traffic | M4: In this section, You are asked to give information about costs for baseline | V4: In this section, You are asked to give information about costs under ETC scenario. | AF4: Required Inputs - white cells | AO4: In this section, You are asked to give information about travel fact at the toll plaza | AX4: In this section, You are asked to give information about fuel consumption in
D5: volume, peak hour volume, D factor and duration of peak period and ETC | M5: operations. Costs are broken down into two categories: one-time costs and | V5: Costs are broken down into two categories: capital investment and operating costs. | AF5: If you have more information about payment split other base year and year 20, go to | AO5: Required Inputs - white cells | AX5: order to estimate the fuel reduction, and other general assumptions.
A6: Where to Start? | D6: Split both in base year and in year 20 or one of them. | M6: continuing costs. All the costs are presented in current value. | V6: All the costs are presented in current value. | AF6: Table IV, expected payment split, in sheet"Input-Details" after completing this table. | AO6: a)Ramp Distance prior to (leading from) the Toll Plaza: The distance that a vehicle | AX6: The Numbers shown in pink cells are the values from previously studies and
A7: Please start with sheet "Input-Start" and fill out all required cells. You may check | D7: If you have information in between, go to sheet "Input-Detail" table Ia, Ib, and 1c | M7: Go to sheet "Input-Detail" table IIa after completing this table if you have | V7: If you have more information, go to sheet "Input-Detail" table IIb after completing this table. | AF7: Default Values - pink cells | AO7: starts to slow down from the normal speed (to accelerate from complete stop). | AX7: used as default values to run the model. Please update it if you have
A8: "Input-Detail" and make some changes based on your own knowledge, or go to the | D8: after completing this table. | M8: detailed information regarding baseline costs. | V8: Required Inputs - white cells | AF8: The values shown in the pink cells are the default number we used previously to run | AO8: b)Prevailing Travel Speed: The travel speed in the adjacent highway sections that | AX8: different values in your case.
A9: "Results Summary" and "Results-Detail" directly to find out the analytical results. | D9: Required Inputs - white cells | M9: Required Inputs - white cells | V9: a) Capital Investment: Initial investment needed to implement ETC project | AF9: the model, please change it if you have different numbers. | AO9: is not influenced by the existence of the toll plaza.
A10: Notice that:always complete this sheet first. | D10: a) Annual Traffic Volume in Base Year as well as in Year 20: | M10: a) One-Time Costs: Costs which occur only once at a specific point of time. | V10: b) Operating Costs: Costs in order to operate the system under ETC scenario | AF10: a) Avg. Tags per Account: The ratio of the number of transponders issued over | AO10: Default Values - pink cells | AX10: Assumptions about Fuel Consumption
D11: "Annual Traffic Volume" here is defined as the number of traffic goes | M11: enter "0" if no costs incurred. | V11: 1) One-time costs: costs which occur only once at a specific point of time | AF11: over the number of accounts open. Several cars may share one account. | AO11: The numbers in pink cells are used previously to run the model, please update it
A12: Other sheets in this files are for the sake of estimation. You may want to have a | D12: through the Toll Plaza per year. | M12: b) Continuing Costs: Costs incurred every year | V12: 2) Operations/Materials Costs | AF12: b)Avg. Usage per Year: Total number of transactions divided by the total | AO12: if your case has different values . | AX12: Average Milage of Consuming one Gallon of Fuel | BA12: 25
A13: glance and get a general idea of how to get these numbers. You can refer to | D13: b) Expected ETC Split in Base Year as well as in Year 20 | M13: 1) Operations/Materials Costs | V13: 3) Others | AF13: number of accounts open. | AX13: Fuel Price per Gallon | BA13: 1.1
A14: footnotes right below the spreadsheet which provide formula and assumptions | D14: c) Peak Hour Volume (PHV) in Base Year. | M14: 2) Others | V14: Staff Costs is estimated automatically by given units of personal year needed for toll | AF14: c)Deposits: This number refers to the required deposits for transponders. | AX14: Emission Rates during Acceleration (grams/gallon)
A15: employed to proceed the clalculation. | D15: "Peak Hour Volume" here is defined as traffic volume in both direction during | M15: Staff Costs is estimated automatically by given units of personal year needed for | V15: collection and information technology, and costs per personal year. | AO15: Configuration of the Toll Plaza | AY15: Nox | BA15: 24.7
D16: the peak period. | M16: toll collection and information technology, and costs per personal year. | AF16: Transaction Time (sec) | AP16: Total Number of Lanes (max 22) | AR16: 12 | AY16: HC | BA16: 9.5
A17: q SHEET "Input-Start" | D17: d) Peak Hour Duration (T) in Base Year | V17: Year | W17: Capital Investment | X17: Operating Costs | AG17: Cash | AI17: 7 | AP17: Ramp Distance prior to the Toll Plaza (miles) | AR17: 0.2 | AY17: CO | BA17: 209
A18: In this Sheet, you are asked to give the basic information required for Benefit-Cost analysis. | D18: e) D factor (D) in Base Year - directional split | M18: Year | N18: One-Time Costs | O18: Continuing Costs: | X18: One-Time Costs | Y18: Staff | Z18: Operations/Materials | AA18: Other | AG18: Ticket | AI18: 4.5 | AP18: Ramp Distance leading from the toll Plaza (miles) | AR18: 0.2 | AX18: Emission Rates during Idling (grams/minute)
A19: Basically, you have to provide the data for Base Year as well as for Year 20. | O19: Staff | P19: Operations/Materials | Q19: Other | V19: Base | W19: 3009340 | X19: 0 | Z19: 8356 | AA19: 301760 | AG19: ETC (headway) | AI19: 2.4 | AY19: Nox | BA19: 0
A20: Then, the model estimates the numbers in between automatically by linear interpolation. | D20: Estimated Annual Traffic Volume (ATV) | M20: Base | N20: 0 | P20: 8356.16 | Q20: 297120 | V20: 1 | W20: 0 | X20: 231886.25 | AF20: Payment Split | AO20: Prevailing Travel Speed (mph) | AR20: 55 | AY20: HC | BA20: 0.15
A21: If you have more data regarding information required other than base in year and in year 20, | F21: Base Year | G21: Year 20 | M21: 1 | N21: 0 | V21: 2 | W21: 0 | X21: 244904.15 | AF21: Manual Lane-Baseline | AH21: Base Year | AI21: Year 20 | AY21: CO | BA21: 2.5
A22: enter the basic data required in this sheet first; | E22: Traffic Volume | F22: 19016173 | G22: 30000000 | M22: 2 | N22: 0 | V22: 3 | W22: 0 | X22: 257922.04 | AG22: Cash | AH22: 0.83 | AI22: 0.83 | AO22: Mode Split among ETC Users | AX22: Cost of Air Polution ($/kg of pollutant)
A23: then, go to the sheet "Input-Detail" to change the number shown in blue cells. | E23: ETC Split | F23: 0 | G23: 0.95 | M23: 3 | N23: 0 | V23: 4 | W23: 0 | X23: 270939.94 | AG23: Ticket | AH23: =1-AH22 -> 0.17 | AI23: =1-AI22 -> 0.17 | AP23: Auto | AR23: 0.9476 | AY23: Nox | BA23: 1.275
M24: 4 | N24: 0 | V24: 5 | W24: 0 | X24: 283957.83 | AF24: Manual Lane-ETC Alternative | AP24: Truck | AR24: 0.0511 | AY24: HC | BA24: 1.275
A25: q SHEET "Input-Detail" | D25: Peak Hour Statistics in Base Year | M25: 5 | N25: 0 | V25: 6 | W25: 0 | X25: 296975.72 | AG25: Cash | AH25: 0.83 | AI25: 1 | AP25: Bus | AR25: 0.0013 | AY25: CO | BA25: 0.0063
A26: In this Sheet, you you may change the numbers estimated automatically by this model based | F26: Morning | G26: Evening | M26: 6 | N26: 0 | V26: 7 | W26: 0 | X26: 309993.62 | AG26: Ticket | AH26: =1-AH25 -> 0.17 | AI26: =1-AI25 -> 0 | AO26: Average Vehicle Occupancy
A27: on the numbers you enter in "Input-Start". | E27: PHV (veh/hr) | F27: 8200 | G27: 8200 | M27: 7 | N27: 0 | V27: 8 | W27: 0 | X27: 323011.51 | AF27: ETC Lane-ETC Alternative | AP27: Auto | AR27: 1.8
E28: T (hr) | F28: 2 | G28: 2 | M28: 8 | N28: 0 | V28: 9 | W28: 0 | X28: 336029.41 | AG28: Cash, Checks | AH28: 0.64 | AI28: 0.64 | AP28: Truck | AR28: 1.1 | AX28: General Assumptions
A29: q SHEET "Results Summary" | E29: D factor | F29: 0.3 | G29: 0.7 | M29: 9 | N29: 0 | V29: 10 | W29: 0 | X29: 349047.3 | AG29: Credit Card | AH29: =1-AH28 -> 0.36 | AI29: =1-AI28 -> 0.36 | AP29: Bus | AR29: 20
A30: In this Sheet, , overall analytical results are presented as well as benefit-cost ratio and | M30: 10 | N30: 0 | V30: 11 | W30: 0 | X30: 362065.2 | AF30: ETC Account Fact | AX30: Inflation Rate | BA30: 0.03
A31: estimated internal interest rate. | M31: 11 | N31: 0 | V31: 12 | W31: 0 | X31: 375083.09 | AF31: Cash & Checks Account | AI31: Base Year | AO31: Time Value for Each Mode ($/hr) | AX31: Annual Interest Rate | BA31: 0.06
M32: 12 | N32: 0 | V32: 13 | W32: 0 | X32: 388100.99 | AG32: Avg. Tags per Accout | AI32: 1.35 | AP32: Auto | AR32: 12.75 | AX32: Discount Rate | BA32: 0.03
A33: q SHEET "Results-Detail" | M33: 13 | N33: 0 | V33: 14 | W33: 0 | X33: 401118.88 | AG33: Avg. Usage per Year | AI33: 160 | AP33: Truck | AR33: 33.41 | AX33: Personal Year (PY)
A34: In this Sheet, benefit-cost analyses are shown for Toll Agency, Users, and Community. | M34: 14 | N34: 0 | V34: 15 | W34: 0 | X34: 414136.78 | AG34: Deposits | AI34: 30 | AP34: Bus (per rider) | AR34: 12.75 | AY34: Hours per Unit Personal Year | BA34: 1768
A35: respectively. | M35: 15 | N35: 0 | V35: 16 | W35: 0 | X35: 427154.67 | AG35: Avg. Balance other than Deposit | AI35: 20 | AY35: PY for Information Technology | BA35: 0.11
M36: 16 | N36: 0 | V36: 17 | W36: 0 | X36: 440172.56 | AF36: Credit Card Account | AI36: Base Year | AY36: PY for Program Costs (Toll Collection) | BA36: 61.5
M37: 17 | N37: 0 | V37: 18 | W37: 0 | X37: 453190.46 | AG37: Avg. Tags per Accout | AI37: 1.35 | AY37: Unit Cost per Personal Year | BA37: 65000
M38: 18 | N38: 0 | V38: 19 | W38: 0 | X38: 466208.35 | AG38: Avg. Usage per Year | AI38: 160
M39: 19 | N39: 0 | V39: 20 | W39: 0 | X39: 479226.25 | AG39: Deposits | AI39: 0
M40: 20 | N40: 0 | AG40: Avg. Balance other than Deposit | AI40: 20

Sheet Input-Detail
C2: Ia. | D2: TRAFFIC DATA - Annual | L2: Ib. | M2: TRAFFIC DATA - Morning Peak | U2: Ic. | V2: TRAFFIC DATA - Evening Peak | AD2: IIa. | AE2: COSTS INFORMATION--Baseline (No ETC) | AM2: IIa. | AN2: COSTS INFORMATION--ETC Alternative | AW2: III. | AX2: FACT OF TOLL TRANSACTION & Travel at Toll Plaza | BF2: IV. | BI2: EXPECTED PAYMENT SPLIT | BS2: V. | BT2: FUEL CONSUMPTION & OTHER ASSUMPTIONS
B3: INSTRUCTION: | K3: INSTRUCTION: | T3: INSTRUCTION: | AC3: INSTRUCTION: | AL3: INSTRUCTION: | AV3: INSTRUCTION: | BE3: INSTRUCTION: | BR3: INSTRUCTION:
C4: Change the numbers in blue cells only - | L4: Change the numbers in blue cells only - | U4: Change the numbers in blue cells only - | AD4: Change the numbers in blue cells only - | AM4: Change the numbers in blue cells only - | AW4: The values shown in pink cells are the default number we used to run the model. | BF4: Change the numbers in blue cells only - | BS4: The values shown in pink cells are the default number we used to run the model.
C5: The data in Base Year and Year 20 you enter in sheet "Input-Start" are | L5: The data in Base Year and Year 20 you enter in sheet "Input-Start" are | U5: The data in Base Year and Year 20 you enter in sheet "Input-Start" are | AD5: The data in Base Year and Year 20 you enter in sheet "Input-Start" are shown | AM5: The data in Base Year and Year 20 you enter in sheet "Input-Start" are | AW5: The numbers in white cells are those you entered in Table III &IV in "Input-Start" Sheet. | BF5: the numbers in white cells are those you entered in "Input-Start" Sheet about . | BS5: The numbers in white cells are those you entered in Table V in "Input-Start" Sheet.
C6: shown on white cells. | L6: shown on white cells. | U6: shown on white cells. | AD6: on white cells after inflation effect. That is, the number show on this table | AM6: shown on white cells after inflation effect. That is, the number show on this | AW6: You can not make any change here. | BF6: payment split among Manual Users as well as among ETC Users. | BS6: You can not make any change here.
C7: Based on these data, the model estimated automatically annual traffic volume | L7: Based on these data, the model estimated automatically peak hour traffic | U7: Based on these data, the model estimated automatically peak hour traffic | AD7: are no longer current value but nominal value in year i. | AM7: table are no longer current value but nominal value. | AW7: If you would like to make any change, go back to the sheet "Input-Start". | BS7: If you would like to make any change, go back to the sheet "Input-Start".
C8: and ETC Split in between by interpolation. | L8: volume, duration of peak period, and D factor for each year. | U8: volume, duration of peak period, and D factor. | AD8: Based on these data, the model estimates continuing costs automatically. | AM8: Based on these data, the model estimated continuing cost automatically. | BF8: Payment Split
C9: Please make reasonable adjustions in blue cells. | L9: a) Peak Hour Volume (PHV): assume that ATV/PHV remains constant over | U9: a) Peak Hour Volume (PHV) - assume that ATV/PHV remains constant over | AD9: For the knowledge of estimation, check the footnote right below the table. | AM9: For the knowledge of estimation, check the footnote right below the table. | AW9: Transaction Time (sec) | BS9: Assumptions about Fuel Consumption
L10: the analysis period. Thus, peak hour volume in year i is estimated by | U10: the analysis period. Thus, peak hour volume in year i is estimated by | AD10: Please make reasonable adjustions in blue cells. | AM10: Please make reasonable adjustions in blue cells. | AX10: Cash | AZ10: ='Input-Start'!AI17 -> 7 | BG10: Year | BH10: Baseline | BJ10: ETC Alternative
C11: Estimated Annual Traffic Volume (ATV) | L11: estimated annual traffic volume times ATV/PHV. | U11: estimated annual traffic volume times ATV/PHV. | AX11: Ticket | AZ11: ='Input-Start'!AI18 -> 4.5 | BH11: Manual Users | BJ11: Manual Users | BL11: ETC Users | BS11: Average Milage of Consuming one Gallon of Fuel | BV11: ='Input-Start'!BA12 -> 25
L12: b) ATV/PHV - the ratio of annual traffic volume over peak hour volume. | U12: b) ATV/PHV - the ratio of annual traffic volume over peak hour volume. | AD12: Year | AE12: One-Time Costs | AF12: Continuing Costs: | AM12: Year | AN12: Capital Investment | AO12: Continuing Costs: | AX12: ETC (headway) | AZ12: ='Input-Start'!AI19 -> 2.4 | BH12: Cash | BI12: Ticket | BJ12: Cash | BK12: Ticket | BL12: Cash &Checks | BM12: Credit Card | BS12: Fuel Price per Gallon | BV12: ='Input-Start'!BA13 -> 1.1
D13: Year | E13: Traffic Vol. | F13: ETC Split | L13: c) Duration of Peak Period (T) in the morning peak in Based Year, hrs/day. | U13: c) Duration of Peak Period (T) in the evening peak in Based Year, hrs/day | AF13: Staff* | AG13: Operations/Materials | AH13: Other | AO13: One-Time Costs | AP13: Staff | AQ13: Operations/Materials | AR13: Other | AW13: ETC Account Fact | BG13: Base | BH13: ='Input-Start'!AH22 -> 0.83 | BI13: =1-BH13 -> 0.17 | BJ13: ='Input-Start'!AH25 -> 0.83 | BK13: =1-BJ13 -> 0.17 | BL13: ='Input-Start'!AH28 -> 0.64 | BM13: =1-BL13 -> 0.36 | BS13: Emission Rates during Acceleration (grams/gallon)
D14: Base | E14: ='Input-Start'!F22 -> 19016173 | F14: ='Input-Start'!F23 -> 0 | L14: d) Direction Factor (D) during the morning peak in Base Year | U14: d) Direction Factor (D) during the evening peak in Base Year | AD14: Base | AE14: ='Input-Start'!N20 -> 0 | AF14: =Cost_PY*('Input-Start'!BA36+PY_for_Inf) -> 4004650 | AG14: 8356.16 | AH14: 297120 | AM14: Base | AN14: ='Input-Start'!W19 -> 3009340 | AO14: ='Input-Start'!X19 -> 0 | AP14: =Cost_PY*('Input-Start'!BA36+PY_for_Inf) -> 4004650 | AQ14: 8356.16 | AR14: 301760 | AW14: Cash & Checks | BG14: 1 | BH14: =BH$13+(BH$33-BH$13)*$D15/$D$34 -> 0.83 | BI14: =1-BH14 -> 0.17 | BJ14: =BJ$13+(BJ$33-BJ$13)*$D15/$D$34 -> 0.8385 | BK14: =1-BJ14 -> 0.1615 | BL14: =BL$13+(BL$33-BL$13)*$D15/$D$34 -> 0.64 | BM14: =1-BL14 -> 0.36 | BT14: Nox | BV14: ='Input-Start'!BA15 -> 24.7
D15: 1 | E15: =E$14+(E$34-E$14)*$D15/$D$34 -> 19565364 | F15: 0.06 | L15: Please make reasonable adjustions in blue cells. | U15: Please make reasonable adjustions in blue cells. | AD15: 1 | AE15: ='Input-Start'!N21^(1+Inflation_Rate)^Year -> 0 | AF15: =Cost_PY*(PY_for_Inf+PY!$L7)*(1+Inflation_Rate)^Year -> 4230053.2 | AG15: 9390.3712 | AH15: 302720 | AM15: 1 | AN15: ='Input-Start'!W20*(1+Inflation_Rate)^Year -> 0 | AO15: ='Input-Start'!X20*(1+Inflation_Rate)^'Input-Detail'!$AM15 -> 238842.84 | AP15: =Cost_PY*(PY_for_Inf+PY!$Q7)*(1+Inflation_Rate)^Year -> 3965664.8 | AQ15: 9390.4 | AR15: 325760 | AX15: Avg. Tags per Accout | AZ15: ='Input-Start'!AI32 -> 1.35 | BG15: 2 | BH15: =BH$13+(BH$33-BH$13)*$D16/$D$34 -> 0.83 | BI15: =1-BH15 -> 0.17 | BJ15: =BJ$13+(BJ$33-BJ$13)*$D16/$D$34 -> 0.847 | BK15: =1-BJ15 -> 0.153 | BL15: =BL$13+(BL$33-BL$13)*$D16/$D$34 -> 0.64 | BM15: =1-BL15 -> 0.36 | BT15: HC | BV15: ='Input-Start'!BA16 -> 9.5
D16: 2 | E16: =E$14+(E$34-E$14)*$D16/$D$34 -> 20114556 | F16: 0.15 | AD16: 2 | AE16: ='Input-Start'!N22^(1+Inflation_Rate)^Year -> 0 | AF16: =Cost_PY*(PY_for_Inf+PY!$L8)*(1+Inflation_Rate)^Year -> 4465376.4 | AG16: 10586.833 | AH16: 308800 | AM16: 2 | AN16: ='Input-Start'!W21*(1+Inflation_Rate)^Year -> 0 | AO16: ='Input-Start'!X21*(1+Inflation_Rate)^'Input-Detail'!$AM16 -> 259818.81 | AP16: =Cost_PY*(PY_for_Inf+PY!$Q8)*(1+Inflation_Rate)^Year -> 3829158.8 | AQ16: 3600 | AR16: 122080 | AX16: Avg. Usage per Year | AZ16: ='Input-Start'!AI33 -> 160 | BG16: 3 | BH16: =BH$13+(BH$33-BH$13)*$D17/$D$34 -> 0.83 | BI16: =1-BH16 -> 0.17 | BJ16: =BJ$13+(BJ$33-BJ$13)*$D17/$D$34 -> 0.8555 | BK16: =1-BJ16 -> 0.1445 | BL16: =BL$13+(BL$33-BL$13)*$D17/$D$34 -> 0.64 | BM16: =1-BL16 -> 0.36 | BT16: CO | BV16: ='Input-Start'!BA17 -> 209
D17: 3 | E17: =E$14+(E$34-E$14)*$D17/$D$34 -> 20663747 | F17: 0.2 | L17: Year | M17: PHV | N17: ATV/PHV | O17: T (hr) | P17: K | U17: Year | V17: PHV | W17: ATV/PHV | X17: T (hr) | Y17: K | AD17: 3 | AE17: ='Input-Start'!N23^(1+Inflation_Rate)^Year -> 0 | AF17: =Cost_PY*(PY_for_Inf+PY!$L9)*(1+Inflation_Rate)^Year -> 4711012 | AG17: 11974.875 | AH17: 315200 | AM17: 3 | AN17: ='Input-Start'!W22*(1+Inflation_Rate)^Year -> 0 | AO17: ='Input-Start'!X22*(1+Inflation_Rate)^'Input-Detail'!$AM17 -> 281838.38 | AP17: =Cost_PY*(PY_for_Inf+PY!$Q9)*(1+Inflation_Rate)^Year -> 3828865.2 | AQ17: 3780 | AR17: 133760 | AX17: Deposits | AZ17: ='Input-Start'!AI34 -> 30 | BG17: 4 | BH17: =BH$13+(BH$33-BH$13)*$D18/$D$34 -> 0.83 | BI17: =1-BH17 -> 0.17 | BJ17: =BJ$13+(BJ$33-BJ$13)*$D18/$D$34 -> 0.864 | BK17: =1-BJ17 -> 0.136 | BL17: =BL$13+(BL$33-BL$13)*$D18/$D$34 -> 0.64 | BM17: =1-BL17 -> 0.36 | BS17: Emission Rates during Idling (grams/minute)
D18: 4 | E18: =E$14+(E$34-E$14)*$D18/$D$34 -> 21212938 | F18: 0.25 | L18: Base | M18: ='Input-Start'!F27 -> 8200 | N18: =E14/M18 -> 2319.0455 | O18: ='Input-Start'!F28 -> 2 | P18: ='Input-Start'!F29 -> 0.3 | U18: Base | V18: ='Input-Start'!G27 -> 8200 | W18: =E14/V18 -> 2319.0455 | X18: ='Input-Start'!G28 -> 2 | Y18: ='Input-Start'!G29 -> 0.7 | AD18: 4 | AE18: ='Input-Start'!N24^(1+Inflation_Rate)^Year -> 0 | AF18: =Cost_PY*(PY_for_Inf+PY!$L10)*(1+Inflation_Rate)^Year -> 4967366.8 | AG18: 13589.472 | AH18: 322240 | AM18: 4 | AN18: ='Input-Start'!W23*(1+Inflation_Rate)^Year -> 0 | AO18: ='Input-Start'!X23*(1+Inflation_Rate)^'Input-Detail'!$AM18 -> 304945.28 | AP18: =Cost_PY*(PY_for_Inf+PY!$Q10)*(1+Inflation_Rate)^Year -> 3770571.1 | AQ18: 3969.04 | AR18: 133920 | AX18: Avg. Balance other than Deposit | AZ18: ='Input-Start'!AI35 -> 20 | BG18: 5 | BH18: =BH$13+(BH$33-BH$13)*$D19/$D$34 -> 0.83 | BI18: =1-BH18 -> 0.17 | BJ18: =BJ$13+(BJ$33-BJ$13)*$D19/$D$34 -> 0.8725 | BK18: =1-BJ18 -> 0.1275 | BL18: =BL$13+(BL$33-BL$13)*$D19/$D$34 -> 0.64 | BM18: =1-BL18 -> 0.36 | BT18: Nox | BV18: ='Input-Start'!BA19 -> 0
D19: 5 | E19: =E$14+(E$34-E$14)*$D19/$D$34 -> 21762130 | F19: 0.3 | L19: 1 | M19: =E15/$N$18 -> 8436.8178 | N19: =E15/M19 -> 2319.0455 | O19: =O18 -> 2 | P19: =P18 -> 0.3 | U19: 1 | V19: =E15/$W$18 -> 8436.8178 | W19: =E15/V19 -> 2319.0455 | X19: =X18 -> 2 | Y19: =Y18 -> 0.7 | AD19: 5 | AE19: ='Input-Start'!N25^(1+Inflation_Rate)^Year -> 0 | AF19: =Cost_PY*(PY_for_Inf+PY!$L11)*(1+Inflation_Rate)^Year -> 5234863.1 | AG19: 15472.362 | AH19: 329760 | AM19: 5 | AN19: ='Input-Start'!W24*(1+Inflation_Rate)^Year -> 0 | AO19: ='Input-Start'!X24*(1+Inflation_Rate)^'Input-Detail'!$AM19 -> 329184.95 | AP19: =Cost_PY*(PY_for_Inf+PY!$Q11)*(1+Inflation_Rate)^Year -> 3737811.1 | AQ19: 4167.44 | AR19: 134080 | AW19: Credit Card | BG19: 6 | BH19: =BH$13+(BH$33-BH$13)*$D20/$D$34 -> 0.83 | BI19: =1-BH19 -> 0.17 | BJ19: =BJ$13+(BJ$33-BJ$13)*$D20/$D$34 -> 0.881 | BK19: =1-BJ19 -> 0.119 | BL19: =BL$13+(BL$33-BL$13)*$D20/$D$34 -> 0.64 | BM19: =1-BL19 -> 0.36 | BT19: HC | BV19: ='Input-Start'!BA20 -> 0.15
D20: 6 | E20: =E$14+(E$34-E$14)*$D20/$D$34 -> 22311321 | F20: 0.35 | L20: 2 | M20: =E16/$N$18 -> 8673.6357 | N20: =E16/M20 -> 2319.0455 | O20: =O19 -> 2 | P20: =P19 -> 0.3 | U20: 2 | V20: =E16/$W$18 -> 8673.6357 | W20: =E16/V20 -> 2319.0455 | X20: =X19 -> 2 | Y20: =Y19 -> 0.7 | AD20: 6 | AE20: ='Input-Start'!N26^(1+Inflation_Rate)^Year -> 0 | AF20: =Cost_PY*(PY_for_Inf+PY!$L12)*(1+Inflation_Rate)^Year -> 5513938.4 | AG20: 17673.38 | AH20: 339652.8 | AM20: 6 | AN20: ='Input-Start'!W25*(1+Inflation_Rate)^Year -> 0 | AO20: ='Input-Start'!X25*(1+Inflation_Rate)^'Input-Detail'!$AM20 -> 354604.55 | AP20: =Cost_PY*(PY_for_Inf+PY!$Q12)*(1+Inflation_Rate)^Year -> 3687489 | AQ20: 4375.812 | AR20: 138102.4 | AX20: Avg. Tags per Accout | AZ20: ='Input-Start'!AI37 -> 1.35 | BG20: 7 | BH20: =BH$13+(BH$33-BH$13)*$D21/$D$34 -> 0.83 | BI20: =1-BH20 -> 0.17 | BJ20: =BJ$13+(BJ$33-BJ$13)*$D21/$D$34 -> 0.8895 | BK20: =1-BJ20 -> 0.1105 | BL20: =BL$13+(BL$33-BL$13)*$D21/$D$34 -> 0.64 | BM20: =1-BL20 -> 0.36 | BT20: CO | BV20: ='Input-Start'!BA21 -> 2.5
D21: 7 | E21: =E$14+(E$34-E$14)*$D21/$D$34 -> 22860512 | F21: 0.4 | L21: 3 | M21: =E17/$N$18 -> 8910.4535 | N21: =E17/M21 -> 2319.0455 | O21: =O20 -> 2 | P21: =P20 -> 0.3 | U21: 3 | V21: =E17/$W$18 -> 8910.4535 | W21: =E17/V21 -> 2319.0455 | X21: =X20 -> 2 | Y21: =Y20 -> 0.7 | AD21: 7 | AE21: ='Input-Start'!N27^(1+Inflation_Rate)^Year -> 0 | AF21: =Cost_PY*(PY_for_Inf+PY!$L13)*(1+Inflation_Rate)^Year -> 5805047 | AG21: 20252.059 | AH21: 349842.38 | AM21: 7 | AN21: ='Input-Start'!W26*(1+Inflation_Rate)^Year -> 0 | AO21: ='Input-Start'!X26*(1+Inflation_Rate)^'Input-Detail'!$AM21 -> 381253.05 | AP21: =Cost_PY*(PY_for_Inf+PY!$Q13)*(1+Inflation_Rate)^Year -> 3571189.9 | AQ21: 4594.6026 | AR21: 142245.47 | AX21: Avg. Usage per Year | AZ21: ='Input-Start'!AI38 -> 160 | BG21: 8 | BH21: =BH$13+(BH$33-BH$13)*$D22/$D$34 -> 0.83 | BI21: =1-BH21 -> 0.17 | BJ21: =BJ$13+(BJ$33-BJ$13)*$D22/$D$34 -> 0.898 | BK21: =1-BJ21 -> 0.102 | BL21: =BL$13+(BL$33-BL$13)*$D22/$D$34 -> 0.64 | BM21: =1-BL21 -> 0.36 | BS21: Cost of Air Polution ($/kg of pollutant)
D22: 8 | E22: =E$14+(E$34-E$14)*$D22/$D$34 -> 23409704 | F22: 0.45 | L22: 4 | M22: =E18/$N$18 -> 9147.2714 | N22: =E18/M22 -> 2319.0455 | O22: =O21 -> 2 | P22: =P21 -> 0.3 | U22: 4 | V22: =E18/$W$18 -> 9147.2714 | W22: =E18/V22 -> 2319.0455 | X22: =X21 -> 2 | Y22: =Y21 -> 0.7 | AD22: 8 | AE22: ='Input-Start'!N28^(1+Inflation_Rate)^Year -> 0 | AF22: =Cost_PY*(PY_for_Inf+PY!$L14)*(1+Inflation_Rate)^Year -> 6108659.4 | AG22: 23279.555 | AH22: 360337.66 | AM22: 8 | AN22: ='Input-Start'!W27*(1+Inflation_Rate)^Year -> 0 | AO22: ='Input-Start'!X27*(1+Inflation_Rate)^'Input-Detail'!$AM22 -> 409181.32 | AP22: =Cost_PY*(PY_for_Inf+PY!$Q14)*(1+Inflation_Rate)^Year -> 3480083.3 | AQ22: 4824.3327 | AR22: 146512.84 | AX22: Deposits | AZ22: ='Input-Start'!AI39 -> 0 | BG22: 9 | BH22: =BH$13+(BH$33-BH$13)*$D23/$D$34 -> 0.83 | BI22: =1-BH22 -> 0.17 | BJ22: =BJ$13+(BJ$33-BJ$13)*$D23/$D$34 -> 0.9065 | BK22: =1-BJ22 -> 0.0935 | BL22: =BL$13+(BL$33-BL$13)*$D23/$D$34 -> 0.64 | BM22: =1-BL22 -> 0.36 | BT22: Nox | BV22: ='Input-Start'!BA23 -> 1.275
D23: 9 | E23: =E$14+(E$34-E$14)*$D23/$D$34 -> 23958895 | F23: 0.5 | L23: 5 | M23: =E19/$N$18 -> 9384.0892 | N23: =E19/M23 -> 2319.0455 | O23: =O22 -> 2 | P23: =P22 -> 0.3 | U23: 5 | V23: =E19/$W$18 -> 9384.0892 | W23: =E19/V23 -> 2319.0455 | X23: =X22 -> 2 | Y23: =Y22 -> 0.7 | AD23: 9 | AE23: ='Input-Start'!N29^(1+Inflation_Rate)^Year -> 0 | AF23: =Cost_PY*(PY_for_Inf+PY!$L15)*(1+Inflation_Rate)^Year -> 6425264.1 | AG23: 26840.945 | AH23: 371147.79 | AM23: 9 | AN23: ='Input-Start'!W28*(1+Inflation_Rate)^Year -> 0 | AO23: ='Input-Start'!X28*(1+Inflation_Rate)^'Input-Detail'!$AM23 -> 438442.16 | AP23: =Cost_PY*(PY_for_Inf+PY!$Q15)*(1+Inflation_Rate)^Year -> 3366961.8 | AQ23: 5065.5494 | AR23: 150908.22 | AX23: Avg. Balance other than Deposit | AZ23: ='Input-Start'!AI40 -> 20 | BG23: 10 | BH23: =BH$13+(BH$33-BH$13)*$D24/$D$34 -> 0.83 | BI23: =1-BH23 -> 0.17 | BJ23: =BJ$13+(BJ$33-BJ$13)*$D24/$D$34 -> 0.915 | BK23: =1-BJ23 -> 0.085 | BL23: =BL$13+(BL$33-BL$13)*$D24/$D$34 -> 0.64 | BM23: =1-BL23 -> 0.36 | BT23: HC | BV23: ='Input-Start'!BA24 -> 1.275
D24: 10 | E24: =E$14+(E$34-E$14)*$D24/$D$34 -> 24508086 | F24: 0.55 | L24: 6 | M24: =E20/$N$18 -> 9620.9071 | N24: =E20/M24 -> 2319.0455 | O24: =O23 -> 2 | P24: =P23 -> 0.3 | U24: 6 | V24: =E20/$W$18 -> 9620.9071 | W24: =E20/V24 -> 2319.0455 | X24: =X23 -> 2 | Y24: =Y23 -> 0.7 | AD24: 10 | AE24: ='Input-Start'!N30^(1+Inflation_Rate)^Year -> 0 | AF24: =Cost_PY*(PY_for_Inf+PY!$L16)*(1+Inflation_Rate)^Year -> 6755367.3 | AG24: 31038 | AH24: 382282.22 | AM24: 10 | AN24: ='Input-Start'!W29*(1+Inflation_Rate)^Year -> 0 | AO24: ='Input-Start'!X29*(1+Inflation_Rate)^'Input-Detail'!$AM24 -> 469090.39 | AP24: =Cost_PY*(PY_for_Inf+PY!$Q16)*(1+Inflation_Rate)^Year -> 3178801.3 | AQ24: 5318.8268 | AR24: 153494.93 | AW24: Configuration of the Toll Plaza | BG24: 11 | BH24: =BH$13+(BH$33-BH$13)*$D25/$D$34 -> 0.83 | BI24: =1-BH24 -> 0.17 | BJ24: =BJ$13+(BJ$33-BJ$13)*$D25/$D$34 -> 0.9235 | BK24: =1-BJ24 -> 0.0765 | BL24: =BL$13+(BL$33-BL$13)*$D25/$D$34 -> 0.64 | BM24: =1-BL24 -> 0.36 | BT24: CO | BV24: ='Input-Start'!BA25 -> 0.0063
D25: 11 | E25: =E$14+(E$34-E$14)*$D25/$D$34 -> 25057278 | F25: 0.6 | L25: 7 | M25: =E21/$N$18 -> 9857.7249 | N25: =E21/M25 -> 2319.0455 | O25: =O24 -> 2 | P25: =P24 -> 0.3 | U25: 7 | V25: =E21/$W$18 -> 9857.7249 | W25: =E21/V25 -> 2319.0455 | X25: =X24 -> 2 | Y25: =Y24 -> 0.7 | AD25: 11 | AE25: ='Input-Start'!N31^(1+Inflation_Rate)^Year -> 0 | AF25: =Cost_PY*(PY_for_Inf+PY!$L17)*(1+Inflation_Rate)^Year -> 7099494 | AG25: 32589.9 | AH25: 393750.69 | AM25: 11 | AN25: ='Input-Start'!W30*(1+Inflation_Rate)^Year -> 0 | AO25: ='Input-Start'!X30*(1+Inflation_Rate)^'Input-Detail'!$AM25 -> 501182.91 | AP25: =Cost_PY*(PY_for_Inf+PY!$Q17)*(1+Inflation_Rate)^Year -> 3015101 | AQ25: 5584.7682 | AR25: 158099.78 | AX25: Total Number of Lanes | AZ25: ='Input-Start'!AR16 -> 12 | BG25: 12 | BH25: =BH$13+(BH$33-BH$13)*$D26/$D$34 -> 0.83 | BI25: =1-BH25 -> 0.17 | BJ25: =BJ$13+(BJ$33-BJ$13)*$D26/$D$34 -> 0.932 | BK25: =1-BJ25 -> 0.068 | BL25: =BL$13+(BL$33-BL$13)*$D26/$D$34 -> 0.64 | BM25: =1-BL25 -> 0.36
D26: 12 | E26: =E$14+(E$34-E$14)*$D26/$D$34 -> 25606469 | F26: 0.65 | L26: 8 | M26: =E22/$N$18 -> 10094.543 | N26: =E22/M26 -> 2319.0455 | O26: =O25 -> 2 | P26: =P25 -> 0.3 | U26: 8 | V26: =E22/$W$18 -> 10094.543 | W26: =E22/V26 -> 2319.0455 | X26: =X25 -> 2 | Y26: =Y25 -> 0.7 | AD26: 12 | AE26: ='Input-Start'!N32^(1+Inflation_Rate)^Year -> 0 | AF26: =Cost_PY*(PY_for_Inf+PY!$L18)*(1+Inflation_Rate)^Year -> 7458188.4 | AG26: 34219.395 | AH26: 405563.21 | AM26: 12 | AN26: ='Input-Start'!W31*(1+Inflation_Rate)^Year -> 0 | AO26: ='Input-Start'!X31*(1+Inflation_Rate)^'Input-Detail'!$AM26 -> 534778.8 | AP26: =Cost_PY*(PY_for_Inf+PY!$Q18)*(1+Inflation_Rate)^Year -> 2769632.4 | AQ26: 5864.0066 | AR26: 162842.78 | AX26: Ramp Distance prior to the Toll Plaza (miles) | AZ26: ='Input-Start'!AR17 -> 0.2 | BG26: 13 | BH26: =BH$13+(BH$33-BH$13)*$D27/$D$34 -> 0.83 | BI26: =1-BH26 -> 0.17 | BJ26: =BJ$13+(BJ$33-BJ$13)*$D27/$D$34 -> 0.9405 | BK26: =1-BJ26 -> 0.0595 | BL26: =BL$13+(BL$33-BL$13)*$D27/$D$34 -> 0.64 | BM26: =1-BL26 -> 0.36
D27: 13 | E27: =E$14+(E$34-E$14)*$D27/$D$34 -> 26155661 | F27: 0.7 | L27: 9 | M27: =E23/$N$18 -> 10331.361 | N27: =E23/M27 -> 2319.0455 | O27: =O26 -> 2 | P27: =P26 -> 0.3 | U27: 9 | V27: =E23/$W$18 -> 10331.361 | W27: =E23/V27 -> 2319.0455 | X27: =X26 -> 2 | Y27: =Y26 -> 0.7 | AD27: 13 | AE27: ='Input-Start'!N33^(1+Inflation_Rate)^Year -> 0 | AF27: =Cost_PY*(PY_for_Inf+PY!$L19)*(1+Inflation_Rate)^Year -> 7832014.9 | AG27: 35930.365 | AH27: 417730.1 | AM27: 13 | AN27: ='Input-Start'!W32*(1+Inflation_Rate)^Year -> 0 | AO27: ='Input-Start'!X32*(1+Inflation_Rate)^'Input-Detail'!$AM27 -> 569939.38 | AP27: =Cost_PY*(PY_for_Inf+PY!$Q19)*(1+Inflation_Rate)^Year -> 2547863.9 | AQ27: 6157.2069 | AR27: 167728.06 | AX27: Ramp Distance leading from the toll Plaza (miles) | AZ27: ='Input-Start'!AR18 -> 0.2 | BG27: 14 | BH27: =BH$13+(BH$33-BH$13)*$D28/$D$34 -> 0.83 | BI27: =1-BH27 -> 0.17 | BJ27: =BJ$13+(BJ$33-BJ$13)*$D28/$D$34 -> 0.949 | BK27: =1-BJ27 -> 0.051 | BL27: =BL$13+(BL$33-BL$13)*$D28/$D$34 -> 0.64 | BM27: =1-BL27 -> 0.36 | BS27: General Assumptions
D28: 14 | E28: =E$14+(E$34-E$14)*$D28/$D$34 -> 26704852 | F28: 0.75 | L28: 10 | M28: =E24/$N$18 -> 10568.178 | N28: =E24/M28 -> 2319.0455 | O28: =O27 -> 2 | P28: =P27 -> 0.3 | U28: 10 | V28: =E24/$W$18 -> 10568.178 | W28: =E24/V28 -> 2319.0455 | X28: =X27 -> 2 | Y28: =Y27 -> 0.7 | AD28: 14 | AE28: ='Input-Start'!N34^(1+Inflation_Rate)^Year -> 0 | AF28: =Cost_PY*(PY_for_Inf+PY!$L20)*(1+Inflation_Rate)^Year -> 8221558.6 | AG28: 37726.883 | AH28: 430262.01 | AM28: 14 | AN28: ='Input-Start'!W33*(1+Inflation_Rate)^Year -> 0 | AO28: ='Input-Start'!X33*(1+Inflation_Rate)^'Input-Detail'!$AM28 -> 606728.3 | AP28: =Cost_PY*(PY_for_Inf+PY!$Q20)*(1+Inflation_Rate)^Year -> 2237003.9 | AQ28: 6465.0673 | AR28: 172759.9 | BG28: 15 | BH28: =BH$13+(BH$33-BH$13)*$D29/$D$34 -> 0.83 | BI28: =1-BH28 -> 0.17 | BJ28: =BJ$13+(BJ$33-BJ$13)*$D29/$D$34 -> 0.9575 | BK28: =1-BJ28 -> 0.0425 | BL28: =BL$13+(BL$33-BL$13)*$D29/$D$34 -> 0.64 | BM28: =1-BL28 -> 0.36
D29: 15 | E29: =E$14+(E$34-E$14)*$D29/$D$34 -> 27254043 | F29: 0.8 | L29: 11 | M29: =E25/$N$18 -> 10804.996 | N29: =E25/M29 -> 2319.0455 | O29: =O28 -> 2 | P29: =P28 -> 0.3 | U29: 11 | V29: =E25/$W$18 -> 10804.996 | W29: =E25/V29 -> 2319.0455 | X29: =X28 -> 2 | Y29: =Y28 -> 0.7 | AD29: 15 | AE29: ='Input-Start'!N35^(1+Inflation_Rate)^Year -> 0 | AF29: =Cost_PY*(PY_for_Inf+PY!$L21)*(1+Inflation_Rate)^Year -> 8627426.2 | AG29: 39613.227 | AH29: 443169.87 | AM29: 15 | AN29: ='Input-Start'!W34*(1+Inflation_Rate)^Year -> 0 | AO29: ='Input-Start'!X34*(1+Inflation_Rate)^'Input-Detail'!$AM29 -> 645211.6 | AP29: =Cost_PY*(PY_for_Inf+PY!$Q21)*(1+Inflation_Rate)^Year -> 1889277.1 | AQ29: 6788.3206 | AR29: 177942.7 | AW29: Prevailing Travel Speed (mph) | AZ29: ='Input-Start'!AR20 -> 55 | BG29: 16 | BH29: =BH$13+(BH$33-BH$13)*$D30/$D$34 -> 0.83 | BI29: =1-BH29 -> 0.17 | BJ29: =BJ$13+(BJ$33-BJ$13)*$D30/$D$34 -> 0.966 | BK29: =1-BJ29 -> 0.034 | BL29: =BL$13+(BL$33-BL$13)*$D30/$D$34 -> 0.64 | BM29: =1-BL29 -> 0.36 | BS29: Inflation Rate | BV29: ='Input-Start'!BA30 -> 0.03
D30: 16 | E30: =E$14+(E$34-E$14)*$D30/$D$34 -> 27803235 | F30: 0.85 | L30: 12 | M30: =E26/$N$18 -> 11041.814 | N30: =E26/M30 -> 2319.0455 | O30: =O29 -> 2 | P30: =P29 -> 0.3 | U30: 12 | V30: =E26/$W$18 -> 11041.814 | W30: =E26/V30 -> 2319.0455 | X30: =X29 -> 2 | Y30: =Y29 -> 0.7 | AD30: 16 | AE30: ='Input-Start'!N36^(1+Inflation_Rate)^Year -> 0 | AF30: =Cost_PY*(PY_for_Inf+PY!$L22)*(1+Inflation_Rate)^Year -> 9050246.4 | AG30: 41593.888 | AH30: 456464.96 | AM30: 16 | AN30: ='Input-Start'!W35*(1+Inflation_Rate)^Year -> 0 | AO30: ='Input-Start'!X35*(1+Inflation_Rate)^'Input-Detail'!$AM30 -> 685457.85 | AP30: =Cost_PY*(PY_for_Inf+PY!$Q22)*(1+Inflation_Rate)^Year -> 1502273.7 | AQ30: 7127.7367 | AR30: 183280.98 | AW30: Mode Split among ETC Users | BG30: 17 | BH30: =BH$13+(BH$33-BH$13)*$D31/$D$34 -> 0.83 | BI30: =1-BH30 -> 0.17 | BJ30: =BJ$13+(BJ$33-BJ$13)*$D31/$D$34 -> 0.9745 | BK30: =1-BJ30 -> 0.0255 | BL30: =BL$13+(BL$33-BL$13)*$D31/$D$34 -> 0.64 | BM30: =1-BL30 -> 0.36 | BS30: Annual Interest Rate | BV30: ='Input-Start'!BA31 -> 0.06
D31: 17 | E31: =E$14+(E$34-E$14)*$D31/$D$34 -> 28352426 | F31: 0.9 | L31: 13 | M31: =E27/$N$18 -> 11278.632 | N31: =E27/M31 -> 2319.0455 | O31: =O30 -> 2 | P31: =P30 -> 0.3 | U31: 13 | V31: =E27/$W$18 -> 11278.632 | W31: =E27/V31 -> 2319.0455 | X31: =X30 -> 2 | Y31: =Y30 -> 0.7 | AD31: 17 | AE31: ='Input-Start'!N37^(1+Inflation_Rate)^Year -> 0 | AF31: =Cost_PY*(PY_for_Inf+PY!$L23)*(1+Inflation_Rate)^Year -> 9490671.1 | AG31: 43673.583 | AH31: 470158.91 | AM31: 17 | AN31: ='Input-Start'!W36*(1+Inflation_Rate)^Year -> 0 | AO31: ='Input-Start'!X36*(1+Inflation_Rate)^'Input-Detail'!$AM31 -> 727538.18 | AP31: =Cost_PY*(PY_for_Inf+PY!$Q23)*(1+Inflation_Rate)^Year -> 1073458 | AQ31: 7484.1235 | AR31: 188779.41 | AX31: Auto | AZ31: ='Input-Start'!AR23 -> 0.9476 | BG31: 18 | BH31: =BH$13+(BH$33-BH$13)*$D32/$D$34 -> 0.83 | BI31: =1-BH31 -> 0.17 | BJ31: =BJ$13+(BJ$33-BJ$13)*$D32/$D$34 -> 0.983 | BK31: =1-BJ31 -> 0.017 | BL31: =BL$13+(BL$33-BL$13)*$D32/$D$34 -> 0.64 | BM31: =1-BL31 -> 0.36 | BS31: Discount Rate | BV31: ='Input-Start'!BA32 -> 0.03
D32: 18 | E32: =E$14+(E$34-E$14)*$D32/$D$34 -> 28901617 | F32: 0.95 | L32: 14 | M32: =E28/$N$18 -> 11515.45 | N32: =E28/M32 -> 2319.0455 | O32: =O31 -> 2 | P32: =P31 -> 0.3 | U32: 14 | V32: =E28/$W$18 -> 11515.45 | W32: =E28/V32 -> 2319.0455 | X32: =X31 -> 2 | Y32: =Y31 -> 0.7 | AD32: 18 | AE32: ='Input-Start'!N38^(1+Inflation_Rate)^Year -> 0 | AF32: =Cost_PY*(PY_for_Inf+PY!$L24)*(1+Inflation_Rate)^Year -> 9949376.1 | AG32: 45857.262 | AH32: 484263.68 | AM32: 18 | AN32: ='Input-Start'!W37*(1+Inflation_Rate)^Year -> 0 | AO32: ='Input-Start'!X37*(1+Inflation_Rate)^'Input-Detail'!$AM32 -> 771526.42 | AP32: =Cost_PY*(PY_for_Inf+PY!$Q24)*(1+Inflation_Rate)^Year -> 600162.82 | AQ32: 7858.3297 | AR32: 194442.79 | AX32: Truck | AZ32: ='Input-Start'!AR24 -> 0.0511 | BG32: 19 | BH32: =BH$13+(BH$33-BH$13)*$D33/$D$34 -> 0.83 | BI32: =1-BH32 -> 0.17 | BJ32: =BJ$13+(BJ$33-BJ$13)*$D33/$D$34 -> 0.9915 | BK32: =1-BJ32 -> 0.0085 | BL32: =BL$13+(BL$33-BL$13)*$D33/$D$34 -> 0.64 | BM32: =1-BL32 -> 0.36 | BS32: Personal Year (PY)
D33: 19 | E33: =E$14+(E$34-E$14)*$D33/$D$34 -> 29450809 | F33: 0.95 | L33: 15 | M33: =E29/$N$18 -> 11752.268 | N33: =E29/M33 -> 2319.0455 | O33: =O32 -> 2 | P33: =P32 -> 0.3 | U33: 15 | V33: =E29/$W$18 -> 11752.268 | W33: =E29/V33 -> 2319.0455 | X33: =X32 -> 2 | Y33: =Y32 -> 0.7 | AD33: 19 | AE33: ='Input-Start'!N39^(1+Inflation_Rate)^Year -> 0 | AF33: =Cost_PY*(PY_for_Inf+PY!$L25)*(1+Inflation_Rate)^Year -> 10427062 | AG33: 48150.125 | AH33: 498791.59 | AM33: 19 | AN33: ='Input-Start'!W38*(1+Inflation_Rate)^Year -> 0 | AO33: ='Input-Start'!X38*(1+Inflation_Rate)^'Input-Detail'!$AM33 -> 817499.17 | AP33: =Cost_PY*(PY_for_Inf+PY!$Q25)*(1+Inflation_Rate)^Year -> 627127.93 | AQ33: 8251.2461 | AR33: 200276.07 | AX33: Bus | AZ33: ='Input-Start'!AR25 -> 0.0013 | BG33: 20 | BH33: ='Input-Start'!AI22 -> 0.83 | BI33: =1-BH33 -> 0.17 | BJ33: ='Input-Start'!AI25 -> 1 | BK33: =1-BJ33 -> 0 | BL33: ='Input-Start'!AI28 -> 0.64 | BM33: =1-BL33 -> 0.36 | BT33: Hours per Unit Personal Year | BV33: ='Input-Start'!BA34 -> 1768
D34: 20 | E34: ='Input-Start'!G22 -> 30000000 | F34: 0.95 | L34: 16 | M34: =E30/$N$18 -> 11989.085 | N34: =E30/M34 -> 2319.0455 | O34: =O33 -> 2 | P34: =P33 -> 0.3 | U34: 16 | V34: =E30/$W$18 -> 11989.085 | W34: =E30/V34 -> 2319.0455 | X34: =X33 -> 2 | Y34: =Y33 -> 0.7 | AD34: 20 | AE34: ='Input-Start'!N40^(1+Inflation_Rate)^Year -> 0 | AF34: =Cost_PY*(PY_for_Inf+PY!$L26)*(1+Inflation_Rate)^Year -> 10924454 | AG34: 50557.631 | AH34: 513755.34 | AM34: 20 | AN34: ='Input-Start'!W39*(1+Inflation_Rate)^Year -> 0 | AO34: ='Input-Start'!X39*(1+Inflation_Rate)^'Input-Detail'!$AM34 -> 865535.91 | AP34: =Cost_PY*(PY_for_Inf+PY!$Q26)*(1+Inflation_Rate)^Year -> 655170.79 | AQ34: 8663.8085 | AR34: 206284.36 | AW34: Average Vehicle Occupancy | BT34: PY for Information Technology | BV34: ='Input-Start'!BA35 -> 0.11
L35: 17 | M35: =E31/$N$18 -> 12225.903 | N35: =E31/M35 -> 2319.0455 | O35: =O34 -> 2 | P35: =P34 -> 0.3 | U35: 17 | V35: =E31/$W$18 -> 12225.903 | W35: =E31/V35 -> 2319.0455 | X35: =X34 -> 2 | Y35: =Y34 -> 0.7 | AX35: Auto | AZ35: ='Input-Start'!AR27 -> 1.8 | BT35: PY for Program Costs (Toll Collection) | BV35: ='Input-Start'!BA36 -> 61.5
L36: 18 | M36: =E32/$N$18 -> 12462.721 | N36: =E32/M36 -> 2319.0455 | O36: =O35 -> 2 | P36: =P35 -> 0.3 | U36: 18 | V36: =E32/$W$18 -> 12462.721 | W36: =E32/V36 -> 2319.0455 | X36: =X35 -> 2 | Y36: =Y35 -> 0.7 | AX36: Truck | AZ36: ='Input-Start'!AR28 -> 1.1 | BT36: Unit Cost per Personal Year | BV36: ='Input-Start'!BA37 -> 65000
L37: 19 | M37: =E33/$N$18 -> 12699.539 | N37: =E33/M37 -> 2319.0455 | O37: =O36 -> 2 | P37: =P36 -> 0.3 | U37: 19 | V37: =E33/$W$18 -> 12699.539 | W37: =E33/V37 -> 2319.0455 | X37: =X36 -> 2 | Y37: =Y36 -> 0.7 | AX37: Bus | AZ37: ='Input-Start'!AR29 -> 20
L38: 20 | M38: =E34/$N$18 -> 12936.357 | N38: =E34/M38 -> 2319.0455 | O38: =O37 -> 2 | P38: =P37 -> 0.3 | U38: 20 | V38: =E34/$W$18 -> 12936.357 | W38: =E34/V38 -> 2319.0455 | X38: =X37 -> 2 | Y38: =Y37 -> 0.7 | AW38: Time Value for Each Mode ($/hr)
AX39: Auto | AZ39: ='Input-Start'!AR32 -> 12.75
AX40: Truck | AZ40: ='Input-Start'!AR33 -> 33.41
AX41: Bus (per rider) | AZ41: ='Input-Start'!AR34 -> 12.75
...

Sheet Results Summary
C3: y Analytical Results
C5: q For 20 years
D6: NPV1 = | E6: PVB2 = | F6: NPC3 = | G6: B/C4 = | H6: IRR5 =
C7: Overall | D7: ='Results-Detail'!S26 -> 1.0237546e+08 | E7: ='Results-Detail'!R26 -> 1.053848e+08 | F7: ='Results-Detail'!Q26 -> 3009340 | G7: =E7/F7 -> 35.019239 | H7: =IRR('Results-Detail'!P5:P25) -> 0.48438116
C8: Toll Agency | D8: ='Results-Detail'!R52 -> 55966011 | E8: ='Results-Detail'!Q52 -> 58975351 | F8: ='Results-Detail'!P52 -> 3009340 | G8: =E8/F8 -> 19.597437
C9: Users | D9: ='Results-Detail'!R78 -> 46345558 | E9: ='Results-Detail'!Q78 -> 46345558 | F9: ='Results-Detail'!P78 -> 0
C10: Community | D10: ='Results-Detail'!R104 -> 63886.949 | E10: ='Results-Detail'!Q104 -> 63886.949 | F10: ='Results-Detail'!P104 -> 0
C11: 1NPV: net present value, NPV = PVB - PVC
C12: 2PVB: present value of benefits
C13: 3PVC: present value of costs
C14: 4B/C: Total benefit over capital investment, B/C = PVB/PVC
C15: 5IRR: Internal Rate of Return
C18: q For 10 years
D20: NPV1 = | E20: PVB2 = | F20: NPC3 = | G20: B/C4 = | H20: IRR5 =
C21: Overall | D21: =SUM('Results-Detail'!S5:S15) -> 21137976 | E21: =SUM('Results-Detail'!R5:R15) -> 24147316 | F21: =SUM('Results-Detail'!Q5:Q15) -> 3009340 | G21: =E21/F21 -> 8.0241234 | H21: =IRR('Results-Detail'!P5:P15) -> 0.44574682
C22: Toll Agency | D22: =SUM('Results-Detail'!R31:R41) -> 11160310 | E22: =SUM('Results-Detail'!Q31:Q41) -> 14169650 | F22: =SUM('Results-Detail'!P31:P41) -> 3009340 | G22: =E22/F22 -> 4.7085574
C23: Users | D23: =SUM('Results-Detail'!R57:R67) -> 9960191.7 | E23: =SUM('Results-Detail'!Q57:Q67) -> 9960191.7 | F23: =SUM('Results-Detail'!P57:P67) -> 0
C24: Community | D24: =SUM('Results-Detail'!R83:R93) -> 17473.878 | E24: =SUM('Results-Detail'!Q83:Q93) -> 17473.878 | F24: =SUM('Results-Detail'!P83:P93) -> 0

Sheet Results-Detail
A2: y Total Cost Streams of Baseline and ETC | E2: y Total Benefit Streams | O2: y Total Net Benefit ($ in base year)
A3: Discount Rate: | C3: ='Input-Detail'!BV31 -> 0.03
A4: Year | B4: Capital Invesment | C4: PVC ($ in Base Year) | E4: Year | F4: DFuel Value | G4: DTime Value | H4: DEnv Value | I4: Agency Cost Reduction | J4: DOperational Revenue | K4: DInterest Gain | L4: Total Benefit | M4: PVB ($ in Base Year) | O4: Year | P4: B-C | Q4: PVC | R4: PVB | S4: NPV
A5: Base | B5: =B31+B57+B83 -> 3009340 | C5: =B5/(1+Discount_Rate)^0 -> 3009340 | E5: Base | F5: =F57 -> 0 | G5: =G57 -> 0 | H5: =F83 -> 0 | I5: =F31 -> -4640 | J5: =G31 -> 0 | K5: =H57 -> 0 | L5: =SUM(F5:K5) -> -4640 | M5: =L5/(1+Discount_Rate)^0 -> -4640 | O5: Base | P5: =L5-B5 -> -3013980 | Q5: =C5 -> 3009340 | R5: =M5 -> -4640 | S5: =R5-Q5 -> -3013980
A6: 1 | B6: =B32+B58+B84 -> 0 | C6: =B6/(1+Discount_Rate)^A6 -> 0 | E6: 1 | F6: =F58 -> 8178.3223 | G6: =G58 -> 97150.891 | H6: =F84 -> 298.93857 | I6: =F32 -> 2505.5121 | J6: =G32 -> 20214.934 | K6: =H58 -> -20214.934 | L6: =SUM(F6:K6) -> 108133.66 | M6: =L6/(1+Discount_Rate)^E6 -> 104984.14 | O6: 1 | P6: =L6-B6 -> 108133.66 | Q6: =C6 -> 0 | R6: =M6 -> 104984.14 | S6: =R6-Q6 -> 104984.14
A7: 2 | B7: =B33+B59+B85 -> 0 | C7: =B7/(1+Discount_Rate)^A7 -> 0 | E7: 2 | F7: =F59 -> 16815.769 | G7: =G59 -> 343912.54 | H7: =F85 -> 682.17609 | I7: =F33 -> 570105.61 | J7: =G33 -> 51955.897 | K7: =H59 -> -51955.897 | L7: =SUM(F7:K7) -> 931516.1 | M7: =L7/(1+Discount_Rate)^E7 -> 878043.26 | O7: 2 | P7: =L7-B7 -> 931516.1 | Q7: =C7 -> 0 | R7: =M7 -> 878043.26 | S7: =R7-Q7 -> 878043.26
A8: 3 | B8: =B34+B60+B86 -> 0 | C8: =B8/(1+Discount_Rate)^A8 -> 0 | E8: 3 | F8: =F60 -> 25912.339 | G8: =G60 -> 530377.59 | H8: =F86 -> 1043.8607 | I8: =F34 -> 789943.26 | J8: =G34 -> 71165.945 | K8: =H60 -> -71165.945 | L8: =SUM(F8:K8) -> 1347277 | M8: =L8/(1+Discount_Rate)^E8 -> 1232949.4 | O8: 3 | P8: =L8-B8 -> 1347277 | Q8: =C8 -> 0 | R8: =M8 -> 1232949.4 | S8: =R8-Q8 -> 1232949.4
A9: 4 | B9: =B35+B61+B87 -> 0 | C9: =B9/(1+Discount_Rate)^A9 -> 0 | E9: 4 | F9: =F61 -> 35468.033 | G9: =G61 -> 776598.07 | H9: =F87 -> 1442.0961 | I9: =F35 -> 1089790.8 | J9: =G35 -> 91321.7 | K9: =H61 -> -91321.7 | L9: =SUM(F9:K9) -> 1903299 | M9: =L9/(1+Discount_Rate)^E9 -> 1691056.5 | O9: 4 | P9: =L9-B9 -> 1903299 | Q9: =C9 -> 0 | R9: =M9 -> 1691056.5 | S9: =R9-Q9 -> 1691056.5
A10: 5 | B10: =B36+B62+B88 -> 0 | C10: =B10/(1+Discount_Rate)^A10 -> 0 | E10: 5 | F10: =F62 -> 45482.851 | G10: =G62 -> 1058900.8 | H10: =F88 -> 1864.1114 | I10: =F36 -> 1374851.9 | J10: =G36 -> 112423.16 | K10: =H62 -> -112423.16 | L10: =SUM(F10:K10) -> 2481099.7 | M10: =L10/(1+Discount_Rate)^E10 -> 2140218.4 | O10: 5 | P10: =L10-B10 -> 2481099.7 | Q10: =C10 -> 0 | R10: =M10 -> 2140218.4 | S10: =R10-Q10 -> 2140218.4
A11: 6 | B11: =B37+B63+B89 -> 0 | C11: =B11/(1+Discount_Rate)^A11 -> 0 | E11: 6 | F11: =F63 -> 55956.793 | G11: =G63 -> 1345197.9 | H11: =F89 -> 2294.8472 | I11: =F37 -> 1686692.9 | J11: =G37 -> 134470.33 | K11: =H63 -> -134470.33 | L11: =SUM(F11:K11) -> 3090142.4 | M11: =L11/(1+Discount_Rate)^E11 -> 2587945.6 | O11: 6 | P11: =L11-B11 -> 3090142.4 | Q11: =C11 -> 0 | R11: =M11 -> 2587945.6 | S11: =R11-Q11 -> 2587945.6
A12: 7 | B12: =B38+B64+B90 -> 0 | C12: =B12/(1+Discount_Rate)^A12 -> 0 | E12: 7 | F12: =F64 -> 66889.859 | G12: =G64 -> 1667968.7 | H12: =F90 -> 2748.1556 | I12: =F38 -> 2075858.4 | J12: =G38 -> 157463.21 | K12: =H64 -> -157463.21 | L12: =SUM(F12:K12) -> 3813465.2 | M12: =L12/(1+Discount_Rate)^E12 -> 3100696.1 | O12: 7 | P12: =L12-B12 -> 3813465.2 | Q12: =C12 -> 0 | R12: =M12 -> 3100696.1 | S12: =R12-Q12 -> 3100696.1
A13: 8 | B13: =B39+B65+B91 -> 0 | C13: =B13/(1+Discount_Rate)^A13 -> 0 | E13: 8 | F13: =F65 -> 78282.05 | G13: =G65 -> 2033817.2 | H13: =F91 -> 3225.7005 | I13: =F39 -> 2451674.9 | J13: =G39 -> 181401.79 | K13: =H65 -> -181401.79 | L13: =SUM(F13:K13) -> 4566999.8 | M13: =L13/(1+Discount_Rate)^E13 -> 3605231.8 | O13: 8 | P13: =L13-B13 -> 4566999.8 | Q13: =C13 -> 0 | R13: =M13 -> 3605231.8 | S13: =R13-Q13 -> 3605231.8
A14: 9 | B14: =B40+B66+B92 -> 0 | C14: =B14/(1+Discount_Rate)^A14 -> 0 | E14: 9 | F14: =F66 -> 90133.364 | G14: =G66 -> 2408482.7 | H14: =F92 -> 3712.6602 | I14: =F40 -> 2861875.1 | J14: =G40 -> 206286.09 | K14: =H66 -> -206286.09 | L14: =SUM(F14:K14) -> 5364203.8 | M14: =L14/(1+Discount_Rate)^E14 -> 4111215.6 | O14: 9 | P14: =L14-B14 -> 5364203.8 | Q14: =C14 -> 0 | R14: =M14 -> 4111215.6 | S14: =R14-Q14 -> 4111215.6
A15: 10 | B15: =B41+B67+B93 -> 0 | C15: =B15/(1+Discount_Rate)^A15 -> 0 | E15: 10 | F15: =F67 -> 102443.8 | G15: =G67 -> 2847232.9 | H15: =F93 -> 4230.4127 | I15: =F41 -> 3361982 | J15: =G41 -> 232116.09 | K15: =H67 -> -232116.09 | L15: =SUM(F15:K15) -> 6315889.2 | M15: =L15/(1+Discount_Rate)^E15 -> 4699614.7 | O15: 10 | P15: =L15-B15 -> 6315889.2 | Q15: =C15 -> 0 | R15: =M15 -> 4699614.7 | S15: =R15-Q15 -> 4699614.7
A16: 11 | B16: =B42+B68+B94 -> 0 | C16: =B16/(1+Discount_Rate)^A16 -> 0 | E16: 11 | F16: =F68 -> 115213.36 | G16: =G68 -> 3303460.8 | H16: =F94 -> 4759.7004 | I16: =F42 -> 3845866.1 | J16: =G42 -> 258891.79 | K16: =H68 -> -258891.79 | L16: =SUM(F16:K16) -> 7269299.9 | M16: =L16/(1+Discount_Rate)^E16 -> 5251496.9 | O16: 11 | P16: =L16-B16 -> 7269299.9 | Q16: =C16 -> 0 | R16: =M16 -> 5251496.9 | S16: =R16-Q16 -> 5251496.9
A17: 12 | B17: =B43+B69+B95 -> 0 | C17: =B17/(1+Discount_Rate)^A17 -> 0 | E17: 12 | F17: =F69 -> 128442.05 | G17: =G69 -> 3810007 | H17: =F95 -> 5312.3 | I17: =F43 -> 4424852.9 | J17: =G43 -> 286613.21 | K17: =H69 -> -286613.21 | L17: =SUM(F17:K17) -> 8368614.3 | M17: =L17/(1+Discount_Rate)^E17 -> 5869577.7 | O17: 12 | P17: =L17-B17 -> 8368614.3 | Q17: =C17 -> 0 | R17: =M17 -> 5869577.7 | S17: =R17-Q17 -> 5869577.7
... A25: 20 | B25: =B51+B77+B103 -> 0 | C25: =B25/(1+Discount_Rate)^A25 -> 0 | E25: 20 | F25: =F77 -> 250800 | G25: =G77 -> 9456912.9 | H25: =F103 -> 10382.358 | I25: =F51 -> 9753112.3 | J25: =G51 -> 490770 | K25: =H77 -> -490770 | L25: =SUM(F25:K25) -> 19471208 | M25: =L25/(1+Discount_Rate)^E25 -> 10780736 | O25: 20 | P25: =L25-B25 -> 19471208 | Q25: =C25 -> 0 | R25: =M25 -> 10780736 | S25: =R25-Q25 -> 10780736
O26: Total | Q26: =SUM(Q5:Q25) -> 3009340 | R26: =SUM(R5:R25) -> 1.053848e+08 | S26: =SUM(S5:S25) -> 1.0237546e+08
A28: a Cost Streams of Toll Agency | E28: a Benefit Streams of Toll Agency | O28: a Net Benefit of Toll Agency ($ in base year)
A30: Year | B30: Capital Investment | C30: PVC ($ in Base Year) | E30: Year | F30: Cost Reduction | G30: DOperational Revenue* | H30: Total Benefit | I30: PVB ($ in Base Year) | O30: Year | P30: PVC | Q30: PVB | R30: NPV
A31: Base | B31: ='Input-Detail'!AN14 -> 3009340 | C31: =B31/(1+Discount_Rate)^0 -> 3009340 | E31: Base | F31: ='Agency Costs Reduction'!L6 -> -4640 | G31: ='Interest Gain'!T6 -> 0 | H31: =SUM(F31:G31) -> -4640 | I31: =H31/(1+Discount_Rate)^0 -> -4640 | O31: Base | P31: =C31 -> 3009340 | Q31: =I31 -> -4640 | R31: =Q31-P31 -> -3013980
A32: 1 | B32: ='Input-Detail'!AN15 -> 0 | C32: =B32/(1+Discount_Rate)^A32 -> 0 | E32: 1 | F32: ='Agency Costs Reduction'!L7 -> 2505.5121 | G32: ='Interest Gain'!T7 -> 20214.934 | H32: =SUM(F32:G32) -> 22720.447 | I32: =H32/(1+Discount_Rate)^E32 -> 22058.686 | O32: 1 | P32: =C32 -> 0 | Q32: =I32 -> 22058.686 | R32: =Q32-P32 -> 22058.686
A33: 2 | B33: ='Input-Detail'!AN16 -> 0 | C33: =B33/(1+Discount_Rate)^A33 -> 0 | E33: 2 | F33: ='Agency Costs Reduction'!L8 -> 570105.61 | G33: ='Interest Gain'!T8 -> 51955.897 | H33: =SUM(F33:G33) -> 622061.51 | I33: =H33/(1+Discount_Rate)^E33 -> 586352.63 | O33: 2 | P33: =C33 -> 0 | Q33: =I33 -> 586352.63 | R33: =Q33-P33 -> 586352.63
A34: 3 | B34: ='Input-Detail'!AN17 -> 0 | C34: =B34/(1+Discount_Rate)^A34 -> 0 | E34: 3 | F34: ='Agency Costs Reduction'!L9 -> 789943.26 | G34: ='Interest Gain'!T9 -> 71165.945 | H34: =SUM(F34:G34) -> 861109.2 | I34: =H34/(1+Discount_Rate)^E34 -> 788036.9 | O34: 3 | P34: =C34 -> 0 | Q34: =I34 -> 788036.9 | R34: =Q34-P34 -> 788036.9
A35: 4 | B35: ='Input-Detail'!AN18 -> 0 | C35: =B35/(1+Discount_Rate)^A35 -> 0 | E35: 4 | F35: ='Agency Costs Reduction'!L10 -> 1089790.8 | G35: ='Interest Gain'!T10 -> 91321.7 | H35: =SUM(F35:G35) -> 1181112.5 | I35: =H35/(1+Discount_Rate)^E35 -> 1049403.2 | O35: 4 | P35: =C35 -> 0 | Q35: =I35 -> 1049403.2 | R35: =Q35-P35 -> 1049403.2
A36: 5 | B36: ='Input-Detail'!AN19 -> 0 | C36: =B36/(1+Discount_Rate)^A36 -> 0 | E36: 5 | F36: ='Agency Costs Reduction'!L11 -> 1374851.9 | G36: ='Interest Gain'!T11 -> 112423.16 | H36: =SUM(F36:G36) -> 1487275.1 | I36: =H36/(1+Discount_Rate)^E36 -> 1282936.6 | O36: 5 | P36: =C36 -> 0 | Q36: =I36 -> 1282936.6 | R36: =Q36-P36 -> 1282936.6
A37: 6 | B37: ='Input-Detail'!AN20 -> 0 | C37: =B37/(1+Discount_Rate)^A37 -> 0 | E37: 6 | F37: ='Agency Costs Reduction'!L12 -> 1686692.9 | G37: ='Interest Gain'!T12 -> 134470.33 | H37: =SUM(F37:G37) -> 1821163.2 | I37: =H37/(1+Discount_Rate)^E37 -> 1525195.5 | O37: 6 | P37: =C37 -> 0 | Q37: =I37 -> 1525195.5 | R37: =Q37-P37 -> 1525195.5
A38: 7 | B38: ='Input-Detail'!AN21 -> 0 | C38: =B38/(1+Discount_Rate)^A38 -> 0 | E38: 7 | F38: ='Agency Costs Reduction'!L13 -> 2075858.4 | G38: ='Interest Gain'!T13 -> 157463.21 | H38: =SUM(F38:G38) -> 2233321.6 | I38: =H38/(1+Discount_Rate)^E38 -> 1815894.8 | O38: 7 | P38: =C38 -> 0 | Q38: =I38 -> 1815894.8 | R38: =Q38-P38 -> 1815894.8
A39: 8 | B39: ='Input-Detail'!AN22 -> 0 | C39: =B39/(1+Discount_Rate)^A39 -> 0 | E39: 8 | F39: ='Agency Costs Reduction'!L14 -> 2451674.9 | G39: ='Interest Gain'!T14 -> 181401.79 | H39: =SUM(F39:G39) -> 2633076.6 | I39: =H39/(1+Discount_Rate)^E39 -> 2078575 | O39: 8 | P39: =C39 -> 0 | Q39: =I39 -> 2078575 | R39: =Q39-P39 -> 2078575
A40: 9 | B40: ='Input-Detail'!AN23 -> 0 | C40: =B40/(1+Discount_Rate)^A40 -> 0 | E40: 9 | F40: ='Agency Costs Reduction'!L15 -> 2861875.1 | G40: ='Interest Gain'!T15 -> 206286.09 | H40: =SUM(F40:G40) -> 3068161.2 | I40: =H40/(1+Discount_Rate)^E40 -> 2351490.1 | O40: 9 | P40: =C40 -> 0 | Q40: =I40 -> 2351490.1 | R40: =Q40-P40 -> 2351490.1
A41: 10 | B41: ='Input-Detail'!AN24 -> 0 | C41: =B41/(1+Discount_Rate)^A41 -> 0 | E41: 10 | F41: ='Agency Costs Reduction'!L16 -> 3361982 | G41: ='Interest Gain'!T16 -> 232116.09 | H41: =SUM(F41:G41) -> 3594098.1 | I41: =H41/(1+Discount_Rate)^E41 -> 2674346.6 | O41: 10 | P41: =C41 -> 0 | Q41: =I41 -> 2674346.6 | R41: =Q41-P41 -> 2674346.6
A42: 11 | B42: ='Input-Detail'!AN25 -> 0 | C42: =B42/(1+Discount_Rate)^A42 -> 0 | E42: 11 | F42: ='Agency Costs Reduction'!L17 -> 3845866.1 | G42: ='Interest Gain'!T17 -> 258891.79 | H42: =SUM(F42:G42) -> 4104757.8 | I42: =H42/(1+Discount_Rate)^E42 -> 2965364.4 | O42: 11 | P42: =C42 -> 0 | Q42: =I42 -> 2965364.4 | R42: =Q42-P42 -> 2965364.4
A43: 12 | B43: ='Input-Detail'!AN26 -> 0 | C43: =B43/(1+Discount_Rate)^A43 -> 0 | E43: 12 | F43: ='Agency Costs Reduction'!L18 -> 4424852.9 | G43: ='Interest Gain'!T18 -> 286613.21 | H43: =SUM(F43:G43) -> 4711466.2 | I43: =H43/(1+Discount_Rate)^E43 -> 3304527.6 | O43: 12 | P43: =C43 -> 0 | Q43: =I43 -> 3304527.6 | R43: =Q43-P43 -> 3304527.6
... A51: 20 | B51: ='Input-Detail'!AN34 -> 0 | C51: =B51/(1+Discount_Rate)^A51 -> 0 | E51: 20 | F51: ='Agency Costs Reduction'!L26 -> 9753112.3 | G51: ='Interest Gain'!T26 -> 490770 | H51: =SUM(F51:G51) -> 10243882 | I51: =H51/(1+Discount_Rate)^E51 -> 5671789.3 | O51: 20 | P51: =C51 -> 0 | Q51: =I51 -> 5671789.3 | R51: =Q51-P51 -> 5671789.3
E52: *DOperational Benefit = the amount of DInterest Gain of users | O52: Total | P52: =SUM(P31:P51) -> 3009340 | Q52: =SUM(Q31:Q51) -> 58975351 | R52: =SUM(R31:R51) -> 55966011
A54: a Cost Streams of Users | E54: a Benefit Streams of Users | O54: a Net Benefit of Users ($ in base year)
A56: Year | B56: Capital Investment | C56: PVC ($ in Base Year) | E56: Year | F56: DFuel Value | G56: DTime Value | H56: DInterest Gain | I56: DTotal | J56: PVB ($ in Base Year) | O56: Year | P56: PVC | Q56: PVB | R56: NPV
A57: Base | B57: 0 | C57: =B57/(1+Discount_Rate)^0 -> 0 | E57: Base | F57: ='Fuel & Emission'!O6 -> 0 | G57: ='Time Value'!P6 -> 0 | H57: =(-1)*'Interest Gain'!T6 -> 0 | I57: =SUM(F57:H57) -> 0 | J57: =I57/(1+Discount_Rate)^0 -> 0 | O57: Base | P57: =C57 -> 0 | Q57: =J57 -> 0 | R57: =Q57-P57 -> 0
A58: 1 | B58: 0 | C58: =B58/(1+Discount_Rate)^A58 -> 0 | E58: 1 | F58: ='Fuel & Emission'!O7 -> 8178.3223 | G58: ='Time Value'!P7 -> 97150.891 | H58: =(-1)*'Interest Gain'!T7 -> -20214.934 | I58: =SUM(F58:H58) -> 85114.279 | J58: =I58/(1+Discount_Rate)^E58 -> 82635.222 | O58: 1 | P58: =C58 -> 0 | Q58: =J58 -> 82635.222 | R58: =Q58-P58 -> 82635.222
A59: 2 | B59: 0 | C59: =B59/(1+Discount_Rate)^A59 -> 0 | E59: 2 | F59: ='Fuel & Emission'!O8 -> 16815.769 | G59: ='Time Value'!P8 -> 343912.54 | H59: =(-1)*'Interest Gain'!T8 -> -51955.897 | I59: =SUM(F59:H59) -> 308772.41 | J59: =I59/(1+Discount_Rate)^E59 -> 291047.61 | O59: 2 | P59: =C59 -> 0 | Q59: =J59 -> 291047.61 | R59: =Q59-P59 -> 291047.61
...

Sheet Agency Costs Reduction
F2: y Reduction of Operating Costs
A4: Year | B4: Baseline | G4: ETC Alternative | L4: Cost Saving
B5: One-Time | C5: Staff | D5: Operations/Materials | E5: Others | F5: Total | G5: One-Time | H5: Staff | I5: Operations/Materials | J5: Others | K5: Total
A6: Base | B6: ='Input-Detail'!AE14 -> 0 | C6: ='Input-Detail'!AF14 -> 4004650 | D6: ='Input-Detail'!AG14 -> 8356.16 | E6: ='Input-Detail'!AH14 -> 297120 | F6: =SUM(B6:E6) -> 4310126.2 | G6: ='Input-Detail'!AO14 -> 0 | H6: ='Input-Detail'!AP14 -> 4004650 | I6: ='Input-Detail'!AQ14 -> 8356.16 | J6: ='Input-Detail'!AR14 -> 301760 | K6: =SUM(G6:J6) -> 4314766.2 | L6: =F6-K6 -> -4640
A7: 1 | B7: ='Input-Detail'!AE15 -> 0 | C7: ='Input-Detail'!AF15 -> 4230053.2 | D7: ='Input-Detail'!AG15 -> 9390.3712 | E7: ='Input-Detail'!AH15 -> 302720 | F7: =SUM(B7:E7) -> 4542163.6 | G7: ='Input-Detail'!AO15 -> 238842.84 | H7: ='Input-Detail'!AP15 -> 3965664.8 | I7: ='Input-Detail'!AQ15 -> 9390.4 | J7: ='Input-Detail'!AR15 -> 325760 | K7: =SUM(G7:J7) -> 4539658.1 | L7: =F7-K7 -> 2505.5121
A8: 2 | B8: ='Input-Detail'!AE16 -> 0 | C8: ='Input-Detail'!AF16 -> 4465376.4 | D8: ='Input-Detail'!AG16 -> 10586.833 | E8: ='Input-Detail'!AH16 -> 308800 | F8: =SUM(B8:E8) -> 4784763.3 | G8: ='Input-Detail'!AO16 -> 259818.81 | H8: ='Input-Detail'!AP16 -> 3829158.8 | I8: ='Input-Detail'!AQ16 -> 3600 | J8: ='Input-Detail'!AR16 -> 122080 | K8: =SUM(G8:J8) -> 4214657.6 | L8: =F8-K8 -> 570105.61
A9: 3 | B9: ='Input-Detail'!AE17 -> 0 | C9: ='Input-Detail'!AF17 -> 4711012 | D9: ='Input-Detail'!AG17 -> 11974.875 | E9: ='Input-Detail'!AH17 -> 315200 | F9: =SUM(B9:E9) -> 5038186.8 | G9: ='Input-Detail'!AO17 -> 281838.38 | H9: ='Input-Detail'!AP17 -> 3828865.2 | I9: ='Input-Detail'!AQ17 -> 3780 | J9: ='Input-Detail'!AR17 -> 133760 | K9: =SUM(G9:J9) -> 4248243.6 | L9: =F9-K9 -> 789943.26
A10: 4 | B10: ='Input-Detail'!AE18 -> 0 | C10: ='Input-Detail'!AF18 -> 4967366.8 | D10: ='Input-Detail'!AG18 -> 13589.472 | E10: ='Input-Detail'!AH18 -> 322240 | F10: =SUM(B10:E10) -> 5303196.3 | G10: ='Input-Detail'!AO18 -> 304945.28 | H10: ='Input-Detail'!AP18 -> 3770571.1 | I10: ='Input-Detail'!AQ18 -> 3969.04 | J10: ='Input-Detail'!AR18 -> 133920 | K10: =SUM(G10:J10) -> 4213405.5 | L10: =F10-K10 -> 1089790.8
A11: 5 | B11: ='Input-Detail'!AE19 -> 0 | C11: ='Input-Detail'!AF19 -> 5234863.1 | D11: ='Input-Detail'!AG19 -> 15472.362 | E11: ='Input-Detail'!AH19 -> 329760 | F11: =SUM(B11:E11) -> 5580095.4 | G11: ='Input-Detail'!AO19 -> 329184.95 | H11: ='Input-Detail'!AP19 -> 3737811.1 | I11: ='Input-Detail'!AQ19 -> 4167.44 | J11: ='Input-Detail'!AR19 -> 134080 | K11: =SUM(G11:J11) -> 4205243.5 | L11: =F11-K11 -> 1374851.9
A12: 6 | B12: ='Input-Detail'!AE20 -> 0 | C12: ='Input-Detail'!AF20 -> 5513938.4 | D12: ='Input-Detail'!AG20 -> 17673.38 | E12: ='Input-Detail'!AH20 -> 339652.8 | F12: =SUM(B12:E12) -> 5871264.6 | G12: ='Input-Detail'!AO20 -> 354604.55 | H12: ='Input-Detail'!AP20 -> 3687489 | I12: ='Input-Detail'!AQ20 -> 4375.812 | J12: ='Input-Detail'!AR20 -> 138102.4 | K12: =SUM(G12:J12) -> 4184571.7 | L12: =F12-K12 -> 1686692.9
A13: 7 | B13: ='Input-Detail'!AE21 -> 0 | C13: ='Input-Detail'!AF21 -> 5805047 | D13: ='Input-Detail'!AG21 -> 20252.059 | E13: ='Input-Detail'!AH21 -> 349842.38 | F13: =SUM(B13:E13) -> 6175141.4 | G13: ='Input-Detail'!AO21 -> 381253.05 | H13: ='Input-Detail'!AP21 -> 3571189.9 | I13: ='Input-Detail'!AQ21 -> 4594.6026 | J13: ='Input-Detail'!AR21 -> 142245.47 | K13: =SUM(G13:J13) -> 4099283 | L13: =F13-K13 -> 2075858.4
A14: 8 | B14: ='Input-Detail'!AE22 -> 0 | C14: ='Input-Detail'!AF22 -> 6108659.4 | D14: ='Input-Detail'!AG22 -> 23279.555 | E14: ='Input-Detail'!AH22 -> 360337.66 | F14: =SUM(B14:E14) -> 6492276.7 | G14: ='Input-Detail'!AO22 -> 409181.32 | H14: ='Input-Detail'!AP22 -> 3480083.3 | I14: ='Input-Detail'!AQ22 -> 4824.3327 | J14: ='Input-Detail'!AR22 -> 146512.84 | K14: =SUM(G14:J14) -> 4040601.8 | L14: =F14-K14 -> 2451674.9
A15: 9 | B15: ='Input-Detail'!AE23 -> 0 | C15: ='Input-Detail'!AF23 -> 6425264.1 | D15: ='Input-Detail'!AG23 -> 26840.945 | E15: ='Input-Detail'!AH23 -> 371147.79 | F15: =SUM(B15:E15) -> 6823252.9 | G15: ='Input-Detail'!AO23 -> 438442.16 | H15: ='Input-Detail'!AP23 -> 3366961.8 | I15: ='Input-Detail'!AQ23 -> 5065.5494 | J15: ='Input-Detail'!AR23 -> 150908.22 | K15: =SUM(G15:J15) -> 3961377.7 | L15: =F15-K15 -> 2861875.1
A16: 10 | B16: ='Input-Detail'!AE24 -> 0 | C16: ='Input-Detail'!AF24 -> 6755367.3 | D16: ='Input-Detail'!AG24 -> 31038 | E16: ='Input-Detail'!AH24 -> 382282.22 | F16: =SUM(B16:E16) -> 7168687.5 | G16: ='Input-Detail'!AO24 -> 469090.39 | H16: ='Input-Detail'!AP24 -> 3178801.3 | I16: ='Input-Detail'!AQ24 -> 5318.8268 | J16: ='Input-Detail'!AR24 -> 153494.93 | K16: =SUM(G16:J16) -> 3806705.5 | L16: =F16-K16 -> 3361982
A17: 11 | B17: ='Input-Detail'!AE25 -> 0 | C17: ='Input-Detail'!AF25 -> 7099494 | D17: ='Input-Detail'!AG25 -> 32589.9 | E17: ='Input-Detail'!AH25 -> 393750.69 | F17: =SUM(B17:E17) -> 7525834.5 | G17: ='Input-Detail'!AO25 -> 501182.91 | H17: ='Input-Detail'!AP25 -> 3015101 | I17: ='Input-Detail'!AQ25 -> 5584.7682 | J17: ='Input-Detail'!AR25 -> 158099.78 | K17: =SUM(G17:J17) -> 3679968.5 | L17: =F17-K17 -> 3845866.1
A18: 12 | B18: ='Input-Detail'!AE26 -> 0 | C18: ='Input-Detail'!AF26 -> 7458188.4 | D18: ='Input-Detail'!AG26 -> 34219.395 | E18: ='Input-Detail'!AH26 -> 405563.21 | F18: =SUM(B18:E18) -> 7897971 | G18: ='Input-Detail'!AO26 -> 534778.8 | H18: ='Input-Detail'!AP26 -> 2769632.4 | I18: ='Input-Detail'!AQ26 -> 5864.0066 | J18: ='Input-Detail'!AR26 -> 162842.78 | K18: =SUM(G18:J18) -> 3473118 | L18: =F18-K18 -> 4424852.9
... A26: 20 | B26: ='Input-Detail'!AE34 -> 0 | C26: ='Input-Detail'!AF34 -> 10924454 | D26: ='Input-Detail'!AG34 -> 50557.631 | E26: ='Input-Detail'!AH34 -> 513755.34 | F26: =SUM(B26:E26) -> 11488767 | G26: ='Input-Detail'!AO34 -> 865535.91 | H26: ='Input-Detail'!AP34 -> 655170.79 | I26: ='Input-Detail'!AQ34 -> 8663.8085 | J26: ='Input-Detail'!AR34 -> 206284.36 | K26: =SUM(G26:J26) -> 1735654.9 | L26: =F26-K26 -> 9753112.3

Sheet Delay
Z1: Optimal Number of ETC Lanes
B3: 1 Transaction Facts | K3: y Total Random and Stop Delay per Year (hrs) | V3: a) Total Random and Stop Delay in the System during the Evening Peak per Day (hr) | BF3: b) Average Random Delay per Manual User (sec) | CJ3: c) Average Random Delay per ETC User (sec)
