Workbook

Sheet Price
K1: Optimal Number of ETC Lanes
B3: 1 Transaction Facts | H3: a) Total Random and Stop Delay in the System during the Evening Peak per Day (hr) | BT3: c) Average Random Delay per ETC User (sec)
H5: Year | I5: Price Diff. | J5: Time Difference (min) | K5: Split (ETC/Manual) | L5: d | M5: NPV | N5: ETC (%) | O5: T (hr) | P5: Total Arrival Rate | Q5: Delay in Manual Lanes | W5: Number of ETC Lanes
B6: Transaction Time (sec) | G6: 0.065587921 | Q6: Arrival rate | R6: Nr. of Lanes | S6: Mean Serive Rate | T6: r | U6: Random Delay (sec) | V6: Acc/Dec Delay (sec) | W6: Arrival rate | X6: Nr. of Lanes | Y6: Mean Serive Rate | Z6: r | AA6: Random Delay (sec)
C7: Cash | D7: ='Input-Detail'!AZ10 -> 7 | G7: NPV0 | N7: 0
C8: Ticket | D8: ='Input-Detail'!AZ11 -> 4.5 | G8: 22059 | H8: 1 | I8: 0 | J8: -1.0727208 | K8: 0.075250573 | L8: 7.4215731e-06 | M8: 31729.96 | N8: 0.06998422 | O8: ='Input-Detail'!X18 -> 2 | P8: ='Input-Detail'!V19*'Input-Detail'!Y19 -> 5905.7725 | Q8: =P8*(1-N8) -> 5492.4616 | R8: =$D$12-X8 -> 11 | S8: =Delay!$N41 -> 545.76464 | T8: =Q8/(R8*S8) -> 0.91489015 | U8: 12.912107 | V8: 52.363636 | W8: =P8-Q8 -> 413.31088 | X8: =ETCLANE!BB8 -> 1 | Y8: =Delay!$O41 -> 1500 | Z8: =W8/(X8*Y8) -> 0.27554059 | AA8: 0.91249573
C9: ETC | D9: ='Input-Detail'!AZ12 -> 2.4 | E9: 0 | H9: 2 | I9: 0 | J9: -1.0083182 | K9: 0.15404974 | L9: 8.9849683e-06 | M9: 783006.26 | N9: 0.13348622 | O9: ='Input-Detail'!X19 -> 2 | P9: ='Input-Detail'!V20*'Input-Detail'!Y20 -> 6071.545 | Q9: =P9*(1-N9) -> 5261.0774 | R9: =$D$12-X9 -> 11 | S9: =Delay!$N42 -> 544.01209 | T9: =Q9/(R9*S9) -> 0.8791712 | U9: 10.951595 | V9: 52.363636 | W9: =P9-Q9 -> 810.46759 | X9: =ETCLANE!BB9 -> 1 | Y9: =Delay!$O42 -> 1500 | Z9: =W9/(X9*Y9) -> 0.54031173 | AA9: 2.8161371
B10: Total Number of Lanes | D10: ='Input-Detail'!AZ25 -> 12 | H10: 3 | I10: 0 | J10: -1.1103072 | K10: 0.23807043 | L10: 5.7807439e-06 | M10: 1245032.8 | N10: 0.19229151 | O10: ='Input-Detail'!X20 -> 2 | P10: ='Input-Detail'!V21*'Input-Detail'!Y21 -> 6237.3175 | Q10: =P10*(1-N10) -> 5037.9343 | R10: =$D$12-X10 -> 10 | S10: =Delay!$N43 -> 542.27076 | T10: =Q10/(R10*S10) -> 0.92904406 | U10: 15.053814 | V10: 52.363636 | W10: =P10-Q10 -> 1199.3832 | X10: =ETCLANE!BB10 -> 2 | Y10: =Delay!$O43 -> 1500 | Z10: =W10/(X10*Y10) -> 0.39979439 | AA10: 0.79901942
B11: Configuration of the Toll Plaza | H11: 4 | I11: 0 | J11: -1.0516707 | K11: 0.32826275 | L11: 5.0809504e-06 | M11: 1786952.8 | N11: 0.24713691 | O11: ='Input-Detail'!X21 -> 2 | P11: ='Input-Detail'!V22*'Input-Detail'!Y22 -> 6403.09 | Q11: =P11*(1-N11) -> 4820.6501 | R11: =$D$12-X11 -> 10 | S11: =Delay!$N44 -> 540.54054 | T11: =Q11/(R11*S11) -> 0.89182027 | U11: 12.075126 | V11: 52.363636 | W11: =P11-Q11 -> 1582.4398 | X11: =ETCLANE!BB11 -> 2 | Y11: =Delay!$O44 -> 1500 | Z11: =W11/(X11*Y11) -> 0.52747995 | AA11: 1.3385215
C12: Total Number of Lanes | D12: ='Input-Detail'!AZ25 -> 12 | H12: 5 | I12: 0 | J12: -1.0112119 | K12: 0.42650201 | L12: 8.2629947e-06 | M12: 2290995.5 | N12: 0.29898451 | O12: ='Input-Detail'!X22 -> 2 | P12: ='Input-Detail'!V23*'Input-Detail'!Y23 -> 6568.8625 | Q12: =P12*(1-N12) -> 4604.8743 | R12: =$D$12-X12 -> 10 | S12: =Delay!$N45 -> 538.82133 | T12: =Q12/(R12*S12) -> 0.8546199 | U12: 10.579796 | V12: 52.363636 | W12: =P12-Q12 -> 1963.9881 | X12: =ETCLANE!BB12 -> 2 | Y12: =Delay!$O45 -> 1500 | Z12: =W12/(X12*Y12) -> 0.65466272 | AA12: 2.2707163
C13: Ramp Distance prior to the Toll Plaza (miles) | D13: ='Input-Detail'!AZ26 -> 0.2 | H13: 6 | I13: 0 | J13: -1.0887094 | K13: 0.53565597 | L13: 5.2565051e-06 | M13: 2774294.3 | N13: 0.34881248 | O13: ='Input-Detail'!X23 -> 2 | P13: ='Input-Detail'!V24*'Input-Detail'!Y24 -> 6734.6349 | Q13: =P13*(1-N13) -> 4385.5102 | R13: =$D$12-X13 -> 9 | S13: =Delay!$N46 -> 537.11302 | T13: =Q13/(R13*S13) -> 0.90721858 | U13: 13.832221 | V13: 52.363636 | W13: =P13-Q13 -> 2349.1247 | X13: =ETCLANE!BB13 -> 3 | Y13: =Delay!$O46 -> 1500 | Z13: =W13/(X13*Y13) -> 0.52202772 | AA13: 0.87329401
C14: Ramp Distance leading from the toll Plaza (miles) | D14: ='Input-Detail'!AZ27 -> 0.2 | H14: 7 | I14: 0 | J14: -1.0423843 | K14: 0.65759171 | L14: 9.5234278e-06 | M14: 3297579.6 | N14: 0.39671513 | O14: ='Input-Detail'!X24 -> 2 | P14: ='Input-Detail'!V25*'Input-Detail'!Y25 -> 6900.4074 | Q14: =P14*(1-N14) -> 4162.9114 | R14: =$D$12-X14 -> 9 | S14: =Delay!$N47 -> 535.4155 | T14: =Q14/(R14*S14) -> 0.86390048 | U14: 11.420879 | V14: 52.363636 | W14: =P14-Q14 -> 2737.496 | X14: =ETCLANE!BB14 -> 3 | Y14: =Delay!$O47 -> 1500 | Z14: =W14/(X14*Y14) -> 0.60833245 | AA14: 1.2414555
B15: Average Travel Speed (mph) | D15: ='Input-Detail'!AZ29 -> 55 | H15: 8 | I15: 0 | J15: -1.0110577 | K15: 0.79545306 | L15: 8.093132e-06 | M15: 3803281.4 | N15: 0.44303751 | O15: ='Input-Detail'!X25 -> 2 | P15: ='Input-Detail'!V26*'Input-Detail'!Y26 -> 7066.1799 | Q15: =P15*(1-N15) -> 3935.5971 | R15: =$D$12-X15 -> 9 | S15: =Delay!$N48 -> 533.72869 | T15: =Q15/(R15*S15) -> 0.81930872 | U15: 10.125638 | V15: 52.363636 | W15: =P15-Q15 -> 3130.5828 | X15: =ETCLANE!BB15 -> 3 | Y15: =Delay!$O48 -> 1500 | Z15: =W15/(X15*Y15) -> 0.69568506 | AA15: 1.8258126
B16: ETC Survival Rate | D16: 0.84 | H16: 9 | I16: 0 | J16: -1.0641648 | K16: 0.95370764 | L16: 7.9325893e-06 | M16: 4324612.4 | N16: 0.48815269 | O16: ='Input-Detail'!X26 -> 2 | P16: ='Input-Detail'!V27*'Input-Detail'!Y27 -> 7231.9524 | Q16: =P16*(1-N16) -> 3701.6554 | R16: =$D$12-X16 -> 8 | S16: =Delay!$N49 -> 532.05247 | T16: =Q16/(R16*S16) -> 0.86966409 | U16: 12.343419 | V16: 52.363636 | W16: =P16-Q16 -> 3530.297 | X16: =ETCLANE!BB16 -> 4 | Y16: =Delay!$O49 -> 1500 | Z16: =W16/(X16*Y16) -> 0.58838284 | AA16: 0.85716933
H17: 10 | I17: 0 | J17: -1.029363 | K17: 1.1355253 | L17: 7.1061015e-06 | M17: 4853905.7 | N17: 0.53173113 | O17: ='Input-Detail'!X27 -> 2 | P17: ='Input-Detail'!V28*'Input-Detail'!Y28 -> 7397.7249 | Q17: =P17*(1-N17) -> 3464.1243 | R17: =$D$12-X17 -> 8 | S17: =Delay!$N50 -> 530.38674 | T17: =Q17/(R17*S17) -> 0.81641471 | U17: 10.539255 | V17: 52.363636 | W17: =P17-Q17 -> 3933.6006 | X17: =ETCLANE!BB17 -> 4 | Y17: =Delay!$O50 -> 1500 | Z17: =W17/(X17*Y17) -> 0.6556001 | AA17: 1.1411105
H18: 11 | I18: 0 | J18: -1.0054556 | K18: 1.3458196 | L18: 6.0171627e-06 | M18: 5368564.1 | N18: 0.57370976 | O18: ='Input-Detail'!X28 -> 2 | P18: ='Input-Detail'!V29*'Input-Detail'!Y29 -> 7563.4974 | Q18: =P18*(1-N18) -> 3224.2451 | R18: =$D$12-X18 -> 8 | S18: =Delay!$N51 -> 528.73141 | T18: =Q18/(R18*S18) -> 0.76225968 | U18: 9.5289408 | V18: 52.363636 | W18: =P18-Q18 -> 4339.2523 | X18: =ETCLANE!BB18 -> 4 | Y18: =Delay!$O51 -> 1500 | Z18: =W18/(X18*Y18) -> 0.72320872 | AA18: 1.5652396
H19: 12 | I19: 0 | J19: -1.0410105 | K19: 1.5912161 | L19: 5.4568003e-06 | M19: 5915262.3 | N19: 0.61408081 | O19: ='Input-Detail'!X29 -> 2 | P19: ='Input-Detail'!V30*'Input-Detail'!Y30 -> 7729.2699 | Q19: =P19*(1-N19) -> 2982.8736 | R19: =$D$12-X19 -> 7 | S19: =Delay!$N52 -> 527.08638 | T19: =Q19/(R19*S19) -> 0.80845343 | U19: 10.923856 | V19: 52.363636 | W19: =P19-Q19 -> 4746.3963 | X19: =ETCLANE!BB19 -> 5 | Y19: =Delay!$O52 -> 1500 | Z19: =W19/(X19*Y19) -> 0.63285284 | AA19: 0.82686041
H20: 13 | I20: 0 | J20: -1.0171937 | K20: 1.8766808 | L20: 9.5794369e-06 | M20: 6434905.6 | N20: 0.65237714 | O20: ='Input-Detail'!X30 -> 2 | P20: ='Input-Detail'!V31*'Input-Detail'!Y31 -> 7895.0424 | Q20: =P20*(1-N20) -> 2744.4972 | R20: =$D$12-X20 -> 7 | S20: =Delay!$N53 -> 525.45156 | T20: =Q20/(R20*S20) -> 0.74616018 | U20: 9.7192767 | V20: 52.363636 | W20: =P20-Q20 -> 5150.5452 | X20: =ETCLANE!BB20 -> 5 | Y20: =Delay!$O53 -> 1500 | Z20: =W20/(X20*Y20) -> 0.68673936 | AA20: 1.0512903
H21: 14 | I21: 0 | J21: -1.0518488 | K21: 2.2108944 | L21: 7.9857443e-06 | M21: 6972281.4 | N21: 0.68856029 | O21: ='Input-Detail'!X31 -> 2 | P21: ='Input-Detail'!V32*'Input-Detail'!Y32 -> 8060.8149 | Q21: =P21*(1-N21) -> 2510.4578 | R21: =$D$12-X21 -> 6 | S21: =Delay!$N54 -> 523.82685 | T21: =Q21/(R21*S21) -> 0.79875562 | U21: 11.390578 | V21: 52.363636 | W21: =P21-Q21 -> 5550.357 | X21: =ETCLANE!BB21 -> 6 | Y21: =Delay!$O54 -> 1500 | Z21: =W21/(X21*Y21) -> 0.61670634 | AA21: 0.64328636
H22: 15 | I22: 0 | J22: -1.0261345 | K22: 2.5996438 | L22: 7.1529341e-06 | M22: 7480146.3 | N22: 0.72219474 | O22: ='Input-Detail'!X32 -> 2 | P22: ='Input-Detail'!V33*'Input-Detail'!Y33 -> 8226.5874 | Q22: =P22*(1-N22) -> 2285.3893 | R22: =$D$12-X22 -> 6 | S22: =Delay!$N55 -> 522.21215 | T22: =Q22/(R22*S22) -> 0.72939362 | U22: 9.9808744 | V22: 52.363636 | W22: =P22-Q22 -> 5941.1981 | X22: =ETCLANE!BB22 -> 6 | Y22: =Delay!$O55 -> 1500 | Z22: =W22/(X22*Y22) -> 0.66013312 | AA22: 0.77643867
H23: 16 | I23: 0 | J23: -1.0099904 | K23: 3.0519616 | L23: 6.0726046e-06 | M23: 7967363.8 | N23: 0.75320595 | O23: ='Input-Detail'!X33 -> 2 | P23: ='Input-Detail'!V34*'Input-Detail'!Y34 -> 8392.3598 | Q23: =P23*(1-N23) -> 2071.1845 | R23: =$D$12-X23 -> 6 | S23: =Delay!$N56 -> 520.60738 | T23: =Q23/(R23*S23) -> 0.66306669 | U23: 9.1788331 | V23: 52.363636 | W23: =P23-Q23 -> 6321.1754 | X23: =ETCLANE!BB23 -> 6 | Y23: =Delay!$O56 -> 1500 | Z23: =W23/(X23*Y23) -> 0.70235282 | AA23: 0.94304301
H24: 17 | I24: 0 | J24: -1.0375728 | K24: 3.5798342 | L24: 5.2706862e-06 | M24: 8474466.1 | N24: 0.78165149 | O24: ='Input-Detail'!X34 -> 2 | P24: ='Input-Detail'!V35*'Input-Detail'!Y35 -> 8558.1323 | Q24: =P24*(1-N24) -> 1868.6555 | R24: =$D$12-X24 -> 5 | S24: =Delay!$N57 -> 519.01243 | T24: =Q24/(R24*S24) -> 0.7200812 | U24: 10.492352 | V24: 52.363636 | W24: =P24-Q24 -> 6689.4769 | X24: =ETCLANE!BB24 -> 7 | Y24: =Delay!$O57 -> 1500 | Z24: =W24/(X24*Y24) -> 0.63709303 | AA24: 0.60161798
B25: 1 Estimation of a0 | H25: 18 | I25: 0 | J25: -1.0199565 | K25: 4.1909234 | L25: 9.1993363e-06 | M25: 8931657.9 | N25: 0.80735605 | O25: ='Input-Detail'!X35 -> 2 | P25: ='Input-Detail'!V36*'Input-Detail'!Y36 -> 8723.9048 | Q25: =P25*(1-N25) -> 1680.6075 | R25: =$D$12-X25 -> 5 | S25: =Delay!$N58 -> 517.42724 | T25: =Q25/(R25*S25) -> 0.64960149 | U25: 9.5319385 | V25: 52.363636 | W25: =P25-Q25 -> 7043.2973 | X25: =ETCLANE!BB25 -> 7 | Y25: =Delay!$O58 -> 1500 | Z25: =W25/(X25*Y25) -> 0.67079022 | AA25: 0.69818646
H26: 19 | I26: 0 | J26: -1.0592761 | K26: 4.9019317 | L26: 7.92225e-06 | M26: 9398822.5 | N26: 0.83056395 | O26: ='Input-Detail'!X36 -> 2 | P26: ='Input-Detail'!V37*'Input-Detail'!Y37 -> 8889.6773 | Q26: =P26*(1-N26) -> 1506.2318 | R26: =$D$12-X26 -> 4 | S26: =Delay!$N59 -> 515.85169 | T26: =Q26/(R26*S26) -> 0.72997328 | U26: 11.672564 | V26: 52.363636 | W26: =P26-Q26 -> 7383.4455 | X26: =ETCLANE!BB26 -> 8 | Y26: =Delay!$O59 -> 1500 | Z26: =W26/(X26*Y26) -> 0.61528713 | AA26: 0.47963623
B27: ATV | C27: 19016173 | H27: 20 | I27: 0 | J27: -1.0356639 | K27: 5.7197755 | L27: 7.1260609e-06 | M27: 9820875.8 | N27: 0.85118551 | O27: ='Input-Detail'!X37 -> 2 | P27: ='Input-Detail'!V38*'Input-Detail'!Y38 -> 9055.4498 | Q27: =P27*(1-N27) -> 1347.5822 | R27: =$D$12-X27 -> 4 | S27: =Delay!$N60 -> 514.28571 | T27: =Q27/(R27*S27) -> 0.65507467 | U27: 10.314714 | V27: 52.363636 | W27: =P27-Q27 -> 7707.8676 | X27: =ETCLANE!BB27 -> 8 | Y27: =Delay!$O60 -> 1500 | Z27: =W27/(X27*Y27) -> 0.6423223 | AA27: 0.53851871
B28: ETC % | C28: 0.06
B29: rel. % | C29: =C28/(1-C28) -> 0.063829787
B30: Time Diff | C30: =-11.06/60 -> -0.18433333
B31: Price Diff | C31: 0
B32: a0 | C32: =LN(C29)-C33*C30-C34*C31 -> -2.7570653
B33: a1 | C33: -0.03
B34: a2 | C34: =C33/('Input-Detail'!AZ39/60) -> -0.14117647

Sheet ETCLANE
Z1: Optimal Number of ETC Lanes
B3: 1 Transaction Facts | K3: y Total Random and Stop Delay per Year (hrs) | V3: a) Total Random and Stop Delay in the System during the Evening Peak per Day (hr) | BF3: b) Average Random Delay per Manual User (sec) | CJ3: c) Average Random Delay per ETC User (sec)
H5: Year | I5: Traffic Vol. | J5: ETC (%) | K5: Peak Arrival Rate in the evening | L5: Delay per Day (Baseline) | O5: Delay Per Year* (hr) | P5: Delay per Day (ETC) | S5: Delay Per Year* (hr) | V5: Year | W5: Traffic Vol. | X5: ETC (%) | Y5: PHV | Z5: ATV/PHV | AA5: T (hr) | AB5: K | AC5: Total Arrival Rate | AD5: Number of ETC Lanes | AZ5: Optimal # of ETC Ln* | BA5: Delay per Day**(hr) | BB5: Suggested # of ETC Ln*** | BC5: Delay per Day**(hr) | BF5: Year | BG5: ETC (%) | BH5: Total Arrival Rate | BI5: Arrival Rate for Manual Lanes | BJ5: Number of ETC Lanes | CH5: Mean Transaction Time (sec) | CJ5: Year | CK5: ETC (%) | CL5: Total Arrival Rate | CM5: Arrival Rate for ETC Users | CN5: Number of ETC Lanes | DJ5: Mean headway (sec)
B6: Transaction Time (sec) | L6: Morning | M6: Evening | N6: Total | P6: Morning | Q6: Evening | R6: Total | AD6: Manual Only | AE6: 1 | AF6: 2 | AG6: 3 | AH6: 4 | AI6: 5 | AJ6: 6 | AK6: 7 | AL6: 8 | AM6: 9 | AN6: 10 | AO6: 11 | AP6: 12 | AQ6: 13 | AR6: 14 | AS6: 15 | AT6: 16 | AU6: 17 | AV6: 18 | AW6: 19 | AX6: 20 | AY6: 21 | BJ6: l/sc for no ETC | BK6: Manual Only | BL6: l/sc under ETC | BM6: 1 | BN6: 2 | BO6: 3 | BP6: 4 | BQ6: 5 | BR6: 6 | BS6: 7 | BT6: 8 | BU6: 9 | BV6: 10 | BW6: 11 | BX6: 12 | BY6: 13 | BZ6: 14 | CA6: 15 | CB6: 16 | CC6: 17 | CD6: 18 | CE6: 19 | CF6: 20 | CG6: 21 | CN6: l/sc under ETC | CO6: 1 | CP6: 2 | CQ6: 3 | CR6: 4 | CS6: 5 | CT6: 6 | CU6: 7 | CV6: 8 | CW6: 9 | CX6: 10 | CY6: 11 | CZ6: 12 | DA6: 13 | DB6: 14 | DC6: 15 | DD6: 16 | DE6: 17 | DF6: 18 | DG6: 19 | DH6: 20 | DI6: 21
C7: Cash | D7: ='Input-Detail'!AZ10 -> 7 | H7: Base | I7: ='Input-Detail'!E14 -> 19016173 | J7: ='Input-Detail'!F14 -> 0 | K7: =AC7 -> 5740 | V7: Base | W7: ='Input-Detail'!E14 -> 19016173 | X7: =J7 -> 0 | Y7: ='Input-Detail'!V18 -> 8200 | Z7: ='Input-Detail'!W18 -> 2319.0455 | AA7: ='Input-Detail'!X18 -> 2 | AB7: ='Input-Detail'!Y18 -> 0.7 | AC7: =Y7*AB7 -> 5740 | AD7: =Peak_Time_Eve*$BH7*(3600/K40+BK7)/3600 -> 32.946409 | BF7: Base | BG7: =$X7 -> 0 | BH7: =$AC7 -> 5740 | BI7: =BH7*(1-BG7) -> 5740 | BJ7: =Peak_Arrival_Manual/K40 -> 10.483472 | BK7: =900*Peak_Time_Eve*(BJ7/Total_Lanes-1+SQRT((BJ7/Total_Lanes-1)^2+8*(BJ7/Total_Lanes)/(Peak_Time_Eve*$K40*Total_Lanes))) -> 3.7566264 | BL7: =Peak_Arrival_Manual/N40 -> 10.483472 | BM7: =IF(BM$6<Total_Lanes,900*Peak_Time_Eve*(($BL7/(Total_Lanes-BM$6))-1+SQRT((($BL7/(Total_Lanes-BM$6))-1)^2+8*($BL7/(Total_Lanes-BM$6))/(Peak_Time_Eve*$N40*(Total_Lanes-BM$6)))),"-") -> 11.367139 | BN7: =IF(BN$6<Total_Lanes,900*Peak_Time_Eve*(($BL7/(Total_Lanes-BN$6))-1+SQRT((($BL7/(Total_Lanes-BN$6))-1)^2+8*($BL7/(Total_Lanes-BN$6))/(Peak_Time_Eve*$N40*(Total_Lanes-BN$6)))),"-") -> 187.29857 | BO7: =IF(BO$6<Total_Lanes,900*Peak_Time_Eve*(($BL7/(Total_Lanes-BO$6))-1+SQRT((($BL7/(Total_Lanes-BO$6))-1)^2+8*($BL7/(Total_Lanes-BO$6))/(Peak_Time_Eve*$N40*(Total_Lanes-BO$6)))),"-") -> 598.50746 | BP7: =IF(BP$6<Total_Lanes,900*Peak_Time_Eve*(($BL7/(Total_Lanes-BP$6))-1+SQRT((($BL7/(Total_Lanes-BP$6))-1)^2+8*($BL7/(Total_Lanes-BP$6))/(Peak_Time_Eve*$N40*(Total_Lanes-BP$6)))),"-") -> 1121.0212 | BQ7: =IF(BQ$6<Total_Lanes,900*Peak_Time_Eve*(($BL7/(Total_Lanes-BQ$6))-1+SQRT((($BL7/(Total_Lanes-BQ$6))-1)^2+8*($BL7/(Total_Lanes-BQ$6))/(Peak_Time_Eve*$N40*(Total_Lanes-BQ$6)))),"-") -> 1794.3223 | BR7: =IF(BR$6<Total_Lanes,900*Peak_Time_Eve*(($BL7/(Total_Lanes-BR$6))-1+SQRT((($BL7/(Total_Lanes-BR$6))-1)^2+8*($BL7/(Total_Lanes-BR$6))/(Peak_Time_Eve*$N40*(Total_Lanes-BR$6)))),"-") -> 2692.6432 | BS7: =IF(BS$6<Total_Lanes,900*Peak_Time_Eve*(($BL7/(Total_Lanes-BS$6))-1+SQRT((($BL7/(Total_Lanes-BS$6))-1)^2+8*($BL7/(Total_Lanes-BS$6))/(Peak_Time_Eve*$N40*(Total_Lanes-BS$6)))),"-") -> 3950.6125 | BT7: =IF(BT$6<Total_Lanes,900*Peak_Time_Eve*(($BL7/(Total_Lanes-BT$6))-1+SQRT((($BL7/(Total_Lanes-BT$6))-1)^2+8*($BL7/(Total_Lanes-BT$6))/(Peak_Time_Eve*$N40*(Total_Lanes-BT$6)))),"-") -> 5837.7817 | ... CG7: =IF(CG$6<Total_Lanes,900*Peak_Time_Eve*(($BL7/(Total_Lanes-CG$6))-1+SQRT((($BL7/(Total_Lanes-CG$6))-1)^2+8*($BL7/(Total_Lanes-CG$6))/(Peak_Time_Eve*$N40*(Total_Lanes-CG$6)))),"-") -> - | CH7: =3600/N40 -> 6.575 | CJ7: Base | CK7: =$X7 -> 0 | CL7: =$AC7 -> 5740 | CM7: =CL7*CK7 -> 0
C8: Ticket | D8: ='Input-Detail'!AZ11 -> 4.5 | H8: 1 | I8: ='Input-Detail'!E15 -> 19565364 | J8: 0.06998422 | K8: =AC8 -> 5905.7725 | L8: =AD55 -> 9.7052873 | M8: =AD8 -> 30.689988 | N8: =SUM(L8:M8) -> 40.395275 | O8: =$S$34*N8 -> 10502.772 | P8: =BC55 -> 9.1634394 | Q8: =BC8 -> 39.609108 | R8: =SUM(P8:Q8) -> 48.772548 | S8: =$S$34*R8 -> 12680.862 | V8: 1 | W8: =W$7+(W$27-W$7)*$V8/20 -> 19565364 | X8: =J8 -> 0.06998422 | Y8: ='Input-Detail'!E15/Z8 -> 8436.8178 | Z8: =Z7 -> 2319.0455 | AA8: =AA7 -> 2 | AB8: =AB7 -> 0.7 | AC8: =Y8*AB8 -> 5905.7725 | AD8: =Peak_Time_Eve*$BH8*(3600/K41+BK8)/3600 -> 30.689988 | AE8: =IF(AE$6<Total_Lanes,($BI8*($CH8+BM8)+$CM8*CO8)*Peak_Time_Eve/3600,"-") -> 39.609108 | AF8: =IF(AF$6<Total_Lanes,($BI8*($CH8+BN8)+$CM8*CP8)*Peak_Time_Eve/3600,"-") -> 208.43637 | AG8: =IF(AG$6<Total_Lanes,($BI8*($CH8+BO8)+$CM8*CQ8)*Peak_Time_Eve/3600,"-") -> 1339.3769 | AH8: =IF(AH$6<Total_Lanes,($BI8*($CH8+BP8)+$CM8*CR8)*Peak_Time_Eve/3600,"-") -> 2866.1779 | AI8: =IF(AI$6<Total_Lanes,($BI8*($CH8+BQ8)+$CM8*CS8)*Peak_Time_Eve/3600,"-") -> 4837.4912 | AJ8: =IF(AJ$6<Total_Lanes,($BI8*($CH8+BR8)+$CM8*CT8)*Peak_Time_Eve/3600,"-") -> 7468.5034 | AK8: =IF(AK$6<Total_Lanes,($BI8*($CH8+BS8)+$CM8*CU8)*Peak_Time_Eve/3600,"-") -> 11153.198 | AL8: =IF(AL$6<Total_Lanes,($BI8*($CH8+BT8)+$CM8*CV8)*Peak_Time_Eve/3600,"-") -> 16681.048 | ... AY8: =IF(AY$6<Total_Lanes,($BI8*($CH8+CG8)+$CM8*DI8)*Peak_Time_Eve/3600,"-") -> - | AZ8: =SUMIF(AE8:AY8,BA8,$AE$6:$AY$6) -> 1 | BA8: =MIN(AE8:AY8) -> 39.609108 | BB8: =IF((SUMIF($BM6:$CG6,$AZ8,$BM8:$CG8)+$CH8)<(SUMIF($CO6:$DI6,$AZ8,$CO8:$DI8)+$DJ8),AZ8+1,AZ8) -> 1 | BC8: =SUMIF($AE$6:$AY$6,$BB8,$AE8:$AY8) -> 39.609108 | BF8: 1 | BG8: =$X8 -> 0.06998422 | BH8: =$AC8 -> 5905.7725 | BI8: =BH8*(1-BG8) -> 5492.4616 | BJ8: =Peak_Arrival_Manual/K41 -> 10.031371 | BK8: =900*Peak_Time_Eve*(BJ8/Total_Lanes-1+SQRT((BJ8/Total_Lanes-1)^2+8*(BJ8/Total_Lanes)/(Peak_Time_Eve*$K41*Total_Lanes))) -> 2.7788954 | BL8: =Peak_Arrival_Manual/N41 -> 10.063792 | BM8: =IF(BM$6<Total_Lanes,900*Peak_Time_Eve*(($BL8/(Total_Lanes-BM$6))-1+SQRT((($BL8/(Total_Lanes-BM$6))-1)^2+8*($BL8/(Total_Lanes-BM$6))/(Peak_Time_Eve*$N41*(Total_Lanes-BM$6)))),"-") -> 6.3158567 | BN8: =IF(BN$6<Total_Lanes,900*Peak_Time_Eve*(($BL8/(Total_Lanes-BN$6))-1+SQRT((($BL8/(Total_Lanes-BN$6))-1)^2+8*($BL8/(Total_Lanes-BN$6))/(Peak_Time_Eve*$N41*(Total_Lanes-BN$6)))),"-") -> 61.698487 | BO8: =IF(BO$6<Total_Lanes,900*Peak_Time_Eve*(($BL8/(Total_Lanes-BO$6))-1+SQRT((($BL8/(Total_Lanes-BO$6))-1)^2+8*($BL8/(Total_Lanes-BO$6))/(Peak_Time_Eve*$N41*(Total_Lanes-BO$6)))),"-") -> 432.34083 | BP8: =IF(BP$6<Total_Lanes,900*Peak_Time_Eve*(($BL8/(Total_Lanes-BP$6))-1+SQRT((($BL8/(Total_Lanes-BP$6))-1)^2+8*($BL8/(Total_Lanes-BP$6))/(Peak_Time_Eve*$N41*(Total_Lanes-BP$6)))),"-") -> 932.70969 | BQ8: =IF(BQ$6<Total_Lanes,900*Peak_Time_Eve*(($BL8/(Total_Lanes-BQ$6))-1+SQRT((($BL8/(Total_Lanes-BQ$6))-1)^2+8*($BL8/(Total_Lanes-BQ$6))/(Peak_Time_Eve*$N41*(Total_Lanes-BQ$6)))),"-") -> 1578.7535 | BR8: =IF(BR$6<Total_Lanes,900*Peak_Time_Eve*(($BL8/(Total_Lanes-BR$6))-1+SQRT((($BL8/(Total_Lanes-BR$6))-1)^2+8*($BL8/(Total_Lanes-BR$6))/(Peak_Time_Eve*$N41*(Total_Lanes-BR$6)))),"-") -> 2440.9945 | BS8: =IF(BS$6<Total_Lanes,900*Peak_Time_Eve*(($BL8/(Total_Lanes-BS$6))-1+SQRT((($BL8/(Total_Lanes-BS$6))-1)^2+8*($BL8/(Total_Lanes-BS$6))/(Peak_Time_Eve*$N41*(Total_Lanes-BS$6)))),"-") -> 3648.55 | BT8: =IF(BT$6<Total_Lanes,900*Peak_Time_Eve*(($BL8/(Total_Lanes-BT$6))-1+SQRT((($BL8/(Total_Lanes-BT$6))-1)^2+8*($BL8/(Total_Lanes-BT$6))/(Peak_Time_Eve*$N41*(Total_Lanes-BT$6)))),"-") -> 5460.148 | ... CG8: =IF(CG$6<Total_Lanes,900*Peak_Time_Eve*(($BL8/(Total_Lanes-CG$6))-1+SQRT((($BL8/(Total_Lanes-CG$6))-1)^2+8*($BL8/(Total_Lanes-CG$6))/(Peak_Time_Eve*$N41*(Total_Lanes-CG$6)))),"-") -> - | CH8: =3600/N41 -> 6.59625 | CJ8: 1 | CK8: =$X8 -> 0.06998422 | CL8: =$AC8 -> 5905.7725 | CM8: =CL8*CK8 -> 413.31088 | CN8: =CM8/O40 -> 0.27554059 | CO8: =IF(CO$6<Total_Lanes,900*Peak_Time_Eve*(($CN8/CO$6-1)+SQRT(($CN8/CO$6-1)^2+8*($CN8/CO$6)/(Peak_Time_Eve*$O41*CO$6))),"-") -> 0.91249573 | CP8: =IF(CP$6<Total_Lanes,900*Peak_Time_Eve*(($CN8/CP$6-1)+SQRT(($CN8/CP$6-1)^2+8*($CN8/CP$6)/(Peak_Time_Eve*$O41*CP$6))),"-") -> 0.19172866 | CQ8: =IF(CQ$6<Total_Lanes,900*Peak_Time_Eve*(($CN8/CQ$6-1)+SQRT(($CN8/CQ$6-1)^2+8*($CN8/CQ$6)/(Peak_Time_Eve*$O41*CQ$6))),"-") -> 0.080906698 | CR8: =IF(CR$6<Total_Lanes,900*Peak_Time_Eve*(($CN8/CR$6-1)+SQRT(($CN8/CR$6-1)^2+8*($CN8/CR$6)/(Peak_Time_Eve*$O41*CR$6))),"-") -> 0.044388231 | CS8: =IF(CS$6<Total_Lanes,900*Peak_Time_Eve*(($CN8/CS$6-1)+SQRT(($CN8/CS$6-1)^2+8*($CN8/CS$6)/(Peak_Time_Eve*$O41*CS$6))),"-") -> 0.027994397 | CT8: =IF(CT$6<Total_Lanes,900*Peak_Time_Eve*(($CN8/CT$6-1)+SQRT(($CN8/CT$6-1)^2+8*($CN8/CT$6)/(Peak_Time_Eve*$O41*CT$6))),"-") -> 0.019253454 | CU8: =IF(CU$6<Total_Lanes,900*Peak_Time_Eve*(($CN8/CU$6-1)+SQRT(($CN8/CU$6-1)^2+8*($CN8/CU$6)/(Peak_Time_Eve*$O41*CU$6))),"-") -> 0.014048813 | CV8: =IF(CV$6<Total_Lanes,900*Peak_Time_Eve*(($CN8/CV$6-1)+SQRT(($CN8/CV$6-1)^2+8*($CN8/CV$6)/(Peak_Time_Eve*$O41*CV$6))),"-") -> 0.010701321 | ... DI8: =IF(DI$6<Total_Lanes,900*Peak_Time_Eve*(($CN8/DI$6-1)+SQRT(($CN8/DI$6-1)^2+8*($CN8/DI$6)/(Peak_Time_Eve*$O41*DI$6))),"-") -> - | DJ8: =3600/O41 -> 2.4
C9: ETC | D9: ='Input-Detail'!AZ12 -> 2.4 | H9: 2 | I9: ='Input-Detail'!E16 -> 20114556 | J9: 0.13348622 | K9: =AC9 -> 6071.545 | L9: =AD56 -> 9.9541178 | M9: =AD9 -> 28.248991 | N9: =SUM(L9:M9) -> 38.203109 | O9: =$S$34*N9 -> 9932.8083 | P9: =BC56 -> 8.5138447 | Q9: =BC9 -> 30.482994 | R9: =SUM(P9:Q9) -> 38.996839 | S9: =$S$34*R9 -> 10139.178 | V9: 2 | W9: =W$7+(W$27-W$7)*$V9/20 -> 20114556 | X9: =MIN((J8+0.1),0.95) -> 0.16998422 | Y9: ='Input-Detail'!E16/Z9 -> 8673.6357 | Z9: =Z8 -> 2319.0455 | AA9: =AA8 -> 2 | AB9: =AB8 -> 0.7 | AC9: =Y9*AB9 -> 6071.545 | AD9: =Peak_Time_Eve*$BH9*(3600/K42+BK9)/3600 -> 28.248991 | AE9: =IF(AE$6<Total_Lanes,($BI9*($CH9+BM9)+$CM9*CO9)*Peak_Time_Eve/3600,"-") -> 30.482994 | AF9: =IF(AF$6<Total_Lanes,($BI9*($CH9+BN9)+$CM9*CP9)*Peak_Time_Eve/3600,"-") -> 41.503054 | AG9: =IF(AG$6<Total_Lanes,($BI9*($CH9+BO9)+$CM9*CQ9)*Peak_Time_Eve/3600,"-") -> 373.91334 | AH9: =IF(AH$6<Total_Lanes,($BI9*($CH9+BP9)+$CM9*CR9)*Peak_Time_Eve/3600,"-") -> 1627.2964 | AI9: =IF(AI$6<Total_Lanes,($BI9*($CH9+BQ9)+$CM9*CS9)*Peak_Time_Eve/3600,"-") -> 3288.5281 | AJ9: =IF(AJ$6<Total_Lanes,($BI9*($CH9+BR9)+$CM9*CT9)*Peak_Time_Eve/3600,"-") -> 5509.4884 | AK9: =IF(AK$6<Total_Lanes,($BI9*($CH9+BS9)+$CM9*CU9)*Peak_Time_Eve/3600,"-") -> 8621 | AL9: =IF(AL$6<Total_Lanes,($BI9*($CH9+BT9)+$CM9*CV9)*Peak_Time_Eve/3600,"-") -> 13289.439 | ... AY9: =IF(AY$6<Total_Lanes,($BI9*($CH9+CG9)+$CM9*DI9)*Peak_Time_Eve/3600,"-") -> - | AZ9: =SUMIF(AE9:AY9,BA9,$AE$6:$AY$6) -> 1 | BA9: =MIN(AE9:AY9) -> 30.482994 | BB9: =IF((SUMIF($BM7:$CG7,$AZ9,$BM9:$CG9)+$CH9)<(SUMIF($CO7:$DI7,$AZ9,$CO9:$DI9)+$DJ9),AZ9+1,AZ9) -> 1 | BC9: =SUMIF($AE$6:$AY$6,$BB9,$AE9:$AY9) -> 30.482994 | BF9: 2 | BG9: =$X9 -> 0.16998422 | BH9: =$AC9 -> 6071.545 | BI9: =BH9*(1-BG9) -> 5039.4781 | BJ9: =Peak_Arrival_Manual/K42 -> 9.2040469 | BK9: =900*Peak_Time_Eve*(BJ9/Total_Lanes-1+SQRT((BJ9/Total_Lanes-1)^2+8*(BJ9/Total_Lanes)/(Peak_Time_Eve*$K42*Total_Lanes))) -> 1.7998344 | BL9: =Peak_Arrival_Manual/N42 -> 9.2635407 | BM9: =IF(BM$6<Total_Lanes,900*Peak_Time_Eve*(($BL9/(Total_Lanes-BM$6))-1+SQRT((($BL9/(Total_Lanes-BM$6))-1)^2+8*($BL9/(Total_Lanes-BM$6))/(Peak_Time_Eve*$N42*(Total_Lanes-BM$6)))),"-") -> 3.1914027 | BN9: =IF(BN$6<Total_Lanes,900*Peak_Time_Eve*(($BL9/(Total_Lanes-BN$6))-1+SQRT((($BL9/(Total_Lanes-BN$6))-1)^2+8*($BL9/(Total_Lanes-BN$6))/(Peak_Time_Eve*$N42*(Total_Lanes-BN$6)))),"-") -> 8.0777039 | BO9: =IF(BO$6<Total_Lanes,900*Peak_Time_Eve*(($BL9/(Total_Lanes-BO$6))-1+SQRT((($BL9/(Total_Lanes-BO$6))-1)^2+8*($BL9/(Total_Lanes-BO$6))/(Peak_Time_Eve*$N42*(Total_Lanes-BO$6)))),"-") -> 126.88805 | BP9: =IF(BP$6<Total_Lanes,900*Peak_Time_Eve*(($BL9/(Total_Lanes-BP$6))-1+SQRT((($BL9/(Total_Lanes-BP$6))-1)^2+8*($BL9/(Total_Lanes-BP$6))/(Peak_Time_Eve*$N42*(Total_Lanes-BP$6)))),"-") -> 574.59444 | BQ9: =IF(BQ$6<Total_Lanes,900*Peak_Time_Eve*(($BL9/(Total_Lanes-BQ$6))-1+SQRT((($BL9/(Total_Lanes-BQ$6))-1)^2+8*($BL9/(Total_Lanes-BQ$6))/(Peak_Time_Eve*$N42*(Total_Lanes-BQ$6)))),"-") -> 1167.9628 | BR9: =IF(BR$6<Total_Lanes,900*Peak_Time_Eve*(($BL9/(Total_Lanes-BR$6))-1+SQRT((($BL9/(Total_Lanes-BR$6))-1)^2+8*($BL9/(Total_Lanes-BR$6))/(Peak_Time_Eve*$N42*(Total_Lanes-BR$6)))),"-") -> 1961.2501 | BS9: =IF(BS$6<Total_Lanes,900*Peak_Time_Eve*(($BL9/(Total_Lanes-BS$6))-1+SQRT((($BL9/(Total_Lanes-BS$6))-1)^2+8*($BL9/(Total_Lanes-BS$6))/(Peak_Time_Eve*$N42*(Total_Lanes-BS$6)))),"-") -> 3072.6222 | BT9: =IF(BT$6<Total_Lanes,900*Peak_Time_Eve*(($BL9/(Total_Lanes-BT$6))-1+SQRT((($BL9/(Total_Lanes-BT$6))-1)^2+8*($BL9/(Total_Lanes-BT$6))/(Peak_Time_Eve*$N42*(Total_Lanes-BT$6)))),"-") -> 4740.0965 | ... CG9: =IF(CG$6<Total_Lanes,900*Peak_Time_Eve*(($BL9/(Total_Lanes-CG$6))-1+SQRT((($BL9/(Total_Lanes-CG$6))-1)^2+8*($BL9/(Total_Lanes-CG$6))/(Peak_Time_Eve*$N42*(Total_Lanes-CG$6)))),"-") -> - | CH9: =3600/N42 -> 6.6175 | CJ9: 2 | CK9: =$X9 -> 0.16998422 | CL9: =$AC9 -> 6071.545 | CM9: =CL9*CK9 -> 1032.0668 | CN9: =CM9/O41 -> 0.68804456 | CO9: =IF(CO$6<Total_Lanes,900*Peak_Time_Eve*(($CN9/CO$6-1)+SQRT(($CN9/CO$6-1)^2+8*($CN9/CO$6)/(Peak_Time_Eve*$O42*CO$6))),"-") -> 5.2686886 | CP9: =IF(CP$6<Total_Lanes,900*Peak_Time_Eve*(($CN9/CP$6-1)+SQRT(($CN9/CP$6-1)^2+8*($CN9/CP$6)/(Peak_Time_Eve*$O42*CP$6))),"-") -> 0.6291628 | CQ9: =IF(CQ$6<Total_Lanes,900*Peak_Time_Eve*(($CN9/CQ$6-1)+SQRT(($CN9/CQ$6-1)^2+8*($CN9/CQ$6)/(Peak_Time_Eve*$O42*CQ$6))),"-") -> 0.23806186 | CR9: =IF(CR$6<Total_Lanes,900*Peak_Time_Eve*(($CN9/CR$6-1)+SQRT(($CN9/CR$6-1)^2+8*($CN9/CR$6)/(Peak_Time_Eve*$O42*CR$6))),"-") -> 0.12464222 | CS9: =IF(CS$6<Total_Lanes,900*Peak_Time_Eve*(($CN9/CS$6-1)+SQRT(($CN9/CS$6-1)^2+8*($CN9/CS$6)/(Peak_Time_Eve*$O42*CS$6))),"-") -> 0.076590133 | CT9: =IF(CT$6<Total_Lanes,900*Peak_Time_Eve*(($CN9/CT$6-1)+SQRT(($CN9/CT$6-1)^2+8*($CN9/CT$6)/(Peak_Time_Eve*$O42*CT$6))),"-") -> 0.051810177 | CU9: =IF(CU$6<Total_Lanes,900*Peak_Time_Eve*(($CN9/CU$6-1)+SQRT(($CN9/CU$6-1)^2+8*($CN9/CU$6)/(Peak_Time_Eve*$O42*CU$6))),"-") -> 0.037373248 | CV9: =IF(CV$6<Total_Lanes,900*Peak_Time_Eve*(($CN9/CV$6-1)+SQRT(($CN9/CV$6-1)^2+8*($CN9/CV$6)/(Peak_Time_Eve*$O42*CV$6))),"-") -> 0.028229329 | ... DI9: =IF(DI$6<Total_Lanes,900*Peak_Time_Eve*(($CN9/DI$6-1)+SQRT(($CN9/DI$6-1)^2+8*($CN9/DI$6)/(Peak_Time_Eve*$O42*DI$6))),"-") -> - | DJ9: =3600/O42 -> 2.4
B10: Total Number of Lanes | D10: ='Input-Detail'!AZ25 -> 12 | H10: 3 | I10: ='Input-Detail'!E17 -> 20663747 | J10: 0.19229151 | K10: =AC10 -> 6237.3175 | L10: =AD57 -> 10.227762 | M10: =AD10 -> 27.848946 | N10: =SUM(L10:M10) -> 38.076708 | O10: =$S$34*N10 -> 9899.9442 | P10: =BC57 -> 8.1252815 | Q10: =BC10 -> 31.536807 | R10: =SUM(P10:Q10) -> 39.662089 | S10: =$S$34*R10 -> 10312.143 | V10: 3 | W10: =W$7+(W$27-W$7)*$V10/20 -> 20663747 | X10: =MIN((J9+0.1),0.95) -> 0.23348622 | Y10: ='Input-Detail'!E17/Z10 -> 8910.4535 | Z10: =Z9 -> 2319.0455 | AA10: =AA9 -> 2 | AB10: =AB9 -> 0.7 | AC10: =Y10*AB10 -> 6237.3175 | AD10: =Peak_Time_Eve*$BH10*(3600/K43+BK10)/3600 -> 27.848946 | AE10: =IF(AE$6<Total_Lanes,($BI10*($CH10+BM10)+$CM10*CO10)*Peak_Time_Eve/3600,"-") -> 67.058426 | AF10: =IF(AF$6<Total_Lanes,($BI10*($CH10+BN10)+$CM10*CP10)*Peak_Time_Eve/3600,"-") -> 31.536807 | AG10: =IF(AG$6<Total_Lanes,($BI10*($CH10+BO10)+$CM10*CQ10)*Peak_Time_Eve/3600,"-") -> 87.385392 | AH10: =IF(AH$6<Total_Lanes,($BI10*($CH10+BP10)+$CM10*CR10)*Peak_Time_Eve/3600,"-") -> 1017.0836 | AI10: =IF(AI$6<Total_Lanes,($BI10*($CH10+BQ10)+$CM10*CS10)*Peak_Time_Eve/3600,"-") -> 2511.3768 | AJ10: =IF(AJ$6<Total_Lanes,($BI10*($CH10+BR10)+$CM10*CT10)*Peak_Time_Eve/3600,"-") -> 4515.6041 | AK10: =IF(AK$6<Total_Lanes,($BI10*($CH10+BS10)+$CM10*CU10)*Peak_Time_Eve/3600,"-") -> 7324.6849 | AL10: =IF(AL$6<Total_Lanes,($BI10*($CH10+BT10)+$CM10*CV10)*Peak_Time_Eve/3600,"-") -> 11539.812 | ... AY10: =IF(AY$6<Total_Lanes,($BI10*($CH10+CG10)+$CM10*DI10)*Peak_Time_Eve/3600,"-") -> - | AZ10: =SUMIF(AE10:AY10,BA10,$AE$6:$AY$6) -> 2 | BA10: =MIN(AE10:AY10) -> 31.536807 | BB10: =IF((SUMIF($BM8:$CG8,$AZ10,$BM10:$CG10)+$CH10)<(SUMIF($CO8:$DI8,$AZ10,$CO10:$DI10)+$DJ10),AZ10+1,AZ10) -> 2 | BC10: =SUMIF($AE$6:$AY$6,$BB10,$AE10:$AY10) -> 31.536807 | BF10: 3 | BG10: =$X10 -> 0.23348622 | BH10: =$AC10 -> 6237.3175 | BI10: =BH10*(1-BG10) -> 4780.9898 | BJ10: =Peak_Arrival_Manual/K43 -> 8.7319466 | BK10: =900*Peak_Time_Eve*(BJ10/Total_Lanes-1+SQRT((BJ10/Total_Lanes-1)^2+8*(BJ10/Total_Lanes)/(Peak_Time_Eve*$K43*Total_Lanes))) -> 1.4618048 | BL10: =Peak_Arrival_Manual/N43 -> 8.81661 | BM10: =IF(BM$6<Total_Lanes,900*Peak_Time_Eve*(($BL10/(Total_Lanes-BM$6))-1+SQRT((($BL10/(Total_Lanes-BM$6))-1)^2+8*($BL10/(Total_Lanes-BM$6))/(Peak_Time_Eve*$N43*(Total_Lanes-BM$6)))),"-") -> 2.4287918 | BN10: =IF(BN$6<Total_Lanes,900*Peak_Time_Eve*(($BL10/(Total_Lanes-BN$6))-1+SQRT((($BL10/(Total_Lanes-BN$6))-1)^2+8*($BL10/(Total_Lanes-BN$6))/(Peak_Time_Eve*$N43*(Total_Lanes-BN$6)))),"-") -> 4.8899399 | BO10: =IF(BO$6<Total_Lanes,900*Peak_Time_Eve*(($BL10/(Total_Lanes-BO$6))-1+SQRT((($BL10/(Total_Lanes-BO$6))-1)^2+8*($BL10/(Total_Lanes-BO$6))/(Peak_Time_Eve*$N43*(Total_Lanes-BO$6)))),"-") -> 26.14449 | BP10: =IF(BP$6<Total_Lanes,900*Peak_Time_Eve*(($BL10/(Total_Lanes-BP$6))-1+SQRT((($BL10/(Total_Lanes-BP$6))-1)^2+8*($BL10/(Total_Lanes-BP$6))/(Peak_Time_Eve*$N43*(Total_Lanes-BP$6)))),"-") -> 376.22558 | BQ10: =IF(BQ$6<Total_Lanes,900*Peak_Time_Eve*(($BL10/(Total_Lanes-BQ$6))-1+SQRT((($BL10/(Total_Lanes-BQ$6))-1)^2+8*($BL10/(Total_Lanes-BQ$6))/(Peak_Time_Eve*$N43*(Total_Lanes-BQ$6)))),"-") -> 938.83697 | BR10: =IF(BR$6<Total_Lanes,900*Peak_Time_Eve*(($BL10/(Total_Lanes-BR$6))-1+SQRT((($BL10/(Total_Lanes-BR$6))-1)^2+8*($BL10/(Total_Lanes-BR$6))/(Peak_Time_Eve*$N43*(Total_Lanes-BR$6)))),"-") -> 1693.4224 | BS10: =IF(BS$6<Total_Lanes,900*Peak_Time_Eve*(($BL10/(Total_Lanes-BS$6))-1+SQRT((($BL10/(Total_Lanes-BS$6))-1)^2+8*($BL10/(Total_Lanes-BS$6))/(Peak_Time_Eve*$N43*(Total_Lanes-BS$6)))),"-") -> 2751.023 | BT10: =IF(BT$6<Total_Lanes,900*Peak_Time_Eve*(($BL10/(Total_Lanes-BT$6))-1+SQRT((($BL10/(Total_Lanes-BT$6))-1)^2+8*($BL10/(Total_Lanes-BT$6))/(Peak_Time_Eve*$N43*(Total_Lanes-BT$6)))),"-") -> 4337.9849 | ... CG10: =IF(CG$6<Total_Lanes,900*Peak_Time_Eve*(($BL10/(Total_Lanes-CG$6))-1+SQRT((($BL10/(Total_Lanes-CG$6))-1)^2+8*($BL10/(Total_Lanes-CG$6))/(Peak_Time_Eve*$N43*(Total_Lanes-CG$6)))),"-") -> - | CH10: =3600/N43 -> 6.63875 | CJ10: 3 | CK10: =$X10 -> 0.23348622 | CL10: =$AC10 -> 6237.3175 | CM10: =CL10*CK10 -> 1456.3277 | CN10: =CM10/O42 -> 0.97088512 | CO10: =IF(CO$6<Total_Lanes,900*Peak_Time_Eve*(($CN10/CO$6-1)+SQRT(($CN10/CO$6-1)^2+8*($CN10/CO$6)/(Peak_Time_Eve*$O43*CO$6))),"-") -> 53.115341 | CP10: =IF(CP$6<Total_Lanes,900*Peak_Time_Eve*(($CN10/CP$6-1)+SQRT(($CN10/CP$6-1)^2+8*($CN10/CP$6)/(Peak_Time_Eve*$O43*CP$6))),"-") -> 1.1314101 | CQ10: =IF(CQ$6<Total_Lanes,900*Peak_Time_Eve*(($CN10/CQ$6-1)+SQRT(($CN10/CQ$6-1)^2+8*($CN10/CQ$6)/(Peak_Time_Eve*$O43*CQ$6))),"-") -> 0.38272157 | CR10: =IF(CR$6<Total_Lanes,900*Peak_Time_Eve*(($CN10/CR$6-1)+SQRT(($CN10/CR$6-1)^2+8*($CN10/CR$6)/(Peak_Time_Eve*$O43*CR$6))),"-") -> 0.19229709 | CS10: =IF(CS$6<Total_Lanes,900*Peak_Time_Eve*(($CN10/CS$6-1)+SQRT(($CN10/CS$6-1)^2+8*($CN10/CS$6)/(Peak_Time_Eve*$O43*CS$6))),"-") -> 0.11565972 | CT10: =IF(CT$6<Total_Lanes,900*Peak_Time_Eve*(($CN10/CT$6-1)+SQRT(($CN10/CT$6-1)^2+8*($CN10/CT$6)/(Peak_Time_Eve*$O43*CT$6))),"-") -> 0.077219177 | CU10: =IF(CU$6<Total_Lanes,900*Peak_Time_Eve*(($CN10/CU$6-1)+SQRT(($CN10/CU$6-1)^2+8*($CN10/CU$6)/(Peak_Time_Eve*$O43*CU$6))),"-") -> 0.055210255 | CV10: =IF(CV$6<Total_Lanes,900*Peak_Time_Eve*(($CN10/CV$6-1)+SQRT(($CN10/CV$6-1)^2+8*($CN10/CV$6)/(Peak_Time_Eve*$O43*CV$6))),"-") -> 0.041436472 | ... DI10: =IF(DI$6<Total_Lanes,900*Peak_Time_Eve*(($CN10/DI$6-1)+SQRT(($CN10/DI$6-1)^2+8*($CN10/DI$6)/(Peak_Time_Eve*$O43*DI$6))),"-") -> - | DJ10: =3600/O43 -> 2.4
H11: 4 | I11: ='Input-Detail'!E18 -> 21212938 | J11: 0.24713691 | K11: =AC11 -> 6403.09 | L11: =AD58 -> 10.503952 | M11: =AD11 -> 27.716433 | N11: =SUM(L11:M11) -> 38.220385 | O11: =$S$34*N11 -> 9937.3002 | P11: =BC58 -> 7.7836883 | Q11: =BC11 -> 27.476336 | R11: =SUM(P11:Q11) -> 35.260024 | S11: =$S$34*R11 -> 9167.6063 | V11: 4 | W11: =W$7+(W$27-W$7)*$V11/20 -> 21212938 | X11: =MIN((J10+0.1),0.95) -> 0.29229151 | Y11: ='Input-Detail'!E18/Z11 -> 9147.2714 | Z11: =Z10 -> 2319.0455 | AA11: =AA10 -> 2 | AB11: =AB10 -> 0.7 | AC11: =Y11*AB11 -> 6403.09 | AD11: =Peak_Time_Eve*$BH11*(3600/K44+BK11)/3600 -> 27.716433 | AE11: =IF(AE$6<Total_Lanes,($BI11*($CH11+BM11)+$CM11*CO11)*Peak_Time_Eve/3600,"-") -> 961.26451 | AF11: =IF(AF$6<Total_Lanes,($BI11*($CH11+BN11)+$CM11*CP11)*Peak_Time_Eve/3600,"-") -> 27.476336 | AG11: =IF(AG$6<Total_Lanes,($BI11*($CH11+BO11)+$CM11*CQ11)*Peak_Time_Eve/3600,"-") -> 41.727803 | AH11: =IF(AH$6<Total_Lanes,($BI11*($CH11+BP11)+$CM11*CR11)*Peak_Time_Eve/3600,"-") -> 493.10969 | AI11: =IF(AI$6<Total_Lanes,($BI11*($CH11+BQ11)+$CM11*CS11)*Peak_Time_Eve/3600,"-") -> 1822.3375 | AJ11: =IF(AJ$6<Total_Lanes,($BI11*($CH11+BR11)+$CM11*CT11)*Peak_Time_Eve/3600,"-") -> 3626.6913 | AK11: =IF(AK$6<Total_Lanes,($BI11*($CH11+BS11)+$CM11*CU11)*Peak_Time_Eve/3600,"-") -> 6157.7655 | AL11: =IF(AL$6<Total_Lanes,($BI11*($CH11+BT11)+$CM11*CV11)*Peak_Time_Eve/3600,"-") -> 9956.3748 | ... AY11: =IF(AY$6<Total_Lanes,($BI11*($CH11+CG11)+$CM11*DI11)*Peak_Time_Eve/3600,"-") -> - | AZ11: =SUMIF(AE11:AY11,BA11,$AE$6:$AY$6) -> 2 | BA11: =MIN(AE11:AY11) -> 27.476336 | BB11: =IF((SUMIF($BM9:$CG9,$AZ11,$BM11:$CG11)+$CH11)<(SUMIF($CO9:$DI9,$AZ11,$CO11:$DI11)+$DJ11),AZ11+1,AZ11) -> 2 | BC11: =SUMIF($AE$6:$AY$6,$BB11,$AE11:$AY11) -> 27.476336 | BF11: 4 | BG11: =$X11 -> 0.29229151 | BH11: =$AC11 -> 6403.09 | BI11: =BH11*(1-BG11) -> 4531.5211 | BJ11: =Peak_Arrival_Manual/K44 -> 8.2763199 | BK11: =900*Peak_Time_Eve*(BJ11/Total_Lanes-1+SQRT((BJ11/Total_Lanes-1)^2+8*(BJ11/Total_Lanes)/(Peak_Time_Eve*$K44*Total_Lanes))) -> 1.2164849 | BL11: =Peak_Arrival_Manual/N44 -> 8.3833141 | BM11: =IF(BM$6<Total_Lanes,900*Peak_Time_Eve*(($BL11/(Total_Lanes-BM$6))-1+SQRT((($BL11/(Total_Lanes-BM$6))-1)^2+8*($BL11/(Total_Lanes-BM$6))/(Peak_Time_Eve*$N44*(Total_Lanes-BM$6)))),"-") -> 1.9353758 | BN11: =IF(BN$6<Total_Lanes,900*Peak_Time_Eve*(($BL11/(Total_Lanes-BN$6))-1+SQRT((($BL11/(Total_Lanes-BN$6))-1)^2+8*($BL11/(Total_Lanes-BN$6))/(Peak_Time_Eve*$N44*(Total_Lanes-BN$6)))),"-") -> 3.4332855 | BO11: =IF(BO$6<Total_Lanes,900*Peak_Time_Eve*(($BL11/(Total_Lanes-BO$6))-1+SQRT((($BL11/(Total_Lanes-BO$6))-1)^2+8*($BL11/(Total_Lanes-BO$6))/(Peak_Time_Eve*$N44*(Total_Lanes-BO$6)))),"-") -> 9.679815 | BP11: =IF(BP$6<Total_Lanes,900*Peak_Time_Eve*(($BL11/(Total_Lanes-BP$6))-1+SQRT((($BL11/(Total_Lanes-BP$6))-1)^2+8*($BL11/(Total_Lanes-BP$6))/(Peak_Time_Eve*$N44*(Total_Lanes-BP$6)))),"-") -> 189.09953 | BQ11: =IF(BQ$6<Total_Lanes,900*Peak_Time_Eve*(($BL11/(Total_Lanes-BQ$6))-1+SQRT((($BL11/(Total_Lanes-BQ$6))-1)^2+8*($BL11/(Total_Lanes-BQ$6))/(Peak_Time_Eve*$N44*(Total_Lanes-BQ$6)))),"-") -> 717.13865 | BR11: =IF(BR$6<Total_Lanes,900*Peak_Time_Eve*(($BL11/(Total_Lanes-BR$6))-1+SQRT((($BL11/(Total_Lanes-BR$6))-1)^2+8*($BL11/(Total_Lanes-BR$6))/(Peak_Time_Eve*$N44*(Total_Lanes-BR$6)))),"-") -> 1433.8823 | BS11: =IF(BS$6<Total_Lanes,900*Peak_Time_Eve*(($BL11/(Total_Lanes-BS$6))-1+SQRT((($BL11/(Total_Lanes-BS$6))-1)^2+8*($BL11/(Total_Lanes-BS$6))/(Peak_Time_Eve*$N44*(Total_Lanes-BS$6)))),"-") -> 2439.2822 | BT11: =IF(BT$6<Total_Lanes,900*Peak_Time_Eve*(($BL11/(Total_Lanes-BT$6))-1+SQRT((($BL11/(Total_Lanes-BT$6))-1)^2+8*($BL11/(Total_Lanes-BT$6))/(Peak_Time_Eve*$N44*(Total_Lanes-BT$6)))),"-") -> 3948.1645 | ... CG11: =IF(CG$6<Total_Lanes,900*Peak_Time_Eve*(($BL11/(Total_Lanes-CG$6))-1+SQRT((($BL11/(Total_Lanes-CG$6))-1)^2+8*($BL11/(Total_Lanes-CG$6))/(Peak_Time_Eve*$N44*(Total_Lanes-CG$6)))),"-") -> - | CH11: =3600/N44 -> 6.66 | CJ11: 4 | CK11: =$X11 -> 0.29229151 | CL11: =$AC11 -> 6403.09 | CM11: =CL11*CK11 -> 1871.5688 | CN11: =CM11/O43 -> 1.2477125 | CO11: =IF(CO$6<Total_Lanes,900*Peak_Time_Eve*(($CN11/CO$6-1)+SQRT(($CN11/CO$6-1)^2+8*($CN11/CO$6)/(Peak_Time_Eve*$O44*CO$6))),"-") -> 903.69425 | CP11: =IF(CP$6<Total_Lanes,900*Peak_Time_Eve*(($CN11/CP$6-1)+SQRT(($CN11/CP$6-1)^2+8*($CN11/CP$6)/(Peak_Time_Eve*$O44*CP$6))),"-") -> 1.9873532 | CQ11: =IF(CQ$6<Total_Lanes,900*Peak_Time_Eve*(($CN11/CQ$6-1)+SQRT(($CN11/CQ$6-1)^2+8*($CN11/CQ$6)/(Peak_Time_Eve*$O44*CQ$6))),"-") -> 0.56948406 | CR11: =IF(CR$6<Total_Lanes,900*Peak_Time_Eve*(($CN11/CR$6-1)+SQRT(($CN11/CR$6-1)^2+8*($CN11/CR$6)/(Peak_Time_Eve*$O44*CR$6))),"-") -> 0.27197208 | CS11: =IF(CS$6<Total_Lanes,900*Peak_Time_Eve*(($CN11/CS$6-1)+SQRT(($CN11/CS$6-1)^2+8*($CN11/CS$6)/(Peak_Time_Eve*$O44*CS$6))),"-") -> 0.15960042 | CT11: =IF(CT$6<Total_Lanes,900*Peak_Time_Eve*(($CN11/CT$6-1)+SQRT(($CN11/CT$6-1)^2+8*($CN11/CT$6)/(Peak_Time_Eve*$O44*CT$6))),"-") -> 0.10501609 | CU11: =IF(CU$6<Total_Lanes,900*Peak_Time_Eve*(($CN11/CU$6-1)+SQRT(($CN11/CU$6-1)^2+8*($CN11/CU$6)/(Peak_Time_Eve*$O44*CU$6))),"-") -> 0.074366312 | CV11: =IF(CV$6<Total_Lanes,900*Peak_Time_Eve*(($CN11/CV$6-1)+SQRT(($CN11/CV$6-1)^2+8*($CN11/CV$6)/(Peak_Time_Eve*$O44*CV$6))),"-") -> 0.055434094 | ... DI11: =IF(DI$6<Total_Lanes,900*Peak_Time_Eve*(($CN11/DI$6-1)+SQRT(($CN11/DI$6-1)^2+8*($CN11/DI$6)/(Peak_Time_Eve*$O44*DI$6))),"-") -> - | DJ11: =3600/O44 -> 2.4
H12: 5 | I12: ='Input-Detail'!E19 -> 21762130 | J12: 0.29898451 | K12: =AC12 -> 6568.8625 | L12: =AD59 -> 10.782368 | M12: =AD12 -> 27.749634 | N12: =SUM(L12:M12) -> 38.532002 | O12: =$S$34*N12 -> 10018.321 | P12: =BC59 -> 7.4051694 | Q12: =BC12 -> 26.900073 | R12: =SUM(P12:Q12) -> 34.305243 | S12: =$S$34*R12 -> 8919.3632 | V12: 5 | W12: =W$7+(W$27-W$7)*$V12/20 -> 21762130 | X12: =MIN((J11+0.1),0.95) -> 0.34713691 | Y12: ='Input-Detail'!E19/Z12 -> 9384.0892 | Z12: =Z11 -> 2319.0455 | AA12: =AA11 -> 2 | AB12: =AB11 -> 0.7 | AC12: =Y12*AB12 -> 6568.8625 | AD12: =Peak_Time_Eve*$BH12*(3600/K45+BK12)/3600 -> 27.749634 | AE12: =IF(AE$6<Total_Lanes,($BI12*($CH12+BM12)+$CM12*CO12)*Peak_Time_Eve/3600,"-") -> 2400.9541 | AF12: =IF(AF$6<Total_Lanes,($BI12*($CH12+BN12)+$CM12*CP12)*Peak_Time_Eve/3600,"-") -> 26.900073 | AG12: =IF(AG$6<Total_Lanes,($BI12*($CH12+BO12)+$CM12*CQ12)*Peak_Time_Eve/3600,"-") -> 30.304528 | AH12: =IF(AH$6<Total_Lanes,($BI12*($CH12+BP12)+$CM12*CR12)*Peak_Time_Eve/3600,"-") -> 126.62547 | AI12: =IF(AI$6<Total_Lanes,($BI12*($CH12+BQ12)+$CM12*CS12)*Peak_Time_Eve/3600,"-") -> 1210.0302 | AJ12: =IF(AJ$6<Total_Lanes,($BI12*($CH12+BR12)+$CM12*CT12)*Peak_Time_Eve/3600,"-") -> 2827.4979 | AK12: =IF(AK$6<Total_Lanes,($BI12*($CH12+BS12)+$CM12*CU12)*Peak_Time_Eve/3600,"-") -> 5100.8194 | AL12: =IF(AL$6<Total_Lanes,($BI12*($CH12+BT12)+$CM12*CV12)*Peak_Time_Eve/3600,"-") -> 8513.5741 | ... AY12: =IF(AY$6<Total_Lanes,($BI12*($CH12+CG12)+$CM12*DI12)*Peak_Time_Eve/3600,"-") -> - | AZ12: =SUMIF(AE12:AY12,BA12,$AE$6:$AY$6) -> 2 | BA12: =MIN(AE12:AY12) -> 26.900073 | BB12: =IF((SUMIF($BM10:$CG10,$AZ12,$BM12:$CG12)+$CH12)<(SUMIF($CO10:$DI10,$AZ12,$CO12:$DI12)+$DJ12),AZ12+1,AZ12) -> 2 | BC12: =SUMIF($AE$6:$AY$6,$BB12,$AE12:$AY12) -> 26.900073 | BF12: 5 | BG12: =$X12 -> 0.34713691 | BH12: =$AC12 -> 6568.8625 | BI12: =BH12*(1-BG12) -> 4288.5679 | BJ12: =Peak_Arrival_Manual/K45 -> 7.8325927 | BK12: =900*Peak_Time_Eve*(BJ12/Total_Lanes-1+SQRT((BJ12/Total_Lanes-1)^2+8*(BJ12/Total_Lanes)/(Peak_Time_Eve*$K45*Total_Lanes))) -> 1.028956 | BL12: =Peak_Arrival_Manual/N45 -> 7.959165 | BM12: =IF(BM$6<Total_Lanes,900*Peak_Time_Eve*(($BL12/(Total_Lanes-BM$6))-1+SQRT((($BL12/(Total_Lanes-BM$6))-1)^2+8*($BL12/(Total_Lanes-BM$6))/(Peak_Time_Eve*$N45*(Total_Lanes-BM$6)))),"-") -> 1.5872582 | BN12: =IF(BN$6<Total_Lanes,900*Peak_Time_Eve*(($BL12/(Total_Lanes-BN$6))-1+SQRT((($BL12/(Total_Lanes-BN$6))-1)^2+8*($BL12/(Total_Lanes-BN$6))/(Peak_Time_Eve*$N45*(Total_Lanes-BN$6)))),"-") -> 2.5964814 | BO12: =IF(BO$6<Total_Lanes,900*Peak_Time_Eve*(($BL12/(Total_Lanes-BO$6))-1+SQRT((($BL12/(Total_Lanes-BO$6))-1)^2+8*($BL12/(Total_Lanes-BO$6))/(Peak_Time_Eve*$N45*(Total_Lanes-BO$6)))),"-") -> 5.6014021 | BP12: =IF(BP$6<Total_Lanes,900*Peak_Time_Eve*(($BL12/(Total_Lanes-BP$6))-1+SQRT((($BL12/(Total_Lanes-BP$6))-1)^2+8*($BL12/(Total_Lanes-BP$6))/(Peak_Time_Eve*$N45*(Total_Lanes-BP$6)))),"-") -> 46.270516 | BQ12: =IF(BQ$6<Total_Lanes,900*Peak_Time_Eve*(($BL12/(Total_Lanes-BQ$6))-1+SQRT((($BL12/(Total_Lanes-BQ$6))-1)^2+8*($BL12/(Total_Lanes-BQ$6))/(Peak_Time_Eve*$N45*(Total_Lanes-BQ$6)))),"-") -> 501.08178 | BR12: =IF(BR$6<Total_Lanes,900*Peak_Time_Eve*(($BL12/(Total_Lanes-BR$6))-1+SQRT((($BL12/(Total_Lanes-BR$6))-1)^2+8*($BL12/(Total_Lanes-BR$6))/(Peak_Time_Eve*$N45*(Total_Lanes-BR$6)))),"-") -> 1180.0055 | BS12: =IF(BS$6<Total_Lanes,900*Peak_Time_Eve*(($BL12/(Total_Lanes-BS$6))-1+SQRT((($BL12/(Total_Lanes-BS$6))-1)^2+8*($BL12/(Total_Lanes-BS$6))/(Peak_Time_Eve*$N45*(Total_Lanes-BS$6)))),"-") -> 2134.1868 | BT12: =IF(BT$6<Total_Lanes,900*Peak_Time_Eve*(($BL12/(Total_Lanes-BT$6))-1+SQRT((($BL12/(Total_Lanes-BT$6))-1)^2+8*($BL12/(Total_Lanes-BT$6))/(Peak_Time_Eve*$N45*(Total_Lanes-BT$6)))),"-") -> 3566.6032 | ... CG12: =IF(CG$6<Total_Lanes,900*Peak_Time_Eve*(($BL12/(Total_Lanes-CG$6))-1+SQRT((($BL12/(Total_Lanes-CG$6))-1)^2+8*($BL12/(Total_Lanes-CG$6))/(Peak_Time_Eve*$N45*(Total_Lanes-CG$6)))),"-") -> - | CH12: =3600/N45 -> 6.68125 | CJ12: 5 | CK12: =$X12 -> 0.34713691 | CL12: =$AC12 -> 6568.8625 | CM12: =CL12*CK12 -> 2280.2946 | CN12: =CM12/O44 -> 1.5201964 | CO12: =IF(CO$6<Total_Lanes,900*Peak_Time_Eve*(($CN12/CO$6-1)+SQRT(($CN12/CO$6-1)^2+8*($CN12/CO$6)/(Peak_Time_Eve*$O45*CO$6))),"-") -> 1879.6946 | CP12: =IF(CP$6<Total_Lanes,900*Peak_Time_Eve*(($CN12/CP$6-1)+SQRT(($CN12/CP$6-1)^2+8*($CN12/CP$6)/(Peak_Time_Eve*$O45*CP$6))),"-") -> 3.7854545 | CQ12: =IF(CQ$6<Total_Lanes,900*Peak_Time_Eve*(($CN12/CQ$6-1)+SQRT(($CN12/CQ$6-1)^2+8*($CN12/CQ$6)/(Peak_Time_Eve*$O45*CQ$6))),"-") -> 0.82145683 | CR12: =IF(CR$6<Total_Lanes,900*Peak_Time_Eve*(($CN12/CR$6-1)+SQRT(($CN12/CR$6-1)^2+8*($CN12/CR$6)/(Peak_Time_Eve*$O45*CR$6))),"-") -> 0.36775798 | CS12: =IF(CS$6<Total_Lanes,900*Peak_Time_Eve*(($CN12/CS$6-1)+SQRT(($CN12/CS$6-1)^2+8*($CN12/CS$6)/(Peak_Time_Eve*$O45*CS$6))),"-") -> 0.20967655 | CT12: =IF(CT$6<Total_Lanes,900*Peak_Time_Eve*(($CN12/CT$6-1)+SQRT(($CN12/CT$6-1)^2+8*($CN12/CT$6)/(Peak_Time_Eve*$O45*CT$6))),"-") -> 0.13573092 | CU12: =IF(CU$6<Total_Lanes,900*Peak_Time_Eve*(($CN12/CU$6-1)+SQRT(($CN12/CU$6-1)^2+8*($CN12/CU$6)/(Peak_Time_Eve*$O45*CU$6))),"-") -> 0.095111548 | CV12: =IF(CV$6<Total_Lanes,900*Peak_Time_Eve*(($CN12/CV$6-1)+SQRT(($CN12/CV$6-1)^2+8*($CN12/CV$6)/(Peak_Time_Eve*$O45*CV$6))),"-") -> 0.070379897 | ... DI12: =IF(DI$6<Total_Lanes,900*Peak_Time_Eve*(($CN12/DI$6-1)+SQRT(($CN12/DI$6-1)^2+8*($CN12/DI$6)/(Peak_Time_Eve*$O45*DI$6))),"-") -> - | DJ12: =3600/O45 -> 2.4
H13: 6 | I13: ='Input-Detail'!E20 -> 22311321 | J13: 0.34881248 | K13: =AC13 -> 6734.6349 | L13: =AD60 -> 11.062503 | M13: =AD13 -> 27.887206 | N13: =SUM(L13:M13) -> 38.949709 | O13: =$S$34*N13 -> 10126.924 | P13: =BC60 -> 7.036956 | Q13: =BC13 -> 25.404034 | R13: =SUM(P13:Q13) -> 32.44099 | S13: =$S$34*R13 -> 8434.6573 | V13: 6 | W13: =W$7+(W$27-W$7)*$V13/20 -> 22311321 | X13: =MIN((J12+0.1),0.95) -> 0.39898451 | Y13: ='Input-Detail'!E20/Z13 -> 9620.9071 | Z13: =Z12 -> 2319.0455 | AA13: =AA12 -> 2 | AB13: =AB12 -> 0.7 | AC13: =Y13*AB13 -> 6734.6349 | AD13: =Peak_Time_Eve*$BH13*(3600/K46+BK13)/3600 -> 27.887206 | AE13: =IF(AE$6<Total_Lanes,($BI13*($CH13+BM13)+$CM13*CO13)*Peak_Time_Eve/3600,"-") -> 4278.8466 | AF13: =IF(AF$6<Total_Lanes,($BI13*($CH13+BN13)+$CM13*CP13)*Peak_Time_Eve/3600,"-") -> 34.64921 | AG13: =IF(AG$6<Total_Lanes,($BI13*($CH13+BO13)+$CM13*CQ13)*Peak_Time_Eve/3600,"-") -> 25.404034 | AH13: =IF(AH$6<Total_Lanes,($BI13*($CH13+BP13)+$CM13*CR13)*Peak_Time_Eve/3600,"-") -> 44.619275 | AI13: =IF(AI$6<Total_Lanes,($BI13*($CH13+BQ13)+$CM13*CS13)*Peak_Time_Eve/3600,"-") -> 664.12642 | AJ13: =IF(AJ$6<Total_Lanes,($BI13*($CH13+BR13)+$CM13*CT13)*Peak_Time_Eve/3600,"-") -> 2099.7996 | AK13: =IF(AK$6<Total_Lanes,($BI13*($CH13+BS13)+$CM13*CU13)*Peak_Time_Eve/3600,"-") -> 4129.8993 | AL13: =IF(AL$6<Total_Lanes,($BI13*($CH13+BT13)+$CM13*CV13)*Peak_Time_Eve/3600,"-") -> 7179.174 | ... AY13: =IF(AY$6<Total_Lanes,($BI13*($CH13+CG13)+$CM13*DI13)*Peak_Time_Eve/3600,"-") -> - | AZ13: =SUMIF(AE13:AY13,BA13,$AE$6:$AY$6) -> 3 | BA13: =MIN(AE13:AY13) -> 25.404034 | BB13: =IF((SUMIF($BM11:$CG11,$AZ13,$BM13:$CG13)+$CH13)<(SUMIF($CO11:$DI11,$AZ13,$CO13:$DI13)+$DJ13),AZ13+1,AZ13) -> 3 | BC13: =SUMIF($AE$6:$AY$6,$BB13,$AE13:$AY13) -> 25.404034 | BF13: 6 | BG13: =$X13 -> 0.39898451 | BH13: =$AC13 -> 6734.6349 | BI13: =BH13*(1-BG13) -> 4047.6199 | BJ13: =Peak_Arrival_Manual/K46 -> 7.392528 | BK13: =900*Peak_Time_Eve*(BJ13/Total_Lanes-1+SQRT((BJ13/Total_Lanes-1)^2+8*(BJ13/Total_Lanes)/(Peak_Time_Eve*$K46*Total_Lanes))) -> 0.87855475 | BL13: =Peak_Arrival_Manual/N46 -> 7.5358812 | BM13: =IF(BM$6<Total_Lanes,900*Peak_Time_Eve*(($BL13/(Total_Lanes-BM$6))-1+SQRT((($BL13/(Total_Lanes-BM$6))-1)^2+8*($BL13/(Total_Lanes-BM$6))/(Peak_Time_Eve*$N46*(Total_Lanes-BM$6)))),"-") -> 1.3239711 | BN13: =IF(BN$6<Total_Lanes,900*Peak_Time_Eve*(($BL13/(Total_Lanes-BN$6))-1+SQRT((($BL13/(Total_Lanes-BN$6))-1)^2+8*($BL13/(Total_Lanes-BN$6))/(Peak_Time_Eve*$N46*(Total_Lanes-BN$6)))),"-") -> 2.0450746 | BO13: =IF(BO$6<Total_Lanes,900*Peak_Time_Eve*(($BL13/(Total_Lanes-BO$6))-1+SQRT((($BL13/(Total_Lanes-BO$6))-1)^2+8*($BL13/(Total_Lanes-BO$6))/(Peak_Time_Eve*$N46*(Total_Lanes-BO$6)))),"-") -> 3.8083517 | BP13: =IF(BP$6<Total_Lanes,900*Peak_Time_Eve*(($BL13/(Total_Lanes-BP$6))-1+SQRT((($BL13/(Total_Lanes-BP$6))-1)^2+8*($BL13/(Total_Lanes-BP$6))/(Peak_Time_Eve*$N46*(Total_Lanes-BP$6)))),"-") -> 12.816977 | BQ13: =IF(BQ$6<Total_Lanes,900*Peak_Time_Eve*(($BL13/(Total_Lanes-BQ$6))-1+SQRT((($BL13/(Total_Lanes-BQ$6))-1)^2+8*($BL13/(Total_Lanes-BQ$6))/(Peak_Time_Eve*$N46*(Total_Lanes-BQ$6)))),"-") -> 288.46049 | BR13: =IF(BR$6<Total_Lanes,900*Peak_Time_Eve*(($BL13/(Total_Lanes-BR$6))-1+SQRT((($BL13/(Total_Lanes-BR$6))-1)^2+8*($BL13/(Total_Lanes-BR$6))/(Peak_Time_Eve*$N46*(Total_Lanes-BR$6)))),"-") -> 926.97753 | BS13: =IF(BS$6<Total_Lanes,900*Peak_Time_Eve*(($BL13/(Total_Lanes-BS$6))-1+SQRT((($BL13/(Total_Lanes-BS$6))-1)^2+8*($BL13/(Total_Lanes-BS$6))/(Peak_Time_Eve*$N46*(Total_Lanes-BS$6)))),"-") -> 1829.8094 | BT13: =IF(BT$6<Total_Lanes,900*Peak_Time_Eve*(($BL13/(Total_Lanes-BT$6))-1+SQRT((($BL13/(Total_Lanes-BT$6))-1)^2+8*($BL13/(Total_Lanes-BT$6))/(Peak_Time_Eve*$N46*(Total_Lanes-BT$6)))),"-") -> 3185.8603 | ... CG13: =IF(CG$6<Total_Lanes,900*Peak_Time_Eve*(($BL13/(Total_Lanes-CG$6))-1+SQRT((($BL13/(Total_Lanes-CG$6))-1)^2+8*($BL13/(Total_Lanes-CG$6))/(Peak_Time_Eve*$N46*(Total_Lanes-CG$6)))),"-") -> - | CH13: =3600/N46 -> 6.7025 | CJ13: 6 | CK13: =$X13 -> 0.39898451 | CL13: =$AC13 -> 6734.6349 | CM13: =CL13*CK13 -> 2687.0151 | CN13: =CM13/O45 -> 1.7913434 | CO13: =IF(CO$6<Total_Lanes,900*Peak_Time_Eve*(($CN13/CO$6-1)+SQRT(($CN13/CO$6-1)^2+8*($CN13/CO$6)/(Peak_Time_Eve*$O46*CO$6))),"-") -> 2854.2586 | CP13: =IF(CP$6<Total_Lanes,900*Peak_Time_Eve*(($CN13/CP$6-1)+SQRT(($CN13/CP$6-1)^2+8*($CN13/CP$6)/(Peak_Time_Eve*$O46*CP$6))),"-") -> 10.034079 | CQ13: =IF(CQ$6<Total_Lanes,900*Peak_Time_Eve*(($CN13/CQ$6-1)+SQRT(($CN13/CQ$6-1)^2+8*($CN13/CQ$6)/(Peak_Time_Eve*$O46*CQ$6))),"-") -> 1.1847079 | CR13: =IF(CR$6<Total_Lanes,900*Peak_Time_Eve*(($CN13/CR$6-1)+SQRT(($CN13/CR$6-1)^2+8*($CN13/CR$6)/(Peak_Time_Eve*$O46*CR$6))),"-") -> 0.48651429 | CS13: =IF(CS$6<Total_Lanes,900*Peak_Time_Eve*(($CN13/CS$6-1)+SQRT(($CN13/CS$6-1)^2+8*($CN13/CS$6)/(Peak_Time_Eve*$O46*CS$6))),"-") -> 0.2679455 | CT13: =IF(CT$6<Total_Lanes,900*Peak_Time_Eve*(($CN13/CT$6-1)+SQRT(($CN13/CT$6-1)^2+8*($CN13/CT$6)/(Peak_Time_Eve*$O46*CT$6))),"-") -> 0.17024174 | CU13: =IF(CU$6<Total_Lanes,900*Peak_Time_Eve*(($CN13/CU$6-1)+SQRT(($CN13/CU$6-1)^2+8*($CN13/CU$6)/(Peak_Time_Eve*$O46*CU$6))),"-") -> 0.11790907 | CV13: =IF(CV$6<Total_Lanes,900*Peak_Time_Eve*(($CN13/CV$6-1)+SQRT(($CN13/CV$6-1)^2+8*($CN13/CV$6)/(Peak_Time_Eve*$O46*CV$6))),"-") -> 0.08655437 | ... DI13: =IF(DI$6<Total_Lanes,900*Peak_Time_Eve*(($CN13/DI$6-1)+SQRT(($CN13/DI$6-1)^2+8*($CN13/DI$6)/(Peak_Time_Eve*$O46*DI$6))),"-") -> - | DJ13: =3600/O46 -> 2.4
H14: 7 | I14: ='Input-Detail'!E21 -> 22860512 | J14: 0.39671513 | K14: =AC14 -> 6900.4074 | L14: =AD61 -> 11.343812 | M14: =AD14 -> 28.091534 | N14: =SUM(L14:M14) -> 39.435345 | O14: =$S$34*N14 -> 10253.19 | P14: =BC61 -> 6.6813999 | Q14: =BC14 -> 23.13272 | R14: =SUM(P14:Q14) -> 29.81412 | S14: =$S$34*R14 -> 7751.6712 | V14: 7 | W14: =W$7+(W$27-W$7)*$V14/20 -> 22860512 | X14: =MIN((J13+0.1),0.95) -> 0.44881248 | Y14: ='Input-Detail'!E21/Z14 -> 9857.7249 | Z14: =Z13 -> 2319.0455 | AA14: =AA13 -> 2 | AB14: =AB13 -> 0.7 | AC14: =Y14*AB14 -> 6900.4074 | AD14: =Peak_Time_Eve*$BH14*(3600/K47+BK14)/3600 -> 28.091534 | AE14: =IF(AE$6<Total_Lanes,($BI14*($CH14+BM14)+$CM14*CO14)*Peak_Time_Eve/3600,"-") -> 6619.0347 | AF14: =IF(AF$6<Total_Lanes,($BI14*($CH14+BN14)+$CM14*CP14)*Peak_Time_Eve/3600,"-") -> 270.21459 | AG14: =IF(AG$6<Total_Lanes,($BI14*($CH14+BO14)+$CM14*CQ14)*Peak_Time_Eve/3600,"-") -> 23.13272 | AH14: =IF(AH$6<Total_Lanes,($BI14*($CH14+BP14)+$CM14*CR14)*Peak_Time_Eve/3600,"-") -> 29.15797 | AI14: =IF(AI$6<Total_Lanes,($BI14*($CH14+BQ14)+$CM14*CS14)*Peak_Time_Eve/3600,"-") -> 208.38261 | AJ14: =IF(AJ$6<Total_Lanes,($BI14*($CH14+BR14)+$CM14*CT14)*Peak_Time_Eve/3600,"-") -> 1428.8942 | AK14: =IF(AK$6<Total_Lanes,($BI14*($CH14+BS14)+$CM14*CU14)*Peak_Time_Eve/3600,"-") -> 3224.4851 | AL14: =IF(AL$6<Total_Lanes,($BI14*($CH14+BT14)+$CM14*CV14)*Peak_Time_Eve/3600,"-") -> 5924.795 | ... AY14: =IF(AY$6<Total_Lanes,($BI14*($CH14+CG14)+$CM14*DI14)*Peak_Time_Eve/3600,"-") -> - | AZ14: =SUMIF(AE14:AY14,BA14,$AE$6:$AY$6) -> 3 | BA14: =MIN(AE14:AY14) -> 23.13272 | BB14: =IF((SUMIF($BM12:$CG12,$AZ14,$BM14:$CG14)+$CH14)<(SUMIF($CO12:$DI12,$AZ14,$CO14:$DI14)+$DJ14),AZ14+1,AZ14) -> 3 | BC14: =SUMIF($AE$6:$AY$6,$BB14,$AE14:$AY14) -> 23.13272 | BF14: 7 | BG14: =$X14 -> 0.44881248 | BH14: =$AC14 -> 6900.4074 | BI14: =BH14*(1-BG14) -> 3803.4184 | BJ14: =Peak_Arrival_Manual/K47 -> 6.9465212 | BK14: =900*Peak_Time_Eve*(BJ14/Total_Lanes-1+SQRT((BJ14/Total_Lanes-1)^2+8*(BJ14/Total_Lanes)/(Peak_Time_Eve*$K47*Total_Lanes))) -> 0.75279344 | BL14: =Peak_Arrival_Manual/N47 -> 7.1036763 | BM14: =IF(BM$6<Total_Lanes,900*Peak_Time_Eve*(($BL14/(Total_Lanes-BM$6))-1+SQRT((($BL14/(Total_Lanes-BM$6))-1)^2+8*($BL14/(Total_Lanes-BM$6))/(Peak_Time_Eve*$N47*(Total_Lanes-BM$6)))),"-") -> 1.1134429 | BN14: =IF(BN$6<Total_Lanes,900*Peak_Time_Eve*(($BL14/(Total_Lanes-BN$6))-1+SQRT((($BL14/(Total_Lanes-BN$6))-1)^2+8*($BL14/(Total_Lanes-BN$6))/(Peak_Time_Eve*$N47*(Total_Lanes-BN$6)))),"-") -> 1.6465024 | BO14: =IF(BO$6<Total_Lanes,900*Peak_Time_Eve*(($BL14/(Total_Lanes-BO$6))-1+SQRT((($BL14/(Total_Lanes-BO$6))-1)^2+8*($BL14/(Total_Lanes-BO$6))/(Peak_Time_Eve*$N47*(Total_Lanes-BO$6)))),"-") -> 2.7883431 | BP14: =IF(BP$6<Total_Lanes,900*Peak_Time_Eve*(($BL14/(Total_Lanes-BP$6))-1+SQRT((($BL14/(Total_Lanes-BP$6))-1)^2+8*($BL14/(Total_Lanes-BP$6))/(Peak_Time_Eve*$N47*(Total_Lanes-BP$6)))),"-") -> 6.5544939 | BQ14: =IF(BQ$6<Total_Lanes,900*Peak_Time_Eve*(($BL14/(Total_Lanes-BQ$6))-1+SQRT((($BL14/(Total_Lanes-BQ$6))-1)^2+8*($BL14/(Total_Lanes-BQ$6))/(Peak_Time_Eve*$N47*(Total_Lanes-BQ$6)))),"-") -> 91.620217 | BR14: =IF(BR$6<Total_Lanes,900*Peak_Time_Eve*(($BL14/(Total_Lanes-BR$6))-1+SQRT((($BL14/(Total_Lanes-BR$6))-1)^2+8*($BL14/(Total_Lanes-BR$6))/(Peak_Time_Eve*$N47*(Total_Lanes-BR$6)))),"-") -> 669.34165 | BS14: =IF(BS$6<Total_Lanes,900*Peak_Time_Eve*(($BL14/(Total_Lanes-BS$6))-1+SQRT((($BL14/(Total_Lanes-BS$6))-1)^2+8*($BL14/(Total_Lanes-BS$6))/(Peak_Time_Eve*$N47*(Total_Lanes-BS$6)))),"-") -> 1519.1743 | BT14: =IF(BT$6<Total_Lanes,900*Peak_Time_Eve*(($BL14/(Total_Lanes-BT$6))-1+SQRT((($BL14/(Total_Lanes-BT$6))-1)^2+8*($BL14/(Total_Lanes-BT$6))/(Peak_Time_Eve*$N47*(Total_Lanes-BT$6)))),"-") -> 2797.1507 | ... CG14: =IF(CG$6<Total_Lanes,900*Peak_Time_Eve*(($BL14/(Total_Lanes-CG$6))-1+SQRT((($BL14/(Total_Lanes-CG$6))-1)^2+8*($BL14/(Total_Lanes-CG$6))/(Peak_Time_Eve*$N47*(Total_Lanes-CG$6)))),"-") -> - | CH14: =3600/N47 -> 6.72375 | CJ14: 7 | CK14: =$X14 -> 0.44881248 | CL14: =$AC14 -> 6900.4074 | CM14: =CL14*CK14 -> 3096.989 | CN14: =CM14/O46 -> 2.0646593 | CO14: =IF(CO$6<Total_Lanes,900*Peak_Time_Eve*(($CN14/CO$6-1)+SQRT(($CN14/CO$6-1)^2+8*($CN14/CO$6)/(Peak_Time_Eve*$O47*CO$6))),"-") -> 3837.4222 | CP14: =IF(CP$6<Total_Lanes,900*Peak_Time_Eve*(($CN14/CP$6-1)+SQRT(($CN14/CP$6-1)^2+8*($CN14/CP$6)/(Peak_Time_Eve*$O47*CP$6))),"-") -> 146.77181 | CQ14: =IF(CQ$6<Total_Lanes,900*Peak_Time_Eve*(($CN14/CQ$6-1)+SQRT(($CN14/CQ$6-1)^2+8*($CN14/CQ$6)/(Peak_Time_Eve*$O47*CQ$6))),"-") -> 1.7631404 | CR14: =IF(CR$6<Total_Lanes,900*Peak_Time_Eve*(($CN14/CR$6-1)+SQRT(($CN14/CR$6-1)^2+8*($CN14/CR$6)/(Peak_Time_Eve*$O47*CR$6))),"-") -> 0.6398567 | CS14: =IF(CS$6<Total_Lanes,900*Peak_Time_Eve*(($CN14/CS$6-1)+SQRT(($CN14/CS$6-1)^2+8*($CN14/CS$6)/(Peak_Time_Eve*$O47*CS$6))),"-") -> 0.33756839 | CT14: =IF(CT$6<Total_Lanes,900*Peak_Time_Eve*(($CN14/CT$6-1)+SQRT(($CN14/CT$6-1)^2+8*($CN14/CT$6)/(Peak_Time_Eve*$O47*CT$6))),"-") -> 0.20983961 | CU14: =IF(CU$6<Total_Lanes,900*Peak_Time_Eve*(($CN14/CU$6-1)+SQRT(($CN14/CU$6-1)^2+8*($CN14/CU$6)/(Peak_Time_Eve*$O47*CU$6))),"-") -> 0.14342337 | CV14: =IF(CV$6<Total_Lanes,900*Peak_Time_Eve*(($CN14/CV$6-1)+SQRT(($CN14/CV$6-1)^2+8*($CN14/CV$6)/(Peak_Time_Eve*$O47*CV$6))),"-") -> 0.1043535 | ... DI14: =IF(DI$6<Total_Lanes,900*Peak_Time_Eve*(($CN14/DI$6-1)+SQRT(($CN14/DI$6-1)^2+8*($CN14/DI$6)/(Peak_Time_Eve*$O47*DI$6))),"-") -> - | DJ14: =3600/O47 -> 2.4
H15: 8 | I15: ='Input-Detail'!E22 -> 23409704 | J15: 0.44303751 | K15: =AC15 -> 7066.1799 | L15: =AD62 -> 11.626355 | M15: =AD15 -> 28.348102 | N15: =SUM(L15:M15) -> 39.974457 | O15: =$S$34*N15 -> 10393.359 | P15: =BC62 -> 6.2752119 | Q15: =BC15 -> 23.048736 | R15: =SUM(P15:Q15) -> 29.323948 | S15: =$S$34*R15 -> 7624.2265 | V15: 8 | W15: =W$7+(W$27-W$7)*$V15/20 -> 23409704 | X15: =MIN((J14+0.1),0.95) -> 0.49671513 | Y15: ='Input-Detail'!E22/Z15 -> 10094.543 | Z15: =Z14 -> 2319.0455 | AA15: =AA14 -> 2 | AB15: =AB14 -> 0.7 | AC15: =Y15*AB15 -> 7066.1799 | AD15: =Peak_Time_Eve*$BH15*(3600/K48+BK15)/3600 -> 28.348102 | AE15: =IF(AE$6<Total_Lanes,($BI15*($CH15+BM15)+$CM15*CO15)*Peak_Time_Eve/3600,"-") -> 9429.2574 | AF15: =IF(AF$6<Total_Lanes,($BI15*($CH15+BN15)+$CM15*CP15)*Peak_Time_Eve/3600,"-") -> 1224.9543 | AG15: =IF(AG$6<Total_Lanes,($BI15*($CH15+BO15)+$CM15*CQ15)*Peak_Time_Eve/3600,"-") -> 23.048736 | AH15: =IF(AH$6<Total_Lanes,($BI15*($CH15+BP15)+$CM15*CR15)*Peak_Time_Eve/3600,"-") -> 23.21964 | AI15: =IF(AI$6<Total_Lanes,($BI15*($CH15+BQ15)+$CM15*CS15)*Peak_Time_Eve/3600,"-") -> 48.38083 | AJ15: =IF(AJ$6<Total_Lanes,($BI15*($CH15+BR15)+$CM15*CT15)*Peak_Time_Eve/3600,"-") -> 821.63386 | AK15: =IF(AK$6<Total_Lanes,($BI15*($CH15+BS15)+$CM15*CU15)*Peak_Time_Eve/3600,"-") -> 2390.123 | AL15: =IF(AL$6<Total_Lanes,($BI15*($CH15+BT15)+$CM15*CV15)*Peak_Time_Eve/3600,"-") -> 4757.3282 | ... AY15: =IF(AY$6<Total_Lanes,($BI15*($CH15+CG15)+$CM15*DI15)*Peak_Time_Eve/3600,"-") -> - | AZ15: =SUMIF(AE15:AY15,BA15,$AE$6:$AY$6) -> 3 | BA15: =MIN(AE15:AY15) -> 23.048736 | BB15: =IF((SUMIF($BM13:$CG13,$AZ15,$BM15:$CG15)+$CH15)<(SUMIF($CO13:$DI13,$AZ15,$CO15:$DI15)+$DJ15),AZ15+1,AZ15) -> 3 | BC15: =SUMIF($AE$6:$AY$6,$BB15,$AE15:$AY15) -> 23.048736 | BF15: 8 | BG15: =$X15 -> 0.49671513 | BH15: =$AC15 -> 7066.1799 | BI15: =BH15*(1-BG15) -> 3556.3014 | BJ15: =Peak_Arrival_Manual/K48 -> 6.4951894 | BK15: =900*Peak_Time_Eve*(BJ15/Total_Lanes-1+SQRT((BJ15/Total_Lanes-1)^2+8*(BJ15/Total_Lanes)/(Peak_Time_Eve*$K48*Total_Lanes))) -> 0.6462403 | BL15: =Peak_Arrival_Manual/N48 -> 6.6631259 | BM15: =IF(BM$6<Total_Lanes,900*Peak_Time_Eve*(($BL15/(Total_Lanes-BM$6))-1+SQRT((($BL15/(Total_Lanes-BM$6))-1)^2+8*($BL15/(Total_Lanes-BM$6))/(Peak_Time_Eve*$N48*(Total_Lanes-BM$6)))),"-") -> 0.94146135 | BN15: =IF(BN$6<Total_Lanes,900*Peak_Time_Eve*(($BL15/(Total_Lanes-BN$6))-1+SQRT((($BL15/(Total_Lanes-BN$6))-1)^2+8*($BL15/(Total_Lanes-BN$6))/(Peak_Time_Eve*$N48*(Total_Lanes-BN$6)))),"-") -> 1.3453462 | BO15: =IF(BO$6<Total_Lanes,900*Peak_Time_Eve*(($BL15/(Total_Lanes-BO$6))-1+SQRT((($BL15/(Total_Lanes-BO$6))-1)^2+8*($BL15/(Total_Lanes-BO$6))/(Peak_Time_Eve*$N48*(Total_Lanes-BO$6)))),"-") -> 2.132027 | BP15: =IF(BP$6<Total_Lanes,900*Peak_Time_Eve*(($BL15/(Total_Lanes-BP$6))-1+SQRT((($BL15/(Total_Lanes-BP$6))-1)^2+8*($BL15/(Total_Lanes-BP$6))/(Peak_Time_Eve*$N48*(Total_Lanes-BP$6)))),"-") -> 4.1732764 | BQ15: =IF(BQ$6<Total_Lanes,900*Peak_Time_Eve*(($BL15/(Total_Lanes-BQ$6))-1+SQRT((($BL15/(Total_Lanes-BQ$6))-1)^2+8*($BL15/(Total_Lanes-BQ$6))/(Peak_Time_Eve*$N48*(Total_Lanes-BQ$6)))),"-") -> 17.326033 | BR15: =IF(BR$6<Total_Lanes,900*Peak_Time_Eve*(($BL15/(Total_Lanes-BR$6))-1+SQRT((($BL15/(Total_Lanes-BR$6))-1)^2+8*($BL15/(Total_Lanes-BR$6))/(Peak_Time_Eve*$N48*(Total_Lanes-BR$6)))),"-") -> 408.86755 | BS15: =IF(BS$6<Total_Lanes,900*Peak_Time_Eve*(($BL15/(Total_Lanes-BS$6))-1+SQRT((($BL15/(Total_Lanes-BS$6))-1)^2+8*($BL15/(Total_Lanes-BS$6))/(Peak_Time_Eve*$N48*(Total_Lanes-BS$6)))),"-") -> 1202.8311 | BT15: =IF(BT$6<Total_Lanes,900*Peak_Time_Eve*(($BL15/(Total_Lanes-BT$6))-1+SQRT((($BL15/(Total_Lanes-BT$6))-1)^2+8*($BL15/(Total_Lanes-BT$6))/(Peak_Time_Eve*$N48*(Total_Lanes-BT$6)))),"-") -> 2401.0249 | ... CG15: =IF(CG$6<Total_Lanes,900*Peak_Time_Eve*(($BL15/(Total_Lanes-CG$6))-1+SQRT((($BL15/(Total_Lanes-CG$6))-1)^2+8*($BL15/(Total_Lanes-CG$6))/(Peak_Time_Eve*$N48*(Total_Lanes-CG$6)))),"-") -> - | CH15: =3600/N48 -> 6.745 | CJ15: 8 | CK15: =$X15 -> 0.49671513 | CL15: =$AC15 -> 7066.1799 | CM15: =CL15*CK15 -> 3509.8785 | CN15: =CM15/O47 -> 2.339919 | CO15: =IF(CO$6<Total_Lanes,900*Peak_Time_Eve*(($CN15/CO$6-1)+SQRT(($CN15/CO$6-1)^2+8*($CN15/CO$6)/(Peak_Time_Eve*$O48*CO$6))),"-") -> 4827.8959 | CP15: =IF(CP$6<Total_Lanes,900*Peak_Time_Eve*(($CN15/CP$6-1)+SQRT(($CN15/CP$6-1)^2+8*($CN15/CP$6)/(Peak_Time_Eve*$O48*CP$6))),"-") -> 620.00608 | CQ15: =IF(CQ$6<Total_Lanes,900*Peak_Time_Eve*(($CN15/CQ$6-1)+SQRT(($CN15/CQ$6-1)^2+8*($CN15/CQ$6)/(Peak_Time_Eve*$O48*CQ$6))),"-") -> 2.8258361 | CR15: =IF(CR$6<Total_Lanes,900*Peak_Time_Eve*(($CN15/CR$6-1)+SQRT(($CN15/CR$6-1)^2+8*($CN15/CR$6)/(Peak_Time_Eve*$O48*CR$6))),"-") -> 0.84523441 | CS15: =IF(CS$6<Total_Lanes,900*Peak_Time_Eve*(($CN15/CS$6-1)+SQRT(($CN15/CS$6-1)^2+8*($CN15/CS$6)/(Peak_Time_Eve*$O48*CS$6))),"-") -> 0.42213512 | CT15: =IF(CT$6<Total_Lanes,900*Peak_Time_Eve*(($CN15/CT$6-1)+SQRT(($CN15/CT$6-1)^2+8*($CN15/CT$6)/(Peak_Time_Eve*$O48*CT$6))),"-") -> 0.25569342 | CU15: =IF(CU$6<Total_Lanes,900*Peak_Time_Eve*(($CN15/CU$6-1)+SQRT(($CN15/CU$6-1)^2+8*($CN15/CU$6)/(Peak_Time_Eve*$O48*CU$6))),"-") -> 0.172143 | CV15: =IF(CV$6<Total_Lanes,900*Peak_Time_Eve*(($CN15/CV$6-1)+SQRT(($CN15/CV$6-1)^2+8*($CN15/CV$6)/(Peak_Time_Eve*$O48*CV$6))),"-") -> 0.12401616 | ... DI15: =IF(DI$6<Total_Lanes,900*Peak_Time_Eve*(($CN15/DI$6-1)+SQRT(($CN15/DI$6-1)^2+8*($CN15/DI$6)/(Peak_Time_Eve*$O48*DI$6))),"-") -> - | DJ15: =3600/O48 -> 2.4
